[13/Apr/2017 22:12:47] ERROR [django.request:135] Internal Server Error: /simengine
Traceback (most recent call last):
  File "/home/ec2-user/envClinicFlow/local/lib/python3.5/site-packages/django/core/handlers/exception.py", line 41, in inner
    response = get_response(request)
  File "/home/ec2-user/envClinicFlow/local/lib/python3.5/site-packages/django/core/handlers/base.py", line 187, in _get_response
    response = self.process_exception_by_middleware(e, request)
  File "/home/ec2-user/envClinicFlow/local/lib/python3.5/site-packages/django/core/handlers/base.py", line 185, in _get_response
    response = wrapped_callback(request, *callback_args, **callback_kwargs)
  File "/home/ec2-user/envClinicFlow/ClinicFlow/simengine/views.py", line 50, in simengine
    mysim = SimulationEngine("ClinicFile1.txt", "Worker1.txt", date, "generated", "generated", "outFile1.txt")
  File "/home/ec2-user/envClinicFlow/ClinicFlow/simengine/SimulationEngine.py", line 147, in SimulationEngine
    Simulation(env,thisClinic,workerSchedule,patientSchedule,outFile)
  File "/home/ec2-user/envClinicFlow/ClinicFlow/simengine/SimulationEngine.py", line 45, in Simulation
    averageClinicTime = averageClinicTime / (len(patientSchedule.patients))
ZeroDivisionError: division by zero
[13/Apr/2017 22:13:07] ERROR [django.request:135] Internal Server Error: /simengine
Traceback (most recent call last):
  File "/home/ec2-user/envClinicFlow/local/lib/python3.5/site-packages/django/core/handlers/exception.py", line 41, in inner
    response = get_response(request)
  File "/home/ec2-user/envClinicFlow/local/lib/python3.5/site-packages/django/core/handlers/base.py", line 187, in _get_response
    response = self.process_exception_by_middleware(e, request)
  File "/home/ec2-user/envClinicFlow/local/lib/python3.5/site-packages/django/core/handlers/base.py", line 185, in _get_response
    response = wrapped_callback(request, *callback_args, **callback_kwargs)
  File "/home/ec2-user/envClinicFlow/ClinicFlow/simengine/views.py", line 50, in simengine
    mysim = SimulationEngine("ClinicFile1.txt", "Worker1.txt", date, "generated", "generated", "outFile1.txt")
  File "/home/ec2-user/envClinicFlow/ClinicFlow/simengine/SimulationEngine.py", line 147, in SimulationEngine
    Simulation(env,thisClinic,workerSchedule,patientSchedule,outFile)
  File "/home/ec2-user/envClinicFlow/ClinicFlow/simengine/SimulationEngine.py", line 45, in Simulation
    averageClinicTime = averageClinicTime / (len(patientSchedule.patients))
ZeroDivisionError: division by zero
[13/Apr/2017 22:13:32] ERROR [django.request:135] Internal Server Error: /simengine
Traceback (most recent call last):
  File "/home/ec2-user/envClinicFlow/local/lib/python3.5/site-packages/django/core/handlers/exception.py", line 41, in inner
    response = get_response(request)
  File "/home/ec2-user/envClinicFlow/local/lib/python3.5/site-packages/django/core/handlers/base.py", line 187, in _get_response
    response = self.process_exception_by_middleware(e, request)
  File "/home/ec2-user/envClinicFlow/local/lib/python3.5/site-packages/django/core/handlers/base.py", line 185, in _get_response
    response = wrapped_callback(request, *callback_args, **callback_kwargs)
  File "/home/ec2-user/envClinicFlow/ClinicFlow/simengine/views.py", line 50, in simengine
    mysim = SimulationEngine("ClinicFile1.txt", "Worker1.txt", date, "generated", "generated", "outFile1.txt")
  File "/home/ec2-user/envClinicFlow/ClinicFlow/simengine/SimulationEngine.py", line 147, in SimulationEngine
    Simulation(env,thisClinic,workerSchedule,patientSchedule,outFile)
  File "/home/ec2-user/envClinicFlow/ClinicFlow/simengine/SimulationEngine.py", line 52, in Simulation
    f = open(outfile, 'a')
PermissionError: [Errno 13] Permission denied: 'outFile1.txt'
[13/Apr/2017 22:53:17] ERROR [django.request:135] Internal Server Error: /simengine
Traceback (most recent call last):
  File "/home/ec2-user/envClinicFlow/local/lib/python3.5/site-packages/django/core/handlers/exception.py", line 41, in inner
    response = get_response(request)
  File "/home/ec2-user/envClinicFlow/local/lib/python3.5/site-packages/django/core/handlers/base.py", line 187, in _get_response
    response = self.process_exception_by_middleware(e, request)
  File "/home/ec2-user/envClinicFlow/local/lib/python3.5/site-packages/django/core/handlers/base.py", line 185, in _get_response
    response = wrapped_callback(request, *callback_args, **callback_kwargs)
  File "/home/ec2-user/envClinicFlow/ClinicFlow/simengine/views.py", line 50, in simengine
    mysim = SimulationEngine("ClinicFile1.txt", "Worker1.txt", date, "generated", "generated", "outFile1.txt")
  File "/home/ec2-user/envClinicFlow/ClinicFlow/simengine/SimulationEngine.py", line 147, in SimulationEngine
    Simulation(env,thisClinic,workerSchedule,patientSchedule,outFile)
  File "/home/ec2-user/envClinicFlow/ClinicFlow/simengine/SimulationEngine.py", line 52, in Simulation
    f = open(outfile, 'a')
PermissionError: [Errno 13] Permission denied: 'outFile1.txt'
[13/Apr/2017 22:57:15] DEBUG [django.template:925] Exception while resolving variable 'patientinfo' in template 'result.html'.
Traceback (most recent call last):
  File "/home/ec2-user/envClinicFlow/local/lib/python3.5/site-packages/django/template/base.py", line 882, in _resolve_lookup
    current = current[bit]
  File "/home/ec2-user/envClinicFlow/local/lib/python3.5/site-packages/django/template/context.py", line 87, in __getitem__
    raise KeyError(key)
KeyError: 'patientinfo'

During handling of the above exception, another exception occurred:

Traceback (most recent call last):
  File "/home/ec2-user/envClinicFlow/local/lib/python3.5/site-packages/django/template/base.py", line 888, in _resolve_lookup
    if isinstance(current, BaseContext) and getattr(type(current), bit):
AttributeError: type object 'RequestContext' has no attribute 'patientinfo'

During handling of the above exception, another exception occurred:

Traceback (most recent call last):
  File "/home/ec2-user/envClinicFlow/local/lib/python3.5/site-packages/django/template/base.py", line 896, in _resolve_lookup
    current = current[int(bit)]
ValueError: invalid literal for int() with base 10: 'patientinfo'

During handling of the above exception, another exception occurred:

Traceback (most recent call last):
  File "/home/ec2-user/envClinicFlow/local/lib/python3.5/site-packages/django/template/base.py", line 903, in _resolve_lookup
    (bit, current))  # missing attribute
django.template.base.VariableDoesNotExist: Failed lookup for key [patientinfo] in '[{\'True\': True, \'None\': None, \'False\': False}, {\'perms\': <django.contrib.auth.context_processors.PermWrapper object at 0x7fa1cc5c31d0>, \'request\': <WSGIRequest: GET \'/simengine?date=asd\'>, \'DEFAULT_MESSAGE_LEVELS\': {\'INFO\': 20, \'ERROR\': 40, \'DEBUG\': 10, \'WARNING\': 30, \'SUCCESS\': 25}, \'user\': <SimpleLazyObject: <django.contrib.auth.models.AnonymousUser object at 0x7fa1cc5c9c88>>, \'csrf_token\': <SimpleLazyObject: \'MkhwiqQnJIEd4uBqy3xpedeXfh5WvQveq2eSv0JQWTqhJ1b1N8lWLaeVaEXOWS8L\'>, \'messages\': <django.contrib.messages.storage.fallback.FallbackStorage object at 0x7fa1d0b4f5c0>}, {}, {\'durations\': \'[["bob", "Registration", [0, 0, 0, "11", "30", 0], [0, 0, 0, "11", "35", 0]], ["bob", "RNInterview", [0, 0, 0, "11", "40", 0], [0, 0, 0, "11", "50", 0]], ["bob", "LaboratoryECG", [0, 0, 0, "11", "54", 0], [0, 0, 0, "12", "01", 0]], ["bob", "Anesthesiologist", [0, 0, 0, "12", "02", 0], [0, 0, 0, "12", "30", 0]]]\', \'averageDownTime\': 10.0, \'averageClinicTime\': 60.0}, {\'block\': <Block Node: content. Contents: [<TextNode: \'\\n<script type="text/javas\'>, <django.template.defaulttags.CsrfTokenNode object at 0x7fa1cc5bd2b0>, <TextNode: \'\\n<!-- \'>, <For Node: for time in patientinfo, tail_len: 3>, <TextNode: \' -->\\n<p>Average time spen\'>, <Variable Node: averageClinicTime>, <TextNode: \' </p>\\n<p>Average down tim\'>, <Variable Node: averageDownTime>, <TextNode: \' </p>\\n<div id="example5.1\'>, <Variable Node: durations|safe>, <TextNode: \';\\n    console.log(duratio\'>, <For Node: for duration in durations, tail_len: 5>, <TextNode: \'\\n\\n    var options = {\\n   \'>, <Variable Node: durations|safe>, <TextNode: \')\\n  }\\n\\n</script>\\n\'>]>}, {}]'
[14/Apr/2017 01:42:35] ERROR [django.security.DisallowedHost:80] Invalid HTTP_HOST header: 'ec2-34-205-53-34.compute-1.amazonaws.com'. You may need to add 'ec2-34-205-53-34.compute-1.amazonaws.com' to ALLOWED_HOSTS.
[14/Apr/2017 10:40:24] WARNING [django.request:152] Not Found: /hndUnblock.cgi
[14/Apr/2017 10:40:25] WARNING [django.request:152] Not Found: /tmUnblock.cgi
[14/Apr/2017 10:40:56] ERROR [django.request:135] Internal Server Error: /
Traceback (most recent call last):
  File "/home/ec2-user/envClinicFlow/local/lib/python3.5/site-packages/django/core/handlers/exception.py", line 41, in inner
    response = get_response(request)
  File "/home/ec2-user/envClinicFlow/local/lib/python3.5/site-packages/django/core/handlers/base.py", line 187, in _get_response
    response = self.process_exception_by_middleware(e, request)
  File "/home/ec2-user/envClinicFlow/local/lib/python3.5/site-packages/django/core/handlers/base.py", line 185, in _get_response
    response = wrapped_callback(request, *callback_args, **callback_kwargs)
  File "/home/ec2-user/envClinicFlow/ClinicFlow/clinicflowx/views.py", line 58, in schedulelists
    for each in result:
  File "/home/ec2-user/envClinicFlow/local/lib/python3.5/site-packages/pymongo/cursor.py", line 1114, in next
    if len(self.__data) or self._refresh():
  File "/home/ec2-user/envClinicFlow/local/lib/python3.5/site-packages/pymongo/cursor.py", line 1036, in _refresh
    self.__collation))
  File "/home/ec2-user/envClinicFlow/local/lib/python3.5/site-packages/pymongo/cursor.py", line 873, in __send_message
    **kwargs)
  File "/home/ec2-user/envClinicFlow/local/lib/python3.5/site-packages/pymongo/mongo_client.py", line 888, in _send_message_with_response
    server = topology.select_server(selector)
  File "/home/ec2-user/envClinicFlow/local/lib/python3.5/site-packages/pymongo/topology.py", line 214, in select_server
    address))
  File "/home/ec2-user/envClinicFlow/local/lib/python3.5/site-packages/pymongo/topology.py", line 189, in select_servers
    self._error_message(selector))
pymongo.errors.ServerSelectionTimeoutError: localhost:27017: [Errno 111] Connection refused
[14/Apr/2017 15:08:34] WARNING [django.request:152] Not Found: /muieblackcat
[14/Apr/2017 15:08:37] WARNING [django.request:152] Not Found: /phpMyAdmin/scripts/setup.php
[14/Apr/2017 15:08:37] WARNING [django.request:152] Not Found: /phpmyadmin/scripts/setup.php
[14/Apr/2017 15:08:38] WARNING [django.request:152] Not Found: /pma/scripts/setup.php
[14/Apr/2017 15:08:40] WARNING [django.request:152] Not Found: /myadmin/scripts/setup.php
[14/Apr/2017 15:08:40] WARNING [django.request:152] Not Found: /MyAdmin/scripts/setup.php
[14/Apr/2017 19:55:20] ERROR [django.security.DisallowedHost:80] Invalid HTTP_HOST header: 'ec2-34-205-53-34.compute-1.amazonaws.com'. You may need to add 'ec2-34-205-53-34.compute-1.amazonaws.com' to ALLOWED_HOSTS.
[14/Apr/2017 20:47:00] ERROR [django.request:135] Internal Server Error: /
Traceback (most recent call last):
  File "/home/ec2-user/envClinicFlow/local/lib/python3.5/site-packages/django/core/handlers/exception.py", line 41, in inner
    response = get_response(request)
  File "/home/ec2-user/envClinicFlow/local/lib/python3.5/site-packages/django/core/handlers/base.py", line 187, in _get_response
    response = self.process_exception_by_middleware(e, request)
  File "/home/ec2-user/envClinicFlow/local/lib/python3.5/site-packages/django/core/handlers/base.py", line 185, in _get_response
    response = wrapped_callback(request, *callback_args, **callback_kwargs)
  File "/home/ec2-user/envClinicFlow/ClinicFlow/clinicflowx/views.py", line 58, in schedulelists
    for each in result:
  File "/home/ec2-user/envClinicFlow/local/lib/python3.5/site-packages/pymongo/cursor.py", line 1114, in next
    if len(self.__data) or self._refresh():
  File "/home/ec2-user/envClinicFlow/local/lib/python3.5/site-packages/pymongo/cursor.py", line 1036, in _refresh
    self.__collation))
  File "/home/ec2-user/envClinicFlow/local/lib/python3.5/site-packages/pymongo/cursor.py", line 873, in __send_message
    **kwargs)
  File "/home/ec2-user/envClinicFlow/local/lib/python3.5/site-packages/pymongo/mongo_client.py", line 888, in _send_message_with_response
    server = topology.select_server(selector)
  File "/home/ec2-user/envClinicFlow/local/lib/python3.5/site-packages/pymongo/topology.py", line 214, in select_server
    address))
  File "/home/ec2-user/envClinicFlow/local/lib/python3.5/site-packages/pymongo/topology.py", line 189, in select_servers
    self._error_message(selector))
pymongo.errors.ServerSelectionTimeoutError: localhost:27017: [Errno 111] Connection refused
[14/Apr/2017 22:20:01] ERROR [django.request:135] Internal Server Error: /simengine
Traceback (most recent call last):
  File "/home/ec2-user/envClinicFlow/local/lib/python3.5/site-packages/django/core/handlers/exception.py", line 41, in inner
    response = get_response(request)
  File "/home/ec2-user/envClinicFlow/local/lib/python3.5/site-packages/django/core/handlers/base.py", line 187, in _get_response
    response = self.process_exception_by_middleware(e, request)
  File "/home/ec2-user/envClinicFlow/local/lib/python3.5/site-packages/django/core/handlers/base.py", line 185, in _get_response
    response = wrapped_callback(request, *callback_args, **callback_kwargs)
  File "/home/ec2-user/envClinicFlow/ClinicFlow/simengine/views.py", line 49, in simengine
    db[date+'result'].delete_many({})
  File "/home/ec2-user/envClinicFlow/local/lib/python3.5/site-packages/pymongo/collection.py", line 1061, in delete_many
    with self._socket_for_writes() as sock_info:
  File "/usr/lib64/python3.5/contextlib.py", line 59, in __enter__
    return next(self.gen)
  File "/home/ec2-user/envClinicFlow/local/lib/python3.5/site-packages/pymongo/mongo_client.py", line 823, in _get_socket
    server = self._get_topology().select_server(selector)
  File "/home/ec2-user/envClinicFlow/local/lib/python3.5/site-packages/pymongo/topology.py", line 214, in select_server
    address))
  File "/home/ec2-user/envClinicFlow/local/lib/python3.5/site-packages/pymongo/topology.py", line 189, in select_servers
    self._error_message(selector))
pymongo.errors.ServerSelectionTimeoutError: localhost:27017: [Errno 111] Connection refused
[15/Apr/2017 00:13:20] ERROR [django.security.DisallowedHost:80] Invalid HTTP_HOST header: 'ec2-34-205-53-34.compute-1.amazonaws.com'. You may need to add 'ec2-34-205-53-34.compute-1.amazonaws.com' to ALLOWED_HOSTS.
[15/Apr/2017 02:06:56] WARNING [django.request:152] Not Found: /manager/html
[15/Apr/2017 07:05:18] ERROR [django.security.DisallowedHost:80] Invalid HTTP_HOST header: 'ec2-34-205-53-34.compute-1.amazonaws.com'. You may need to add 'ec2-34-205-53-34.compute-1.amazonaws.com' to ALLOWED_HOSTS.
[15/Apr/2017 07:10:00] ERROR [django.request:135] Internal Server Error: /
Traceback (most recent call last):
  File "/home/ec2-user/envClinicFlow/local/lib/python3.5/site-packages/django/core/handlers/exception.py", line 41, in inner
    response = get_response(request)
  File "/home/ec2-user/envClinicFlow/local/lib/python3.5/site-packages/django/core/handlers/base.py", line 187, in _get_response
    response = self.process_exception_by_middleware(e, request)
  File "/home/ec2-user/envClinicFlow/local/lib/python3.5/site-packages/django/core/handlers/base.py", line 185, in _get_response
    response = wrapped_callback(request, *callback_args, **callback_kwargs)
  File "/home/ec2-user/envClinicFlow/ClinicFlow/clinicflowx/views.py", line 58, in schedulelists
    for each in result:
  File "/home/ec2-user/envClinicFlow/local/lib/python3.5/site-packages/pymongo/cursor.py", line 1114, in next
    if len(self.__data) or self._refresh():
  File "/home/ec2-user/envClinicFlow/local/lib/python3.5/site-packages/pymongo/cursor.py", line 1036, in _refresh
    self.__collation))
  File "/home/ec2-user/envClinicFlow/local/lib/python3.5/site-packages/pymongo/cursor.py", line 873, in __send_message
    **kwargs)
  File "/home/ec2-user/envClinicFlow/local/lib/python3.5/site-packages/pymongo/mongo_client.py", line 888, in _send_message_with_response
    server = topology.select_server(selector)
  File "/home/ec2-user/envClinicFlow/local/lib/python3.5/site-packages/pymongo/topology.py", line 214, in select_server
    address))
  File "/home/ec2-user/envClinicFlow/local/lib/python3.5/site-packages/pymongo/topology.py", line 189, in select_servers
    self._error_message(selector))
pymongo.errors.ServerSelectionTimeoutError: localhost:27017: [Errno 111] Connection refused
[15/Apr/2017 09:29:33] ERROR [django.security.DisallowedHost:80] Invalid HTTP_HOST header: 'ec2-34-205-53-34.compute-1.amazonaws.com'. You may need to add 'ec2-34-205-53-34.compute-1.amazonaws.com' to ALLOWED_HOSTS.
[15/Apr/2017 11:35:26] WARNING [django.request:152] Not Found: /manager/html
[15/Apr/2017 14:31:45] ERROR [django.security.DisallowedHost:80] Invalid HTTP_HOST header: 'ec2-34-205-53-34.compute-1.amazonaws.com'. You may need to add 'ec2-34-205-53-34.compute-1.amazonaws.com' to ALLOWED_HOSTS.
[15/Apr/2017 20:07:06] ERROR [django.security.DisallowedHost:80] Invalid HTTP_HOST header: 'ec2-34-205-53-34.compute-1.amazonaws.com'. You may need to add 'ec2-34-205-53-34.compute-1.amazonaws.com' to ALLOWED_HOSTS.
[15/Apr/2017 20:30:14] ERROR [django.request:135] Internal Server Error: /
Traceback (most recent call last):
  File "/home/ec2-user/envClinicFlow/local/lib/python3.5/site-packages/django/core/handlers/exception.py", line 41, in inner
    response = get_response(request)
  File "/home/ec2-user/envClinicFlow/local/lib/python3.5/site-packages/django/core/handlers/base.py", line 187, in _get_response
    response = self.process_exception_by_middleware(e, request)
  File "/home/ec2-user/envClinicFlow/local/lib/python3.5/site-packages/django/core/handlers/base.py", line 185, in _get_response
    response = wrapped_callback(request, *callback_args, **callback_kwargs)
  File "/home/ec2-user/envClinicFlow/ClinicFlow/clinicflowx/views.py", line 58, in schedulelists
    for each in result:
  File "/home/ec2-user/envClinicFlow/local/lib/python3.5/site-packages/pymongo/cursor.py", line 1114, in next
    if len(self.__data) or self._refresh():
  File "/home/ec2-user/envClinicFlow/local/lib/python3.5/site-packages/pymongo/cursor.py", line 1036, in _refresh
    self.__collation))
  File "/home/ec2-user/envClinicFlow/local/lib/python3.5/site-packages/pymongo/cursor.py", line 873, in __send_message
    **kwargs)
  File "/home/ec2-user/envClinicFlow/local/lib/python3.5/site-packages/pymongo/mongo_client.py", line 888, in _send_message_with_response
    server = topology.select_server(selector)
  File "/home/ec2-user/envClinicFlow/local/lib/python3.5/site-packages/pymongo/topology.py", line 214, in select_server
    address))
  File "/home/ec2-user/envClinicFlow/local/lib/python3.5/site-packages/pymongo/topology.py", line 189, in select_servers
    self._error_message(selector))
pymongo.errors.ServerSelectionTimeoutError: localhost:27017: [Errno 111] Connection refused
[15/Apr/2017 20:30:15] ERROR [django.request:135] Internal Server Error: /
Traceback (most recent call last):
  File "/home/ec2-user/envClinicFlow/local/lib/python3.5/site-packages/django/core/handlers/exception.py", line 41, in inner
    response = get_response(request)
  File "/home/ec2-user/envClinicFlow/local/lib/python3.5/site-packages/django/core/handlers/base.py", line 187, in _get_response
    response = self.process_exception_by_middleware(e, request)
  File "/home/ec2-user/envClinicFlow/local/lib/python3.5/site-packages/django/core/handlers/base.py", line 185, in _get_response
    response = wrapped_callback(request, *callback_args, **callback_kwargs)
  File "/home/ec2-user/envClinicFlow/ClinicFlow/clinicflowx/views.py", line 58, in schedulelists
    for each in result:
  File "/home/ec2-user/envClinicFlow/local/lib/python3.5/site-packages/pymongo/cursor.py", line 1114, in next
    if len(self.__data) or self._refresh():
  File "/home/ec2-user/envClinicFlow/local/lib/python3.5/site-packages/pymongo/cursor.py", line 1036, in _refresh
    self.__collation))
  File "/home/ec2-user/envClinicFlow/local/lib/python3.5/site-packages/pymongo/cursor.py", line 873, in __send_message
    **kwargs)
  File "/home/ec2-user/envClinicFlow/local/lib/python3.5/site-packages/pymongo/mongo_client.py", line 888, in _send_message_with_response
    server = topology.select_server(selector)
  File "/home/ec2-user/envClinicFlow/local/lib/python3.5/site-packages/pymongo/topology.py", line 214, in select_server
    address))
  File "/home/ec2-user/envClinicFlow/local/lib/python3.5/site-packages/pymongo/topology.py", line 189, in select_servers
    self._error_message(selector))
pymongo.errors.ServerSelectionTimeoutError: localhost:27017: [Errno 111] Connection refused
[15/Apr/2017 21:15:34] ERROR [django.security.DisallowedHost:80] Invalid HTTP_HOST header: 'ec2-34-205-53-34.compute-1.amazonaws.com'. You may need to add 'ec2-34-205-53-34.compute-1.amazonaws.com' to ALLOWED_HOSTS.
[15/Apr/2017 21:55:28] ERROR [django.security.DisallowedHost:80] Invalid HTTP_HOST header: 'ec2-34-205-53-34.compute-1.amazonaws.com'. You may need to add 'ec2-34-205-53-34.compute-1.amazonaws.com' to ALLOWED_HOSTS.
[16/Apr/2017 01:34:39] ERROR [django.request:135] Internal Server Error: /
Traceback (most recent call last):
  File "/home/ec2-user/envClinicFlow/local/lib/python3.5/site-packages/django/core/handlers/exception.py", line 41, in inner
    response = get_response(request)
  File "/home/ec2-user/envClinicFlow/local/lib/python3.5/site-packages/django/core/handlers/base.py", line 187, in _get_response
    response = self.process_exception_by_middleware(e, request)
  File "/home/ec2-user/envClinicFlow/local/lib/python3.5/site-packages/django/core/handlers/base.py", line 185, in _get_response
    response = wrapped_callback(request, *callback_args, **callback_kwargs)
  File "/home/ec2-user/envClinicFlow/ClinicFlow/clinicflowx/views.py", line 58, in schedulelists
    for each in result:
  File "/home/ec2-user/envClinicFlow/local/lib/python3.5/site-packages/pymongo/cursor.py", line 1114, in next
    if len(self.__data) or self._refresh():
  File "/home/ec2-user/envClinicFlow/local/lib/python3.5/site-packages/pymongo/cursor.py", line 1036, in _refresh
    self.__collation))
  File "/home/ec2-user/envClinicFlow/local/lib/python3.5/site-packages/pymongo/cursor.py", line 873, in __send_message
    **kwargs)
  File "/home/ec2-user/envClinicFlow/local/lib/python3.5/site-packages/pymongo/mongo_client.py", line 888, in _send_message_with_response
    server = topology.select_server(selector)
  File "/home/ec2-user/envClinicFlow/local/lib/python3.5/site-packages/pymongo/topology.py", line 214, in select_server
    address))
  File "/home/ec2-user/envClinicFlow/local/lib/python3.5/site-packages/pymongo/topology.py", line 189, in select_servers
    self._error_message(selector))
pymongo.errors.ServerSelectionTimeoutError: localhost:27017: [Errno 111] Connection refused
[16/Apr/2017 01:53:51] ERROR [django.security.DisallowedHost:80] Invalid HTTP_HOST header: 'ec2-34-205-53-34.compute-1.amazonaws.com'. You may need to add 'ec2-34-205-53-34.compute-1.amazonaws.com' to ALLOWED_HOSTS.
[16/Apr/2017 04:19:01] ERROR [django.request:135] Internal Server Error: /
Traceback (most recent call last):
  File "/home/ec2-user/envClinicFlow/local/lib/python3.5/site-packages/django/core/handlers/exception.py", line 41, in inner
    response = get_response(request)
  File "/home/ec2-user/envClinicFlow/local/lib/python3.5/site-packages/django/core/handlers/base.py", line 187, in _get_response
    response = self.process_exception_by_middleware(e, request)
  File "/home/ec2-user/envClinicFlow/local/lib/python3.5/site-packages/django/core/handlers/base.py", line 185, in _get_response
    response = wrapped_callback(request, *callback_args, **callback_kwargs)
  File "/home/ec2-user/envClinicFlow/ClinicFlow/clinicflowx/views.py", line 58, in schedulelists
    for each in result:
  File "/home/ec2-user/envClinicFlow/local/lib/python3.5/site-packages/pymongo/cursor.py", line 1114, in next
    if len(self.__data) or self._refresh():
  File "/home/ec2-user/envClinicFlow/local/lib/python3.5/site-packages/pymongo/cursor.py", line 1036, in _refresh
    self.__collation))
  File "/home/ec2-user/envClinicFlow/local/lib/python3.5/site-packages/pymongo/cursor.py", line 873, in __send_message
    **kwargs)
  File "/home/ec2-user/envClinicFlow/local/lib/python3.5/site-packages/pymongo/mongo_client.py", line 888, in _send_message_with_response
    server = topology.select_server(selector)
  File "/home/ec2-user/envClinicFlow/local/lib/python3.5/site-packages/pymongo/topology.py", line 214, in select_server
    address))
  File "/home/ec2-user/envClinicFlow/local/lib/python3.5/site-packages/pymongo/topology.py", line 189, in select_servers
    self._error_message(selector))
pymongo.errors.ServerSelectionTimeoutError: localhost:27017: [Errno 111] Connection refused
[16/Apr/2017 07:57:19] ERROR [django.security.DisallowedHost:80] Invalid HTTP_HOST header: 'ec2-34-205-53-34.compute-1.amazonaws.com'. You may need to add 'ec2-34-205-53-34.compute-1.amazonaws.com' to ALLOWED_HOSTS.
[16/Apr/2017 10:43:17] ERROR [django.security.DisallowedHost:80] Invalid HTTP_HOST header: 'ec2-34-205-53-34.compute-1.amazonaws.com'. You may need to add 'ec2-34-205-53-34.compute-1.amazonaws.com' to ALLOWED_HOSTS.
[16/Apr/2017 13:28:15] ERROR [django.request:135] Internal Server Error: /
Traceback (most recent call last):
  File "/home/ec2-user/envClinicFlow/local/lib/python3.5/site-packages/django/core/handlers/exception.py", line 41, in inner
    response = get_response(request)
  File "/home/ec2-user/envClinicFlow/local/lib/python3.5/site-packages/django/core/handlers/base.py", line 187, in _get_response
    response = self.process_exception_by_middleware(e, request)
  File "/home/ec2-user/envClinicFlow/local/lib/python3.5/site-packages/django/core/handlers/base.py", line 185, in _get_response
    response = wrapped_callback(request, *callback_args, **callback_kwargs)
  File "/home/ec2-user/envClinicFlow/ClinicFlow/clinicflowx/views.py", line 58, in schedulelists
    for each in result:
  File "/home/ec2-user/envClinicFlow/local/lib/python3.5/site-packages/pymongo/cursor.py", line 1114, in next
    if len(self.__data) or self._refresh():
  File "/home/ec2-user/envClinicFlow/local/lib/python3.5/site-packages/pymongo/cursor.py", line 1036, in _refresh
    self.__collation))
  File "/home/ec2-user/envClinicFlow/local/lib/python3.5/site-packages/pymongo/cursor.py", line 873, in __send_message
    **kwargs)
  File "/home/ec2-user/envClinicFlow/local/lib/python3.5/site-packages/pymongo/mongo_client.py", line 888, in _send_message_with_response
    server = topology.select_server(selector)
  File "/home/ec2-user/envClinicFlow/local/lib/python3.5/site-packages/pymongo/topology.py", line 214, in select_server
    address))
  File "/home/ec2-user/envClinicFlow/local/lib/python3.5/site-packages/pymongo/topology.py", line 189, in select_servers
    self._error_message(selector))
pymongo.errors.ServerSelectionTimeoutError: localhost:27017: [Errno 111] Connection refused
[16/Apr/2017 19:59:25] WARNING [django.request:152] Not Found: /muieblackcat
[16/Apr/2017 19:59:25] WARNING [django.request:152] Not Found: /phpmyadmin/scripts/setup.php
[16/Apr/2017 20:09:32] WARNING [django.request:152] Not Found: /CFIDE/administrator/
[16/Apr/2017 21:26:31] ERROR [django.security.DisallowedHost:80] Invalid HTTP_HOST header: 'ec2-34-205-53-34.compute-1.amazonaws.com'. You may need to add 'ec2-34-205-53-34.compute-1.amazonaws.com' to ALLOWED_HOSTS.
[16/Apr/2017 21:38:21] ERROR [django.security.DisallowedHost:80] Invalid HTTP_HOST header: 'ec2-34-205-53-34.compute-1.amazonaws.com'. You may need to add 'ec2-34-205-53-34.compute-1.amazonaws.com' to ALLOWED_HOSTS.
[16/Apr/2017 22:56:42] ERROR [django.security.DisallowedHost:80] Invalid HTTP_HOST header: 'ec2-34-205-53-34.compute-1.amazonaws.com'. You may need to add 'ec2-34-205-53-34.compute-1.amazonaws.com' to ALLOWED_HOSTS.
[17/Apr/2017 05:23:02] WARNING [django.request:152] Not Found: /muieblackcat
[17/Apr/2017 05:32:56] ERROR [django.security.DisallowedHost:80] Invalid HTTP_HOST header: 'ec2-34-205-53-34.compute-1.amazonaws.com'. You may need to add 'ec2-34-205-53-34.compute-1.amazonaws.com' to ALLOWED_HOSTS.
[17/Apr/2017 06:13:16] ERROR [django.security.DisallowedHost:80] Invalid HTTP_HOST header: 'ec2-34-205-53-34.compute-1.amazonaws.com'. You may need to add 'ec2-34-205-53-34.compute-1.amazonaws.com' to ALLOWED_HOSTS.
[17/Apr/2017 08:10:59] ERROR [django.request:135] Internal Server Error: /
Traceback (most recent call last):
  File "/home/ec2-user/envClinicFlow/local/lib/python3.5/site-packages/django/core/handlers/exception.py", line 41, in inner
    response = get_response(request)
  File "/home/ec2-user/envClinicFlow/local/lib/python3.5/site-packages/django/core/handlers/base.py", line 187, in _get_response
    response = self.process_exception_by_middleware(e, request)
  File "/home/ec2-user/envClinicFlow/local/lib/python3.5/site-packages/django/core/handlers/base.py", line 185, in _get_response
    response = wrapped_callback(request, *callback_args, **callback_kwargs)
  File "/home/ec2-user/envClinicFlow/ClinicFlow/clinicflowx/views.py", line 58, in schedulelists
    for each in result:
  File "/home/ec2-user/envClinicFlow/local/lib/python3.5/site-packages/pymongo/cursor.py", line 1114, in next
    if len(self.__data) or self._refresh():
  File "/home/ec2-user/envClinicFlow/local/lib/python3.5/site-packages/pymongo/cursor.py", line 1036, in _refresh
    self.__collation))
  File "/home/ec2-user/envClinicFlow/local/lib/python3.5/site-packages/pymongo/cursor.py", line 873, in __send_message
    **kwargs)
  File "/home/ec2-user/envClinicFlow/local/lib/python3.5/site-packages/pymongo/mongo_client.py", line 888, in _send_message_with_response
    server = topology.select_server(selector)
  File "/home/ec2-user/envClinicFlow/local/lib/python3.5/site-packages/pymongo/topology.py", line 214, in select_server
    address))
  File "/home/ec2-user/envClinicFlow/local/lib/python3.5/site-packages/pymongo/topology.py", line 189, in select_servers
    self._error_message(selector))
pymongo.errors.ServerSelectionTimeoutError: localhost:27017: [Errno 111] Connection refused
[17/Apr/2017 17:50:14] ERROR [django.security.DisallowedHost:80] Invalid HTTP_HOST header: 'ec2-34-205-53-34.compute-1.amazonaws.com'. You may need to add 'ec2-34-205-53-34.compute-1.amazonaws.com' to ALLOWED_HOSTS.
[17/Apr/2017 19:03:01] WARNING [django.request:152] Not Found: /current_config/Account1
[17/Apr/2017 22:40:19] ERROR [django.security.DisallowedHost:80] Invalid HTTP_HOST header: 'ec2-34-205-53-34.compute-1.amazonaws.com'. You may need to add 'ec2-34-205-53-34.compute-1.amazonaws.com' to ALLOWED_HOSTS.
[17/Apr/2017 22:56:34] ERROR [django.security.DisallowedHost:80] Invalid HTTP_HOST header: 'proxyjudge.info'. You may need to add 'proxyjudge.info' to ALLOWED_HOSTS.
[17/Apr/2017 23:13:06] ERROR [django.security.DisallowedHost:80] Invalid HTTP_HOST header: 'ec2-34-205-53-34.compute-1.amazonaws.com'. You may need to add 'ec2-34-205-53-34.compute-1.amazonaws.com' to ALLOWED_HOSTS.
[18/Apr/2017 00:55:46] ERROR [django.security.DisallowedHost:80] Invalid HTTP_HOST header: 'ec2-34-205-53-34.compute-1.amazonaws.com'. You may need to add 'ec2-34-205-53-34.compute-1.amazonaws.com' to ALLOWED_HOSTS.
[18/Apr/2017 00:57:08] ERROR [django.security.DisallowedHost:80] Invalid HTTP_HOST header: 'ec2-34-205-53-34.compute-1.amazonaws.com'. You may need to add 'ec2-34-205-53-34.compute-1.amazonaws.com' to ALLOWED_HOSTS.
[18/Apr/2017 04:35:12] ERROR [django.security.DisallowedHost:80] Invalid HTTP_HOST header: 'ec2-34-205-53-34.compute-1.amazonaws.com'. You may need to add 'ec2-34-205-53-34.compute-1.amazonaws.com' to ALLOWED_HOSTS.
[18/Apr/2017 08:40:39] ERROR [django.security.DisallowedHost:80] Invalid HTTP_HOST header: 'ec2-34-205-53-34.compute-1.amazonaws.com'. You may need to add 'ec2-34-205-53-34.compute-1.amazonaws.com' to ALLOWED_HOSTS.
[18/Apr/2017 09:22:36] WARNING [django.request:152] Not Found: /xmlrpc.php
[18/Apr/2017 10:46:10] ERROR [django.security.DisallowedHost:80] Invalid HTTP_HOST header: 'clientapi.ipip.net'. You may need to add 'clientapi.ipip.net' to ALLOWED_HOSTS.
[18/Apr/2017 10:46:38] ERROR [django.request:135] Internal Server Error: /
Traceback (most recent call last):
  File "/home/ec2-user/envClinicFlow/local/lib/python3.5/site-packages/django/core/handlers/exception.py", line 41, in inner
    response = get_response(request)
  File "/home/ec2-user/envClinicFlow/local/lib/python3.5/site-packages/django/core/handlers/base.py", line 187, in _get_response
    response = self.process_exception_by_middleware(e, request)
  File "/home/ec2-user/envClinicFlow/local/lib/python3.5/site-packages/django/core/handlers/base.py", line 185, in _get_response
    response = wrapped_callback(request, *callback_args, **callback_kwargs)
  File "/home/ec2-user/envClinicFlow/ClinicFlow/clinicflowx/views.py", line 58, in schedulelists
    for each in result:
  File "/home/ec2-user/envClinicFlow/local/lib/python3.5/site-packages/pymongo/cursor.py", line 1114, in next
    if len(self.__data) or self._refresh():
  File "/home/ec2-user/envClinicFlow/local/lib/python3.5/site-packages/pymongo/cursor.py", line 1036, in _refresh
    self.__collation))
  File "/home/ec2-user/envClinicFlow/local/lib/python3.5/site-packages/pymongo/cursor.py", line 873, in __send_message
    **kwargs)
  File "/home/ec2-user/envClinicFlow/local/lib/python3.5/site-packages/pymongo/mongo_client.py", line 888, in _send_message_with_response
    server = topology.select_server(selector)
  File "/home/ec2-user/envClinicFlow/local/lib/python3.5/site-packages/pymongo/topology.py", line 214, in select_server
    address))
  File "/home/ec2-user/envClinicFlow/local/lib/python3.5/site-packages/pymongo/topology.py", line 189, in select_servers
    self._error_message(selector))
pymongo.errors.ServerSelectionTimeoutError: localhost:27017: [Errno 111] Connection refused
[18/Apr/2017 12:00:44] ERROR [django.security.DisallowedHost:80] Invalid HTTP_HOST header: 'ec2-34-205-53-34.compute-1.amazonaws.com'. You may need to add 'ec2-34-205-53-34.compute-1.amazonaws.com' to ALLOWED_HOSTS.
[18/Apr/2017 16:01:24] ERROR [django.security.DisallowedHost:80] Invalid HTTP_HOST header: ''. The domain name provided is not valid according to RFC 1034/1035.
[18/Apr/2017 19:27:35] ERROR [django.request:135] Internal Server Error: /
Traceback (most recent call last):
  File "/home/ec2-user/envClinicFlow/local/lib/python3.5/site-packages/django/core/handlers/exception.py", line 41, in inner
    response = get_response(request)
  File "/home/ec2-user/envClinicFlow/local/lib/python3.5/site-packages/django/core/handlers/base.py", line 187, in _get_response
    response = self.process_exception_by_middleware(e, request)
  File "/home/ec2-user/envClinicFlow/local/lib/python3.5/site-packages/django/core/handlers/base.py", line 185, in _get_response
    response = wrapped_callback(request, *callback_args, **callback_kwargs)
  File "/home/ec2-user/envClinicFlow/ClinicFlow/clinicflowx/views.py", line 58, in schedulelists
    for each in result:
  File "/home/ec2-user/envClinicFlow/local/lib/python3.5/site-packages/pymongo/cursor.py", line 1114, in next
    if len(self.__data) or self._refresh():
  File "/home/ec2-user/envClinicFlow/local/lib/python3.5/site-packages/pymongo/cursor.py", line 1036, in _refresh
    self.__collation))
  File "/home/ec2-user/envClinicFlow/local/lib/python3.5/site-packages/pymongo/cursor.py", line 873, in __send_message
    **kwargs)
  File "/home/ec2-user/envClinicFlow/local/lib/python3.5/site-packages/pymongo/mongo_client.py", line 888, in _send_message_with_response
    server = topology.select_server(selector)
  File "/home/ec2-user/envClinicFlow/local/lib/python3.5/site-packages/pymongo/topology.py", line 214, in select_server
    address))
  File "/home/ec2-user/envClinicFlow/local/lib/python3.5/site-packages/pymongo/topology.py", line 189, in select_servers
    self._error_message(selector))
pymongo.errors.ServerSelectionTimeoutError: localhost:27017: [Errno 111] Connection refused
[18/Apr/2017 19:27:36] ERROR [django.request:135] Internal Server Error: /
Traceback (most recent call last):
  File "/home/ec2-user/envClinicFlow/local/lib/python3.5/site-packages/django/core/handlers/exception.py", line 41, in inner
    response = get_response(request)
  File "/home/ec2-user/envClinicFlow/local/lib/python3.5/site-packages/django/core/handlers/base.py", line 187, in _get_response
    response = self.process_exception_by_middleware(e, request)
  File "/home/ec2-user/envClinicFlow/local/lib/python3.5/site-packages/django/core/handlers/base.py", line 185, in _get_response
    response = wrapped_callback(request, *callback_args, **callback_kwargs)
  File "/home/ec2-user/envClinicFlow/ClinicFlow/clinicflowx/views.py", line 58, in schedulelists
    for each in result:
  File "/home/ec2-user/envClinicFlow/local/lib/python3.5/site-packages/pymongo/cursor.py", line 1114, in next
    if len(self.__data) or self._refresh():
  File "/home/ec2-user/envClinicFlow/local/lib/python3.5/site-packages/pymongo/cursor.py", line 1036, in _refresh
    self.__collation))
  File "/home/ec2-user/envClinicFlow/local/lib/python3.5/site-packages/pymongo/cursor.py", line 873, in __send_message
    **kwargs)
  File "/home/ec2-user/envClinicFlow/local/lib/python3.5/site-packages/pymongo/mongo_client.py", line 888, in _send_message_with_response
    server = topology.select_server(selector)
  File "/home/ec2-user/envClinicFlow/local/lib/python3.5/site-packages/pymongo/topology.py", line 214, in select_server
    address))
  File "/home/ec2-user/envClinicFlow/local/lib/python3.5/site-packages/pymongo/topology.py", line 189, in select_servers
    self._error_message(selector))
pymongo.errors.ServerSelectionTimeoutError: localhost:27017: [Errno 111] Connection refused
[18/Apr/2017 20:34:03] ERROR [django.security.DisallowedHost:80] Invalid HTTP_HOST header: 'ec2-34-205-53-34.compute-1.amazonaws.com'. You may need to add 'ec2-34-205-53-34.compute-1.amazonaws.com' to ALLOWED_HOSTS.
[18/Apr/2017 21:08:13] ERROR [django.security.DisallowedHost:80] Invalid HTTP_HOST header: 'ec2-34-205-53-34.compute-1.amazonaws.com'. You may need to add 'ec2-34-205-53-34.compute-1.amazonaws.com' to ALLOWED_HOSTS.
[18/Apr/2017 21:50:49] ERROR [django.request:135] Internal Server Error: /
Traceback (most recent call last):
  File "/home/ec2-user/envClinicFlow/local/lib/python3.5/site-packages/django/core/handlers/exception.py", line 41, in inner
    response = get_response(request)
  File "/home/ec2-user/envClinicFlow/local/lib/python3.5/site-packages/django/core/handlers/base.py", line 187, in _get_response
    response = self.process_exception_by_middleware(e, request)
  File "/home/ec2-user/envClinicFlow/local/lib/python3.5/site-packages/django/core/handlers/base.py", line 185, in _get_response
    response = wrapped_callback(request, *callback_args, **callback_kwargs)
  File "/home/ec2-user/envClinicFlow/ClinicFlow/clinicflowx/views.py", line 58, in schedulelists
    for each in result:
  File "/home/ec2-user/envClinicFlow/local/lib/python3.5/site-packages/pymongo/cursor.py", line 1114, in next
    if len(self.__data) or self._refresh():
  File "/home/ec2-user/envClinicFlow/local/lib/python3.5/site-packages/pymongo/cursor.py", line 1036, in _refresh
    self.__collation))
  File "/home/ec2-user/envClinicFlow/local/lib/python3.5/site-packages/pymongo/cursor.py", line 873, in __send_message
    **kwargs)
  File "/home/ec2-user/envClinicFlow/local/lib/python3.5/site-packages/pymongo/mongo_client.py", line 888, in _send_message_with_response
    server = topology.select_server(selector)
  File "/home/ec2-user/envClinicFlow/local/lib/python3.5/site-packages/pymongo/topology.py", line 214, in select_server
    address))
  File "/home/ec2-user/envClinicFlow/local/lib/python3.5/site-packages/pymongo/topology.py", line 189, in select_servers
    self._error_message(selector))
pymongo.errors.ServerSelectionTimeoutError: localhost:27017: [Errno 111] Connection refused
[18/Apr/2017 22:49:23] WARNING [django.request:152] Not Found: /cgi/common.cgi
[18/Apr/2017 22:49:24] WARNING [django.request:152] Not Found: /stssys.htm
[18/Apr/2017 22:49:27] WARNING [django.request:152] Not Found: /command.php
[18/Apr/2017 22:49:54] ERROR [django.request:135] Internal Server Error: /
Traceback (most recent call last):
  File "/home/ec2-user/envClinicFlow/local/lib/python3.5/site-packages/django/core/handlers/exception.py", line 41, in inner
    response = get_response(request)
  File "/home/ec2-user/envClinicFlow/local/lib/python3.5/site-packages/django/core/handlers/base.py", line 187, in _get_response
    response = self.process_exception_by_middleware(e, request)
  File "/home/ec2-user/envClinicFlow/local/lib/python3.5/site-packages/django/core/handlers/base.py", line 185, in _get_response
    response = wrapped_callback(request, *callback_args, **callback_kwargs)
  File "/home/ec2-user/envClinicFlow/ClinicFlow/clinicflowx/views.py", line 58, in schedulelists
    for each in result:
  File "/home/ec2-user/envClinicFlow/local/lib/python3.5/site-packages/pymongo/cursor.py", line 1114, in next
    if len(self.__data) or self._refresh():
  File "/home/ec2-user/envClinicFlow/local/lib/python3.5/site-packages/pymongo/cursor.py", line 1036, in _refresh
    self.__collation))
  File "/home/ec2-user/envClinicFlow/local/lib/python3.5/site-packages/pymongo/cursor.py", line 873, in __send_message
    **kwargs)
  File "/home/ec2-user/envClinicFlow/local/lib/python3.5/site-packages/pymongo/mongo_client.py", line 888, in _send_message_with_response
    server = topology.select_server(selector)
  File "/home/ec2-user/envClinicFlow/local/lib/python3.5/site-packages/pymongo/topology.py", line 214, in select_server
    address))
  File "/home/ec2-user/envClinicFlow/local/lib/python3.5/site-packages/pymongo/topology.py", line 189, in select_servers
    self._error_message(selector))
pymongo.errors.ServerSelectionTimeoutError: localhost:27017: [Errno 111] Connection refused
[19/Apr/2017 01:14:25] ERROR [django.security.DisallowedHost:80] Invalid HTTP_HOST header: 'ec2-34-205-53-34.compute-1.amazonaws.com'. You may need to add 'ec2-34-205-53-34.compute-1.amazonaws.com' to ALLOWED_HOSTS.
[19/Apr/2017 02:08:31] ERROR [django.security.DisallowedHost:80] Invalid HTTP_HOST header: 'ec2-34-205-53-34.compute-1.amazonaws.com'. You may need to add 'ec2-34-205-53-34.compute-1.amazonaws.com' to ALLOWED_HOSTS.
[19/Apr/2017 02:20:35] ERROR [django.security.DisallowedHost:80] Invalid HTTP_HOST header: 'clientapi.ipip.net'. You may need to add 'clientapi.ipip.net' to ALLOWED_HOSTS.
[19/Apr/2017 02:21:02] ERROR [django.request:135] Internal Server Error: /
Traceback (most recent call last):
  File "/home/ec2-user/envClinicFlow/local/lib/python3.5/site-packages/django/core/handlers/exception.py", line 41, in inner
    response = get_response(request)
  File "/home/ec2-user/envClinicFlow/local/lib/python3.5/site-packages/django/core/handlers/base.py", line 187, in _get_response
    response = self.process_exception_by_middleware(e, request)
  File "/home/ec2-user/envClinicFlow/local/lib/python3.5/site-packages/django/core/handlers/base.py", line 185, in _get_response
    response = wrapped_callback(request, *callback_args, **callback_kwargs)
  File "/home/ec2-user/envClinicFlow/ClinicFlow/clinicflowx/views.py", line 58, in schedulelists
    for each in result:
  File "/home/ec2-user/envClinicFlow/local/lib/python3.5/site-packages/pymongo/cursor.py", line 1114, in next
    if len(self.__data) or self._refresh():
  File "/home/ec2-user/envClinicFlow/local/lib/python3.5/site-packages/pymongo/cursor.py", line 1036, in _refresh
    self.__collation))
  File "/home/ec2-user/envClinicFlow/local/lib/python3.5/site-packages/pymongo/cursor.py", line 873, in __send_message
    **kwargs)
  File "/home/ec2-user/envClinicFlow/local/lib/python3.5/site-packages/pymongo/mongo_client.py", line 888, in _send_message_with_response
    server = topology.select_server(selector)
  File "/home/ec2-user/envClinicFlow/local/lib/python3.5/site-packages/pymongo/topology.py", line 214, in select_server
    address))
  File "/home/ec2-user/envClinicFlow/local/lib/python3.5/site-packages/pymongo/topology.py", line 189, in select_servers
    self._error_message(selector))
pymongo.errors.ServerSelectionTimeoutError: localhost:27017: [Errno 111] Connection refused
[19/Apr/2017 03:42:55] ERROR [django.security.DisallowedHost:80] Invalid HTTP_HOST header: 'check.proxyradar.com'. You may need to add 'check.proxyradar.com' to ALLOWED_HOSTS.
[19/Apr/2017 04:57:24] WARNING [django.request:152] Not Found: /w00tw00t.at.blackhats.romanian.anti-sec:)
[19/Apr/2017 04:57:25] WARNING [django.request:152] Not Found: /phpMyAdmin/scripts/setup.php
[19/Apr/2017 04:57:26] WARNING [django.request:152] Not Found: /phpmyadmin/scripts/setup.php
[19/Apr/2017 04:57:27] WARNING [django.request:152] Not Found: /pma/scripts/setup.php
[19/Apr/2017 04:57:27] WARNING [django.request:152] Not Found: /myadmin/scripts/setup.php
[19/Apr/2017 04:57:28] WARNING [django.request:152] Not Found: /MyAdmin/scripts/setup.php
[19/Apr/2017 05:47:38] ERROR [django.request:135] Internal Server Error: /
Traceback (most recent call last):
  File "/home/ec2-user/envClinicFlow/local/lib/python3.5/site-packages/django/core/handlers/exception.py", line 41, in inner
    response = get_response(request)
  File "/home/ec2-user/envClinicFlow/local/lib/python3.5/site-packages/django/core/handlers/base.py", line 187, in _get_response
    response = self.process_exception_by_middleware(e, request)
  File "/home/ec2-user/envClinicFlow/local/lib/python3.5/site-packages/django/core/handlers/base.py", line 185, in _get_response
    response = wrapped_callback(request, *callback_args, **callback_kwargs)
  File "/home/ec2-user/envClinicFlow/ClinicFlow/clinicflowx/views.py", line 58, in schedulelists
    for each in result:
  File "/home/ec2-user/envClinicFlow/local/lib/python3.5/site-packages/pymongo/cursor.py", line 1114, in next
    if len(self.__data) or self._refresh():
  File "/home/ec2-user/envClinicFlow/local/lib/python3.5/site-packages/pymongo/cursor.py", line 1036, in _refresh
    self.__collation))
  File "/home/ec2-user/envClinicFlow/local/lib/python3.5/site-packages/pymongo/cursor.py", line 873, in __send_message
    **kwargs)
  File "/home/ec2-user/envClinicFlow/local/lib/python3.5/site-packages/pymongo/mongo_client.py", line 888, in _send_message_with_response
    server = topology.select_server(selector)
  File "/home/ec2-user/envClinicFlow/local/lib/python3.5/site-packages/pymongo/topology.py", line 214, in select_server
    address))
  File "/home/ec2-user/envClinicFlow/local/lib/python3.5/site-packages/pymongo/topology.py", line 189, in select_servers
    self._error_message(selector))
pymongo.errors.ServerSelectionTimeoutError: localhost:27017: [Errno 111] Connection refused
[19/Apr/2017 06:54:06] ERROR [django.request:135] Internal Server Error: /
Traceback (most recent call last):
  File "/home/ec2-user/envClinicFlow/local/lib/python3.5/site-packages/django/core/handlers/exception.py", line 41, in inner
    response = get_response(request)
  File "/home/ec2-user/envClinicFlow/local/lib/python3.5/site-packages/django/core/handlers/base.py", line 187, in _get_response
    response = self.process_exception_by_middleware(e, request)
  File "/home/ec2-user/envClinicFlow/local/lib/python3.5/site-packages/django/core/handlers/base.py", line 185, in _get_response
    response = wrapped_callback(request, *callback_args, **callback_kwargs)
  File "/home/ec2-user/envClinicFlow/ClinicFlow/clinicflowx/views.py", line 58, in schedulelists
    for each in result:
  File "/home/ec2-user/envClinicFlow/local/lib/python3.5/site-packages/pymongo/cursor.py", line 1114, in next
    if len(self.__data) or self._refresh():
  File "/home/ec2-user/envClinicFlow/local/lib/python3.5/site-packages/pymongo/cursor.py", line 1036, in _refresh
    self.__collation))
  File "/home/ec2-user/envClinicFlow/local/lib/python3.5/site-packages/pymongo/cursor.py", line 873, in __send_message
    **kwargs)
  File "/home/ec2-user/envClinicFlow/local/lib/python3.5/site-packages/pymongo/mongo_client.py", line 888, in _send_message_with_response
    server = topology.select_server(selector)
  File "/home/ec2-user/envClinicFlow/local/lib/python3.5/site-packages/pymongo/topology.py", line 214, in select_server
    address))
  File "/home/ec2-user/envClinicFlow/local/lib/python3.5/site-packages/pymongo/topology.py", line 189, in select_servers
    self._error_message(selector))
pymongo.errors.ServerSelectionTimeoutError: localhost:27017: [Errno 111] Connection refused
[19/Apr/2017 07:54:04] ERROR [django.security.DisallowedHost:80] Invalid HTTP_HOST header: 'check.proxyradar.com'. You may need to add 'check.proxyradar.com' to ALLOWED_HOSTS.
[19/Apr/2017 12:12:42] ERROR [django.security.DisallowedHost:80] Invalid HTTP_HOST header: 'check.proxyradar.com'. You may need to add 'check.proxyradar.com' to ALLOWED_HOSTS.
[19/Apr/2017 13:02:16] ERROR [django.security.DisallowedHost:80] Invalid HTTP_HOST header: 'ec2-34-205-53-34.compute-1.amazonaws.com'. You may need to add 'ec2-34-205-53-34.compute-1.amazonaws.com' to ALLOWED_HOSTS.
[19/Apr/2017 13:27:35] WARNING [django.request:152] Not Found: /CFIDE/administrator/
[19/Apr/2017 15:04:10] ERROR [django.security.DisallowedHost:80] Invalid HTTP_HOST header: 'httpheader.net'. You may need to add 'httpheader.net' to ALLOWED_HOSTS.
[19/Apr/2017 16:32:39] ERROR [django.security.DisallowedHost:80] Invalid HTTP_HOST header: 'check.proxyradar.com'. You may need to add 'check.proxyradar.com' to ALLOWED_HOSTS.
[19/Apr/2017 19:41:19] ERROR [django.request:135] Internal Server Error: /
Traceback (most recent call last):
  File "/home/ec2-user/envClinicFlow/local/lib/python3.5/site-packages/django/core/handlers/exception.py", line 41, in inner
    response = get_response(request)
  File "/home/ec2-user/envClinicFlow/local/lib/python3.5/site-packages/django/core/handlers/base.py", line 187, in _get_response
    response = self.process_exception_by_middleware(e, request)
  File "/home/ec2-user/envClinicFlow/local/lib/python3.5/site-packages/django/core/handlers/base.py", line 185, in _get_response
    response = wrapped_callback(request, *callback_args, **callback_kwargs)
  File "/home/ec2-user/envClinicFlow/ClinicFlow/clinicflowx/views.py", line 58, in schedulelists
    for each in result:
  File "/home/ec2-user/envClinicFlow/local/lib/python3.5/site-packages/pymongo/cursor.py", line 1114, in next
    if len(self.__data) or self._refresh():
  File "/home/ec2-user/envClinicFlow/local/lib/python3.5/site-packages/pymongo/cursor.py", line 1036, in _refresh
    self.__collation))
  File "/home/ec2-user/envClinicFlow/local/lib/python3.5/site-packages/pymongo/cursor.py", line 873, in __send_message
    **kwargs)
  File "/home/ec2-user/envClinicFlow/local/lib/python3.5/site-packages/pymongo/mongo_client.py", line 888, in _send_message_with_response
    server = topology.select_server(selector)
  File "/home/ec2-user/envClinicFlow/local/lib/python3.5/site-packages/pymongo/topology.py", line 214, in select_server
    address))
  File "/home/ec2-user/envClinicFlow/local/lib/python3.5/site-packages/pymongo/topology.py", line 189, in select_servers
    self._error_message(selector))
pymongo.errors.ServerSelectionTimeoutError: localhost:27017: [Errno 111] Connection refused
[19/Apr/2017 20:40:37] ERROR [django.security.DisallowedHost:80] Invalid HTTP_HOST header: 'check.proxyradar.com'. You may need to add 'check.proxyradar.com' to ALLOWED_HOSTS.
[20/Apr/2017 00:53:56] ERROR [django.security.DisallowedHost:80] Invalid HTTP_HOST header: 'check.proxyradar.com'. You may need to add 'check.proxyradar.com' to ALLOWED_HOSTS.
[20/Apr/2017 01:06:38] ERROR [django.request:135] Internal Server Error: /
Traceback (most recent call last):
  File "/home/ec2-user/envClinicFlow/local/lib/python3.5/site-packages/django/core/handlers/exception.py", line 41, in inner
    response = get_response(request)
  File "/home/ec2-user/envClinicFlow/local/lib/python3.5/site-packages/django/core/handlers/base.py", line 187, in _get_response
    response = self.process_exception_by_middleware(e, request)
  File "/home/ec2-user/envClinicFlow/local/lib/python3.5/site-packages/django/core/handlers/base.py", line 185, in _get_response
    response = wrapped_callback(request, *callback_args, **callback_kwargs)
  File "/home/ec2-user/envClinicFlow/ClinicFlow/clinicflowx/views.py", line 58, in schedulelists
    for each in result:
  File "/home/ec2-user/envClinicFlow/local/lib/python3.5/site-packages/pymongo/cursor.py", line 1114, in next
    if len(self.__data) or self._refresh():
  File "/home/ec2-user/envClinicFlow/local/lib/python3.5/site-packages/pymongo/cursor.py", line 1036, in _refresh
    self.__collation))
  File "/home/ec2-user/envClinicFlow/local/lib/python3.5/site-packages/pymongo/cursor.py", line 873, in __send_message
    **kwargs)
  File "/home/ec2-user/envClinicFlow/local/lib/python3.5/site-packages/pymongo/mongo_client.py", line 888, in _send_message_with_response
    server = topology.select_server(selector)
  File "/home/ec2-user/envClinicFlow/local/lib/python3.5/site-packages/pymongo/topology.py", line 214, in select_server
    address))
  File "/home/ec2-user/envClinicFlow/local/lib/python3.5/site-packages/pymongo/topology.py", line 189, in select_servers
    self._error_message(selector))
pymongo.errors.ServerSelectionTimeoutError: localhost:27017: [Errno 111] Connection refused
[20/Apr/2017 04:42:08] ERROR [django.security.DisallowedHost:80] Invalid HTTP_HOST header: 'ec2-34-205-53-34.compute-1.amazonaws.com'. You may need to add 'ec2-34-205-53-34.compute-1.amazonaws.com' to ALLOWED_HOSTS.
[20/Apr/2017 05:01:53] ERROR [django.security.DisallowedHost:80] Invalid HTTP_HOST header: 'check.proxyradar.com'. You may need to add 'check.proxyradar.com' to ALLOWED_HOSTS.
[20/Apr/2017 09:17:21] ERROR [django.security.DisallowedHost:80] Invalid HTTP_HOST header: 'check.proxyradar.com'. You may need to add 'check.proxyradar.com' to ALLOWED_HOSTS.
[20/Apr/2017 12:51:21] WARNING [django.request:152] Not Found: /mainAction.action
[20/Apr/2017 13:15:09] ERROR [django.security.DisallowedHost:80] Invalid HTTP_HOST header: 'ec2-34-205-53-34.compute-1.amazonaws.com'. You may need to add 'ec2-34-205-53-34.compute-1.amazonaws.com' to ALLOWED_HOSTS.
[20/Apr/2017 13:19:00] ERROR [django.security.DisallowedHost:80] Invalid HTTP_HOST header: 'check.proxyradar.com'. You may need to add 'check.proxyradar.com' to ALLOWED_HOSTS.
[20/Apr/2017 14:44:26] ERROR [django.request:135] Internal Server Error: /
Traceback (most recent call last):
  File "/home/ec2-user/envClinicFlow/local/lib/python3.5/site-packages/django/core/handlers/exception.py", line 41, in inner
    response = get_response(request)
  File "/home/ec2-user/envClinicFlow/local/lib/python3.5/site-packages/django/core/handlers/base.py", line 187, in _get_response
    response = self.process_exception_by_middleware(e, request)
  File "/home/ec2-user/envClinicFlow/local/lib/python3.5/site-packages/django/core/handlers/base.py", line 185, in _get_response
    response = wrapped_callback(request, *callback_args, **callback_kwargs)
  File "/home/ec2-user/envClinicFlow/ClinicFlow/clinicflowx/views.py", line 58, in schedulelists
    for each in result:
  File "/home/ec2-user/envClinicFlow/local/lib/python3.5/site-packages/pymongo/cursor.py", line 1114, in next
    if len(self.__data) or self._refresh():
  File "/home/ec2-user/envClinicFlow/local/lib/python3.5/site-packages/pymongo/cursor.py", line 1036, in _refresh
    self.__collation))
  File "/home/ec2-user/envClinicFlow/local/lib/python3.5/site-packages/pymongo/cursor.py", line 873, in __send_message
    **kwargs)
  File "/home/ec2-user/envClinicFlow/local/lib/python3.5/site-packages/pymongo/mongo_client.py", line 888, in _send_message_with_response
    server = topology.select_server(selector)
  File "/home/ec2-user/envClinicFlow/local/lib/python3.5/site-packages/pymongo/topology.py", line 214, in select_server
    address))
  File "/home/ec2-user/envClinicFlow/local/lib/python3.5/site-packages/pymongo/topology.py", line 189, in select_servers
    self._error_message(selector))
pymongo.errors.ServerSelectionTimeoutError: localhost:27017: [Errno 111] Connection refused
[20/Apr/2017 15:55:50] WARNING [django.request:152] Not Found: /mainAction.action
[20/Apr/2017 17:34:14] ERROR [django.security.DisallowedHost:80] Invalid HTTP_HOST header: 'check.proxyradar.com'. You may need to add 'check.proxyradar.com' to ALLOWED_HOSTS.
[20/Apr/2017 18:46:05] ERROR [django.security.DisallowedHost:80] Invalid HTTP_HOST header: 'ec2-34-205-53-34.compute-1.amazonaws.com'. You may need to add 'ec2-34-205-53-34.compute-1.amazonaws.com' to ALLOWED_HOSTS.
[20/Apr/2017 19:48:49] WARNING [django.request:152] Not Found: /mainAction.action
[20/Apr/2017 20:10:29] WARNING [django.request:152] Not Found: /hndUnblock.cgi
[20/Apr/2017 20:10:30] WARNING [django.request:152] Not Found: /tmUnblock.cgi
[20/Apr/2017 20:11:01] ERROR [django.request:135] Internal Server Error: /
Traceback (most recent call last):
  File "/home/ec2-user/envClinicFlow/local/lib/python3.5/site-packages/django/core/handlers/exception.py", line 41, in inner
    response = get_response(request)
  File "/home/ec2-user/envClinicFlow/local/lib/python3.5/site-packages/django/core/handlers/base.py", line 187, in _get_response
    response = self.process_exception_by_middleware(e, request)
  File "/home/ec2-user/envClinicFlow/local/lib/python3.5/site-packages/django/core/handlers/base.py", line 185, in _get_response
    response = wrapped_callback(request, *callback_args, **callback_kwargs)
  File "/home/ec2-user/envClinicFlow/ClinicFlow/clinicflowx/views.py", line 58, in schedulelists
    for each in result:
  File "/home/ec2-user/envClinicFlow/local/lib/python3.5/site-packages/pymongo/cursor.py", line 1114, in next
    if len(self.__data) or self._refresh():
  File "/home/ec2-user/envClinicFlow/local/lib/python3.5/site-packages/pymongo/cursor.py", line 1036, in _refresh
    self.__collation))
  File "/home/ec2-user/envClinicFlow/local/lib/python3.5/site-packages/pymongo/cursor.py", line 873, in __send_message
    **kwargs)
  File "/home/ec2-user/envClinicFlow/local/lib/python3.5/site-packages/pymongo/mongo_client.py", line 888, in _send_message_with_response
    server = topology.select_server(selector)
  File "/home/ec2-user/envClinicFlow/local/lib/python3.5/site-packages/pymongo/topology.py", line 214, in select_server
    address))
  File "/home/ec2-user/envClinicFlow/local/lib/python3.5/site-packages/pymongo/topology.py", line 189, in select_servers
    self._error_message(selector))
pymongo.errors.ServerSelectionTimeoutError: localhost:27017: [Errno 111] Connection refused
[20/Apr/2017 21:45:28] ERROR [django.security.DisallowedHost:80] Invalid HTTP_HOST header: 'check.proxyradar.com'. You may need to add 'check.proxyradar.com' to ALLOWED_HOSTS.
[20/Apr/2017 22:02:40] WARNING [django.request:152] Not Found: /phpmyadmin
[20/Apr/2017 22:02:40] WARNING [django.request:152] Not Found: /phpmyadmin
[20/Apr/2017 22:10:46] ERROR [django.security.DisallowedHost:80] Invalid HTTP_HOST header: 'ec2-34-205-53-34.compute-1.amazonaws.com'. You may need to add 'ec2-34-205-53-34.compute-1.amazonaws.com' to ALLOWED_HOSTS.
[21/Apr/2017 01:36:52] ERROR [django.request:135] Internal Server Error: /
Traceback (most recent call last):
  File "/home/ec2-user/envClinicFlow/local/lib/python3.5/site-packages/django/core/handlers/exception.py", line 41, in inner
    response = get_response(request)
  File "/home/ec2-user/envClinicFlow/local/lib/python3.5/site-packages/django/core/handlers/base.py", line 187, in _get_response
    response = self.process_exception_by_middleware(e, request)
  File "/home/ec2-user/envClinicFlow/local/lib/python3.5/site-packages/django/core/handlers/base.py", line 185, in _get_response
    response = wrapped_callback(request, *callback_args, **callback_kwargs)
  File "/home/ec2-user/envClinicFlow/ClinicFlow/clinicflowx/views.py", line 58, in schedulelists
    for each in result:
  File "/home/ec2-user/envClinicFlow/local/lib/python3.5/site-packages/pymongo/cursor.py", line 1114, in next
    if len(self.__data) or self._refresh():
  File "/home/ec2-user/envClinicFlow/local/lib/python3.5/site-packages/pymongo/cursor.py", line 1036, in _refresh
    self.__collation))
  File "/home/ec2-user/envClinicFlow/local/lib/python3.5/site-packages/pymongo/cursor.py", line 873, in __send_message
    **kwargs)
  File "/home/ec2-user/envClinicFlow/local/lib/python3.5/site-packages/pymongo/mongo_client.py", line 888, in _send_message_with_response
    server = topology.select_server(selector)
  File "/home/ec2-user/envClinicFlow/local/lib/python3.5/site-packages/pymongo/topology.py", line 214, in select_server
    address))
  File "/home/ec2-user/envClinicFlow/local/lib/python3.5/site-packages/pymongo/topology.py", line 189, in select_servers
    self._error_message(selector))
pymongo.errors.ServerSelectionTimeoutError: localhost:27017: [Errno 111] Connection refused
[21/Apr/2017 02:02:28] ERROR [django.security.DisallowedHost:80] Invalid HTTP_HOST header: 'check.proxyradar.com'. You may need to add 'check.proxyradar.com' to ALLOWED_HOSTS.
[21/Apr/2017 02:22:07] ERROR [django.request:135] Internal Server Error: /
Traceback (most recent call last):
  File "/home/ec2-user/envClinicFlow/local/lib/python3.5/site-packages/django/core/handlers/exception.py", line 41, in inner
    response = get_response(request)
  File "/home/ec2-user/envClinicFlow/local/lib/python3.5/site-packages/django/core/handlers/base.py", line 187, in _get_response
    response = self.process_exception_by_middleware(e, request)
  File "/home/ec2-user/envClinicFlow/local/lib/python3.5/site-packages/django/core/handlers/base.py", line 185, in _get_response
    response = wrapped_callback(request, *callback_args, **callback_kwargs)
  File "/home/ec2-user/envClinicFlow/ClinicFlow/clinicflowx/views.py", line 58, in schedulelists
    for each in result:
  File "/home/ec2-user/envClinicFlow/local/lib/python3.5/site-packages/pymongo/cursor.py", line 1114, in next
    if len(self.__data) or self._refresh():
  File "/home/ec2-user/envClinicFlow/local/lib/python3.5/site-packages/pymongo/cursor.py", line 1036, in _refresh
    self.__collation))
  File "/home/ec2-user/envClinicFlow/local/lib/python3.5/site-packages/pymongo/cursor.py", line 873, in __send_message
    **kwargs)
  File "/home/ec2-user/envClinicFlow/local/lib/python3.5/site-packages/pymongo/mongo_client.py", line 888, in _send_message_with_response
    server = topology.select_server(selector)
  File "/home/ec2-user/envClinicFlow/local/lib/python3.5/site-packages/pymongo/topology.py", line 214, in select_server
    address))
  File "/home/ec2-user/envClinicFlow/local/lib/python3.5/site-packages/pymongo/topology.py", line 189, in select_servers
    self._error_message(selector))
pymongo.errors.ServerSelectionTimeoutError: localhost:27017: [Errno 111] Connection refused
[21/Apr/2017 05:45:33] ERROR [django.security.DisallowedHost:80] Invalid HTTP_HOST header: 'ec2-34-205-53-34.compute-1.amazonaws.com'. You may need to add 'ec2-34-205-53-34.compute-1.amazonaws.com' to ALLOWED_HOSTS.
[21/Apr/2017 06:09:02] ERROR [django.security.DisallowedHost:80] Invalid HTTP_HOST header: 'check.proxyradar.com'. You may need to add 'check.proxyradar.com' to ALLOWED_HOSTS.
[21/Apr/2017 06:19:52] ERROR [django.request:135] Internal Server Error: /
Traceback (most recent call last):
  File "/home/ec2-user/envClinicFlow/local/lib/python3.5/site-packages/django/core/handlers/exception.py", line 41, in inner
    response = get_response(request)
  File "/home/ec2-user/envClinicFlow/local/lib/python3.5/site-packages/django/core/handlers/base.py", line 187, in _get_response
    response = self.process_exception_by_middleware(e, request)
  File "/home/ec2-user/envClinicFlow/local/lib/python3.5/site-packages/django/core/handlers/base.py", line 185, in _get_response
    response = wrapped_callback(request, *callback_args, **callback_kwargs)
  File "/home/ec2-user/envClinicFlow/ClinicFlow/clinicflowx/views.py", line 58, in schedulelists
    for each in result:
  File "/home/ec2-user/envClinicFlow/local/lib/python3.5/site-packages/pymongo/cursor.py", line 1114, in next
    if len(self.__data) or self._refresh():
  File "/home/ec2-user/envClinicFlow/local/lib/python3.5/site-packages/pymongo/cursor.py", line 1036, in _refresh
    self.__collation))
  File "/home/ec2-user/envClinicFlow/local/lib/python3.5/site-packages/pymongo/cursor.py", line 873, in __send_message
    **kwargs)
  File "/home/ec2-user/envClinicFlow/local/lib/python3.5/site-packages/pymongo/mongo_client.py", line 888, in _send_message_with_response
    server = topology.select_server(selector)
  File "/home/ec2-user/envClinicFlow/local/lib/python3.5/site-packages/pymongo/topology.py", line 214, in select_server
    address))
  File "/home/ec2-user/envClinicFlow/local/lib/python3.5/site-packages/pymongo/topology.py", line 189, in select_servers
    self._error_message(selector))
pymongo.errors.ServerSelectionTimeoutError: localhost:27017: [Errno 111] Connection refused
[21/Apr/2017 06:46:43] ERROR [django.security.DisallowedHost:80] Invalid HTTP_HOST header: 'ec2-34-205-53-34.compute-1.amazonaws.com'. You may need to add 'ec2-34-205-53-34.compute-1.amazonaws.com' to ALLOWED_HOSTS.
[21/Apr/2017 07:27:21] WARNING [django.request:152] Not Found: /manager/html
[21/Apr/2017 10:33:33] ERROR [django.security.DisallowedHost:80] Invalid HTTP_HOST header: 'check.proxyradar.com'. You may need to add 'check.proxyradar.com' to ALLOWED_HOSTS.
[21/Apr/2017 14:43:57] ERROR [django.security.DisallowedHost:80] Invalid HTTP_HOST header: 'check.proxyradar.com'. You may need to add 'check.proxyradar.com' to ALLOWED_HOSTS.
[21/Apr/2017 18:47:54] ERROR [django.security.DisallowedHost:80] Invalid HTTP_HOST header: 'ec2-34-205-53-34.compute-1.amazonaws.com'. You may need to add 'ec2-34-205-53-34.compute-1.amazonaws.com' to ALLOWED_HOSTS.
[21/Apr/2017 18:47:54] ERROR [django.security.DisallowedHost:80] Invalid HTTP_HOST header: 'ec2-34-205-53-34.compute-1.amazonaws.com'. You may need to add 'ec2-34-205-53-34.compute-1.amazonaws.com' to ALLOWED_HOSTS.
[21/Apr/2017 18:48:04] ERROR [django.request:135] Internal Server Error: /
Traceback (most recent call last):
  File "/home/ec2-user/envClinicFlow/local/lib/python3.5/site-packages/django/core/handlers/exception.py", line 41, in inner
    response = get_response(request)
  File "/home/ec2-user/envClinicFlow/local/lib/python3.5/site-packages/django/core/handlers/base.py", line 187, in _get_response
    response = self.process_exception_by_middleware(e, request)
  File "/home/ec2-user/envClinicFlow/local/lib/python3.5/site-packages/django/core/handlers/base.py", line 185, in _get_response
    response = wrapped_callback(request, *callback_args, **callback_kwargs)
  File "/home/ec2-user/envClinicFlow/ClinicFlow/clinicflowx/views.py", line 58, in schedulelists
    for each in result:
  File "/home/ec2-user/envClinicFlow/local/lib/python3.5/site-packages/pymongo/cursor.py", line 1114, in next
    if len(self.__data) or self._refresh():
  File "/home/ec2-user/envClinicFlow/local/lib/python3.5/site-packages/pymongo/cursor.py", line 1036, in _refresh
    self.__collation))
  File "/home/ec2-user/envClinicFlow/local/lib/python3.5/site-packages/pymongo/cursor.py", line 873, in __send_message
    **kwargs)
  File "/home/ec2-user/envClinicFlow/local/lib/python3.5/site-packages/pymongo/mongo_client.py", line 888, in _send_message_with_response
    server = topology.select_server(selector)
  File "/home/ec2-user/envClinicFlow/local/lib/python3.5/site-packages/pymongo/topology.py", line 214, in select_server
    address))
  File "/home/ec2-user/envClinicFlow/local/lib/python3.5/site-packages/pymongo/topology.py", line 189, in select_servers
    self._error_message(selector))
pymongo.errors.ServerSelectionTimeoutError: localhost:27017: [Errno 111] Connection refused
[21/Apr/2017 20:48:35] WARNING [django.request:152] Not Found: /CFIDE/administrator/
[21/Apr/2017 21:07:23] ERROR [django.security.DisallowedHost:80] Invalid HTTP_HOST header: 'clientapi.ipip.net'. You may need to add 'clientapi.ipip.net' to ALLOWED_HOSTS.
[21/Apr/2017 21:07:50] ERROR [django.request:135] Internal Server Error: /
Traceback (most recent call last):
  File "/home/ec2-user/envClinicFlow/local/lib/python3.5/site-packages/django/core/handlers/exception.py", line 41, in inner
    response = get_response(request)
  File "/home/ec2-user/envClinicFlow/local/lib/python3.5/site-packages/django/core/handlers/base.py", line 187, in _get_response
    response = self.process_exception_by_middleware(e, request)
  File "/home/ec2-user/envClinicFlow/local/lib/python3.5/site-packages/django/core/handlers/base.py", line 185, in _get_response
    response = wrapped_callback(request, *callback_args, **callback_kwargs)
  File "/home/ec2-user/envClinicFlow/ClinicFlow/clinicflowx/views.py", line 58, in schedulelists
    for each in result:
  File "/home/ec2-user/envClinicFlow/local/lib/python3.5/site-packages/pymongo/cursor.py", line 1114, in next
    if len(self.__data) or self._refresh():
  File "/home/ec2-user/envClinicFlow/local/lib/python3.5/site-packages/pymongo/cursor.py", line 1036, in _refresh
    self.__collation))
  File "/home/ec2-user/envClinicFlow/local/lib/python3.5/site-packages/pymongo/cursor.py", line 873, in __send_message
    **kwargs)
  File "/home/ec2-user/envClinicFlow/local/lib/python3.5/site-packages/pymongo/mongo_client.py", line 888, in _send_message_with_response
    server = topology.select_server(selector)
  File "/home/ec2-user/envClinicFlow/local/lib/python3.5/site-packages/pymongo/topology.py", line 214, in select_server
    address))
  File "/home/ec2-user/envClinicFlow/local/lib/python3.5/site-packages/pymongo/topology.py", line 189, in select_servers
    self._error_message(selector))
pymongo.errors.ServerSelectionTimeoutError: localhost:27017: [Errno 111] Connection refused
[21/Apr/2017 21:48:12] ERROR [django.security.DisallowedHost:80] Invalid HTTP_HOST header: 'ec2-34-205-53-34.compute-1.amazonaws.com'. You may need to add 'ec2-34-205-53-34.compute-1.amazonaws.com' to ALLOWED_HOSTS.
[22/Apr/2017 00:50:40] ERROR [django.security.DisallowedHost:80] Invalid HTTP_HOST header: 'ec2-34-205-53-34.compute-1.amazonaws.com'. You may need to add 'ec2-34-205-53-34.compute-1.amazonaws.com' to ALLOWED_HOSTS.
[22/Apr/2017 02:11:31] ERROR [django.request:135] Internal Server Error: /
Traceback (most recent call last):
  File "/home/ec2-user/envClinicFlow/local/lib/python3.5/site-packages/django/core/handlers/exception.py", line 41, in inner
    response = get_response(request)
  File "/home/ec2-user/envClinicFlow/local/lib/python3.5/site-packages/django/core/handlers/base.py", line 187, in _get_response
    response = self.process_exception_by_middleware(e, request)
  File "/home/ec2-user/envClinicFlow/local/lib/python3.5/site-packages/django/core/handlers/base.py", line 185, in _get_response
    response = wrapped_callback(request, *callback_args, **callback_kwargs)
  File "/home/ec2-user/envClinicFlow/ClinicFlow/clinicflowx/views.py", line 58, in schedulelists
    for each in result:
  File "/home/ec2-user/envClinicFlow/local/lib/python3.5/site-packages/pymongo/cursor.py", line 1114, in next
    if len(self.__data) or self._refresh():
  File "/home/ec2-user/envClinicFlow/local/lib/python3.5/site-packages/pymongo/cursor.py", line 1036, in _refresh
    self.__collation))
  File "/home/ec2-user/envClinicFlow/local/lib/python3.5/site-packages/pymongo/cursor.py", line 873, in __send_message
    **kwargs)
  File "/home/ec2-user/envClinicFlow/local/lib/python3.5/site-packages/pymongo/mongo_client.py", line 888, in _send_message_with_response
    server = topology.select_server(selector)
  File "/home/ec2-user/envClinicFlow/local/lib/python3.5/site-packages/pymongo/topology.py", line 214, in select_server
    address))
  File "/home/ec2-user/envClinicFlow/local/lib/python3.5/site-packages/pymongo/topology.py", line 189, in select_servers
    self._error_message(selector))
pymongo.errors.ServerSelectionTimeoutError: localhost:27017: [Errno 111] Connection refused
[22/Apr/2017 04:41:45] ERROR [django.security.DisallowedHost:80] Invalid HTTP_HOST header: 'clientapi.ipip.net'. You may need to add 'clientapi.ipip.net' to ALLOWED_HOSTS.
[22/Apr/2017 04:42:12] ERROR [django.request:135] Internal Server Error: /
Traceback (most recent call last):
  File "/home/ec2-user/envClinicFlow/local/lib/python3.5/site-packages/django/core/handlers/exception.py", line 41, in inner
    response = get_response(request)
  File "/home/ec2-user/envClinicFlow/local/lib/python3.5/site-packages/django/core/handlers/base.py", line 187, in _get_response
    response = self.process_exception_by_middleware(e, request)
  File "/home/ec2-user/envClinicFlow/local/lib/python3.5/site-packages/django/core/handlers/base.py", line 185, in _get_response
    response = wrapped_callback(request, *callback_args, **callback_kwargs)
  File "/home/ec2-user/envClinicFlow/ClinicFlow/clinicflowx/views.py", line 58, in schedulelists
    for each in result:
  File "/home/ec2-user/envClinicFlow/local/lib/python3.5/site-packages/pymongo/cursor.py", line 1114, in next
    if len(self.__data) or self._refresh():
  File "/home/ec2-user/envClinicFlow/local/lib/python3.5/site-packages/pymongo/cursor.py", line 1036, in _refresh
    self.__collation))
  File "/home/ec2-user/envClinicFlow/local/lib/python3.5/site-packages/pymongo/cursor.py", line 873, in __send_message
    **kwargs)
  File "/home/ec2-user/envClinicFlow/local/lib/python3.5/site-packages/pymongo/mongo_client.py", line 888, in _send_message_with_response
    server = topology.select_server(selector)
  File "/home/ec2-user/envClinicFlow/local/lib/python3.5/site-packages/pymongo/topology.py", line 214, in select_server
    address))
  File "/home/ec2-user/envClinicFlow/local/lib/python3.5/site-packages/pymongo/topology.py", line 189, in select_servers
    self._error_message(selector))
pymongo.errors.ServerSelectionTimeoutError: localhost:27017: [Errno 111] Connection refused
[22/Apr/2017 06:16:21] ERROR [django.security.DisallowedHost:80] Invalid HTTP_HOST header: 'ec2-34-205-53-34.compute-1.amazonaws.com'. You may need to add 'ec2-34-205-53-34.compute-1.amazonaws.com' to ALLOWED_HOSTS.
[22/Apr/2017 07:47:58] ERROR [django.security.DisallowedHost:80] Invalid HTTP_HOST header: 'ec2-34-205-53-34.compute-1.amazonaws.com'. You may need to add 'ec2-34-205-53-34.compute-1.amazonaws.com' to ALLOWED_HOSTS.
[22/Apr/2017 11:29:02] ERROR [django.security.DisallowedHost:80] Invalid HTTP_HOST header: 'ec2-34-205-53-34.compute-1.amazonaws.com'. You may need to add 'ec2-34-205-53-34.compute-1.amazonaws.com' to ALLOWED_HOSTS.
[22/Apr/2017 12:05:37] ERROR [django.security.DisallowedHost:80] Invalid HTTP_HOST header: 'ec2-34-205-53-34.compute-1.amazonaws.com'. You may need to add 'ec2-34-205-53-34.compute-1.amazonaws.com' to ALLOWED_HOSTS.
[22/Apr/2017 21:39:45] ERROR [django.security.DisallowedHost:80] Invalid HTTP_HOST header: 'ec2-34-205-53-34.compute-1.amazonaws.com'. You may need to add 'ec2-34-205-53-34.compute-1.amazonaws.com' to ALLOWED_HOSTS.
[23/Apr/2017 00:21:45] WARNING [django.request:152] Not Found: /muieblackcat
[23/Apr/2017 00:21:46] WARNING [django.request:152] Not Found: /scripts/setup.php
[23/Apr/2017 00:21:46] WARNING [django.request:152] Not Found: /admin/scripts/setup.php
[23/Apr/2017 00:21:46] WARNING [django.request:152] Not Found: /admin/pma/scripts/setup.php
[23/Apr/2017 00:21:46] WARNING [django.request:152] Not Found: /myadmin/scripts/setup.php
[23/Apr/2017 00:21:46] WARNING [django.request:152] Not Found: /mysql/scripts/setup.php
[23/Apr/2017 00:21:47] WARNING [django.request:152] Not Found: /phpadmin/scripts/setup.php
[23/Apr/2017 00:21:47] WARNING [django.request:152] Not Found: /pma/scripts/setup.php
[23/Apr/2017 00:21:47] WARNING [django.request:152] Not Found: /blog/scripts/setup.php
[23/Apr/2017 00:21:48] WARNING [django.request:152] Not Found: /blog/pma/scripts/setup.php
[23/Apr/2017 00:21:49] WARNING [django.request:152] Not Found: /php/phpmyadmin/scripts/setup.php
[23/Apr/2017 00:21:49] WARNING [django.request:152] Not Found: /phpmyadmin/scripts/setup.php
[23/Apr/2017 00:21:49] WARNING [django.request:152] Not Found: /phpMyAdmin2/scripts/setup.php
[23/Apr/2017 00:21:49] WARNING [django.request:152] Not Found: /dbadmin/scripts/setup.php
[23/Apr/2017 00:21:49] WARNING [django.request:152] Not Found: /dbadmin/pma/scripts/setup.php
[23/Apr/2017 00:21:49] WARNING [django.request:152] Not Found: /admin/sql/scripts/setup.php
[23/Apr/2017 00:21:50] WARNING [django.request:152] Not Found: /database/sql/scripts/setup.php
[23/Apr/2017 00:21:50] WARNING [django.request:152] Not Found: /web/phpmyadmin/scripts/setup.php
[23/Apr/2017 00:21:50] WARNING [django.request:152] Not Found: /php/scripts/setup.php
[23/Apr/2017 00:21:51] WARNING [django.request:152] Not Found: /admin/phpmyadmin/scripts/setup.php
[23/Apr/2017 00:21:51] WARNING [django.request:152] Not Found: /php/phpmyadmin/scripts/setup.php
[23/Apr/2017 00:21:51] WARNING [django.request:152] Not Found: /db/scripts/setup.php
[23/Apr/2017 00:21:51] WARNING [django.request:152] Not Found: /admin/mysql/scripts/setup.php
[23/Apr/2017 00:21:52] WARNING [django.request:152] Not Found: /admn/scripts/setup.php
[23/Apr/2017 00:21:52] WARNING [django.request:152] Not Found: /apache-default/phpmyadmin/scripts/setup.php
[23/Apr/2017 00:21:52] WARNING [django.request:152] Not Found: /blog/phpmyadmin/scripts/setup.php
[23/Apr/2017 00:21:53] WARNING [django.request:152] Not Found: /forum/phpmyadmin/scripts/setup.php
[23/Apr/2017 00:21:53] WARNING [django.request:152] Not Found: /htdocs/scripts/setup.php
[23/Apr/2017 00:21:53] WARNING [django.request:152] Not Found: /httpdocs/scripts/setup.php
[23/Apr/2017 00:21:53] WARNING [django.request:152] Not Found: /php/scripts/setup.php
[23/Apr/2017 00:21:53] WARNING [django.request:152] Not Found: /php/phpmyadmin/scripts/setup.php
[23/Apr/2017 00:21:53] WARNING [django.request:152] Not Found: /xampp/phpmyadmin/scripts/setup.php
[23/Apr/2017 00:21:54] WARNING [django.request:152] Not Found: /pmadmin/scripts/setup.php
[23/Apr/2017 00:21:54] WARNING [django.request:152] Not Found: /admn/scripts/setup.php
[23/Apr/2017 00:21:54] WARNING [django.request:152] Not Found: /websql/scripts/setup.php
[23/Apr/2017 00:21:54] WARNING [django.request:152] Not Found: /admin/scripts/setup.php
[23/Apr/2017 00:21:54] WARNING [django.request:152] Not Found: /web/sql/scripts/setup.php
[23/Apr/2017 00:21:55] WARNING [django.request:152] Not Found: /cpadmin/sql/scripts/setup.php
[23/Apr/2017 00:21:55] WARNING [django.request:152] Not Found: /cpadmin/scripts/setup.php
[23/Apr/2017 00:21:55] WARNING [django.request:152] Not Found: /cpadmindb/scripts/setup.php
[23/Apr/2017 00:21:55] WARNING [django.request:152] Not Found: /database
[23/Apr/2017 03:14:50] ERROR [django.request:135] Internal Server Error: /
Traceback (most recent call last):
  File "/home/ec2-user/envClinicFlow/local/lib/python3.5/site-packages/django/core/handlers/exception.py", line 41, in inner
    response = get_response(request)
  File "/home/ec2-user/envClinicFlow/local/lib/python3.5/site-packages/django/core/handlers/base.py", line 187, in _get_response
    response = self.process_exception_by_middleware(e, request)
  File "/home/ec2-user/envClinicFlow/local/lib/python3.5/site-packages/django/core/handlers/base.py", line 185, in _get_response
    response = wrapped_callback(request, *callback_args, **callback_kwargs)
  File "/home/ec2-user/envClinicFlow/ClinicFlow/clinicflowx/views.py", line 58, in schedulelists
    for each in result:
  File "/home/ec2-user/envClinicFlow/local/lib/python3.5/site-packages/pymongo/cursor.py", line 1114, in next
    if len(self.__data) or self._refresh():
  File "/home/ec2-user/envClinicFlow/local/lib/python3.5/site-packages/pymongo/cursor.py", line 1036, in _refresh
    self.__collation))
  File "/home/ec2-user/envClinicFlow/local/lib/python3.5/site-packages/pymongo/cursor.py", line 873, in __send_message
    **kwargs)
  File "/home/ec2-user/envClinicFlow/local/lib/python3.5/site-packages/pymongo/mongo_client.py", line 888, in _send_message_with_response
    server = topology.select_server(selector)
  File "/home/ec2-user/envClinicFlow/local/lib/python3.5/site-packages/pymongo/topology.py", line 214, in select_server
    address))
  File "/home/ec2-user/envClinicFlow/local/lib/python3.5/site-packages/pymongo/topology.py", line 189, in select_servers
    self._error_message(selector))
pymongo.errors.ServerSelectionTimeoutError: localhost:27017: [Errno 111] Connection refused
[23/Apr/2017 18:20:01] ERROR [django.request:135] Internal Server Error: /
Traceback (most recent call last):
  File "/home/ec2-user/envClinicFlow/local/lib/python3.5/site-packages/django/core/handlers/exception.py", line 41, in inner
    response = get_response(request)
  File "/home/ec2-user/envClinicFlow/local/lib/python3.5/site-packages/django/core/handlers/base.py", line 187, in _get_response
    response = self.process_exception_by_middleware(e, request)
  File "/home/ec2-user/envClinicFlow/local/lib/python3.5/site-packages/django/core/handlers/base.py", line 185, in _get_response
    response = wrapped_callback(request, *callback_args, **callback_kwargs)
  File "/home/ec2-user/envClinicFlow/ClinicFlow/clinicflowx/views.py", line 58, in schedulelists
    for each in result:
  File "/home/ec2-user/envClinicFlow/local/lib/python3.5/site-packages/pymongo/cursor.py", line 1114, in next
    if len(self.__data) or self._refresh():
  File "/home/ec2-user/envClinicFlow/local/lib/python3.5/site-packages/pymongo/cursor.py", line 1036, in _refresh
    self.__collation))
  File "/home/ec2-user/envClinicFlow/local/lib/python3.5/site-packages/pymongo/cursor.py", line 873, in __send_message
    **kwargs)
  File "/home/ec2-user/envClinicFlow/local/lib/python3.5/site-packages/pymongo/mongo_client.py", line 888, in _send_message_with_response
    server = topology.select_server(selector)
  File "/home/ec2-user/envClinicFlow/local/lib/python3.5/site-packages/pymongo/topology.py", line 214, in select_server
    address))
  File "/home/ec2-user/envClinicFlow/local/lib/python3.5/site-packages/pymongo/topology.py", line 189, in select_servers
    self._error_message(selector))
pymongo.errors.ServerSelectionTimeoutError: localhost:27017: [Errno 111] Connection refused
[23/Apr/2017 20:32:16] ERROR [django.security.DisallowedHost:80] Invalid HTTP_HOST header: 'check.proxyradar.com'. You may need to add 'check.proxyradar.com' to ALLOWED_HOSTS.
[23/Apr/2017 22:20:08] ERROR [django.security.DisallowedHost:80] Invalid HTTP_HOST header: 'ec2-34-205-53-34.compute-1.amazonaws.com'. You may need to add 'ec2-34-205-53-34.compute-1.amazonaws.com' to ALLOWED_HOSTS.
