[Thu Apr 13 18:45:29.255462 2017] [:error] [pid 2202] [client 24.146.44.164:61749] mod_wsgi (pid=2202): Target WSGI script '/home/ec2-user/envClinicFlow/ClinicFlow/ClinicFlow/wsgi.py' cannot be loaded as Python module.
[Thu Apr 13 18:45:29.255529 2017] [:error] [pid 2202] [client 24.146.44.164:61749] mod_wsgi (pid=2202): Exception occurred processing WSGI script '/home/ec2-user/envClinicFlow/ClinicFlow/ClinicFlow/wsgi.py'.
[Thu Apr 13 18:45:29.260005 2017] [:error] [pid 2202] [client 24.146.44.164:61749] Traceback (most recent call last):
[Thu Apr 13 18:45:29.260042 2017] [:error] [pid 2202] [client 24.146.44.164:61749]   File "/usr/lib64/python3.5/logging/config.py", line 558, in configure
[Thu Apr 13 18:45:29.260046 2017] [:error] [pid 2202] [client 24.146.44.164:61749]     handler = self.configure_handler(handlers[name])
[Thu Apr 13 18:45:29.260052 2017] [:error] [pid 2202] [client 24.146.44.164:61749]   File "/usr/lib64/python3.5/logging/config.py", line 731, in configure_handler
[Thu Apr 13 18:45:29.260054 2017] [:error] [pid 2202] [client 24.146.44.164:61749]     result = factory(**kwargs)
[Thu Apr 13 18:45:29.260059 2017] [:error] [pid 2202] [client 24.146.44.164:61749]   File "/usr/lib64/python3.5/logging/__init__.py", line 1008, in __init__
[Thu Apr 13 18:45:29.260061 2017] [:error] [pid 2202] [client 24.146.44.164:61749]     StreamHandler.__init__(self, self._open())
[Thu Apr 13 18:45:29.260065 2017] [:error] [pid 2202] [client 24.146.44.164:61749]   File "/usr/lib64/python3.5/logging/__init__.py", line 1037, in _open
[Thu Apr 13 18:45:29.260068 2017] [:error] [pid 2202] [client 24.146.44.164:61749]     return open(self.baseFilename, self.mode, encoding=self.encoding)
[Thu Apr 13 18:45:29.260083 2017] [:error] [pid 2202] [client 24.146.44.164:61749] PermissionError: [Errno 13] Permission denied: '/mysite.log'
[Thu Apr 13 18:45:29.260095 2017] [:error] [pid 2202] [client 24.146.44.164:61749] 
[Thu Apr 13 18:45:29.260097 2017] [:error] [pid 2202] [client 24.146.44.164:61749] During handling of the above exception, another exception occurred:
[Thu Apr 13 18:45:29.260099 2017] [:error] [pid 2202] [client 24.146.44.164:61749] 
[Thu Apr 13 18:45:29.260105 2017] [:error] [pid 2202] [client 24.146.44.164:61749] Traceback (most recent call last):
[Thu Apr 13 18:45:29.260129 2017] [:error] [pid 2202] [client 24.146.44.164:61749]   File "/home/ec2-user/envClinicFlow/ClinicFlow/ClinicFlow/wsgi.py", line 20, in <module>
[Thu Apr 13 18:45:29.260133 2017] [:error] [pid 2202] [client 24.146.44.164:61749]     application = get_wsgi_application()
[Thu Apr 13 18:45:29.260138 2017] [:error] [pid 2202] [client 24.146.44.164:61749]   File "/home/ec2-user/envClinicFlow/local/lib/python3.5/site-packages/django/core/wsgi.py", line 13, in get_wsgi_application
[Thu Apr 13 18:45:29.260140 2017] [:error] [pid 2202] [client 24.146.44.164:61749]     django.setup(set_prefix=False)
[Thu Apr 13 18:45:29.260145 2017] [:error] [pid 2202] [client 24.146.44.164:61749]   File "/home/ec2-user/envClinicFlow/local/lib/python3.5/site-packages/django/__init__.py", line 22, in setup
[Thu Apr 13 18:45:29.260147 2017] [:error] [pid 2202] [client 24.146.44.164:61749]     configure_logging(settings.LOGGING_CONFIG, settings.LOGGING)
[Thu Apr 13 18:45:29.260152 2017] [:error] [pid 2202] [client 24.146.44.164:61749]   File "/home/ec2-user/envClinicFlow/local/lib/python3.5/site-packages/django/utils/log.py", line 75, in configure_logging
[Thu Apr 13 18:45:29.260154 2017] [:error] [pid 2202] [client 24.146.44.164:61749]     logging_config_func(logging_settings)
[Thu Apr 13 18:45:29.260159 2017] [:error] [pid 2202] [client 24.146.44.164:61749]   File "/usr/lib64/python3.5/logging/config.py", line 795, in dictConfig
[Thu Apr 13 18:45:29.260161 2017] [:error] [pid 2202] [client 24.146.44.164:61749]     dictConfigClass(config).configure()
[Thu Apr 13 18:45:29.260165 2017] [:error] [pid 2202] [client 24.146.44.164:61749]   File "/usr/lib64/python3.5/logging/config.py", line 566, in configure
[Thu Apr 13 18:45:29.260167 2017] [:error] [pid 2202] [client 24.146.44.164:61749]     '%r: %s' % (name, e))
[Thu Apr 13 18:45:29.260184 2017] [:error] [pid 2202] [client 24.146.44.164:61749] ValueError: Unable to configure handler 'file': [Errno 13] Permission denied: '/mysite.log'
[Thu Apr 13 18:46:13.631175 2017] [:error] [pid 2204] [client 24.146.44.164:61750] mod_wsgi (pid=2204): Target WSGI script '/home/ec2-user/envClinicFlow/ClinicFlow/ClinicFlow/wsgi.py' cannot be loaded as Python module.
[Thu Apr 13 18:46:13.631230 2017] [:error] [pid 2204] [client 24.146.44.164:61750] mod_wsgi (pid=2204): Exception occurred processing WSGI script '/home/ec2-user/envClinicFlow/ClinicFlow/ClinicFlow/wsgi.py'.
[Thu Apr 13 18:46:13.632316 2017] [:error] [pid 2204] [client 24.146.44.164:61750] Traceback (most recent call last):
[Thu Apr 13 18:46:13.632348 2017] [:error] [pid 2204] [client 24.146.44.164:61750]   File "/usr/lib64/python3.5/logging/config.py", line 558, in configure
[Thu Apr 13 18:46:13.632352 2017] [:error] [pid 2204] [client 24.146.44.164:61750]     handler = self.configure_handler(handlers[name])
[Thu Apr 13 18:46:13.632357 2017] [:error] [pid 2204] [client 24.146.44.164:61750]   File "/usr/lib64/python3.5/logging/config.py", line 731, in configure_handler
[Thu Apr 13 18:46:13.632360 2017] [:error] [pid 2204] [client 24.146.44.164:61750]     result = factory(**kwargs)
[Thu Apr 13 18:46:13.632364 2017] [:error] [pid 2204] [client 24.146.44.164:61750]   File "/usr/lib64/python3.5/logging/__init__.py", line 1008, in __init__
[Thu Apr 13 18:46:13.632366 2017] [:error] [pid 2204] [client 24.146.44.164:61750]     StreamHandler.__init__(self, self._open())
[Thu Apr 13 18:46:13.632370 2017] [:error] [pid 2204] [client 24.146.44.164:61750]   File "/usr/lib64/python3.5/logging/__init__.py", line 1037, in _open
[Thu Apr 13 18:46:13.632373 2017] [:error] [pid 2204] [client 24.146.44.164:61750]     return open(self.baseFilename, self.mode, encoding=self.encoding)
[Thu Apr 13 18:46:13.632386 2017] [:error] [pid 2204] [client 24.146.44.164:61750] PermissionError: [Errno 13] Permission denied: '/mysite.log'
[Thu Apr 13 18:46:13.632396 2017] [:error] [pid 2204] [client 24.146.44.164:61750] 
[Thu Apr 13 18:46:13.632399 2017] [:error] [pid 2204] [client 24.146.44.164:61750] During handling of the above exception, another exception occurred:
[Thu Apr 13 18:46:13.632401 2017] [:error] [pid 2204] [client 24.146.44.164:61750] 
[Thu Apr 13 18:46:13.632406 2017] [:error] [pid 2204] [client 24.146.44.164:61750] Traceback (most recent call last):
[Thu Apr 13 18:46:13.632441 2017] [:error] [pid 2204] [client 24.146.44.164:61750]   File "/home/ec2-user/envClinicFlow/ClinicFlow/ClinicFlow/wsgi.py", line 20, in <module>
[Thu Apr 13 18:46:13.632444 2017] [:error] [pid 2204] [client 24.146.44.164:61750]     application = get_wsgi_application()
[Thu Apr 13 18:46:13.632450 2017] [:error] [pid 2204] [client 24.146.44.164:61750]   File "/home/ec2-user/envClinicFlow/local/lib/python3.5/site-packages/django/core/wsgi.py", line 13, in get_wsgi_application
[Thu Apr 13 18:46:13.632452 2017] [:error] [pid 2204] [client 24.146.44.164:61750]     django.setup(set_prefix=False)
[Thu Apr 13 18:46:13.632457 2017] [:error] [pid 2204] [client 24.146.44.164:61750]   File "/home/ec2-user/envClinicFlow/local/lib/python3.5/site-packages/django/__init__.py", line 22, in setup
[Thu Apr 13 18:46:13.632459 2017] [:error] [pid 2204] [client 24.146.44.164:61750]     configure_logging(settings.LOGGING_CONFIG, settings.LOGGING)
[Thu Apr 13 18:46:13.632464 2017] [:error] [pid 2204] [client 24.146.44.164:61750]   File "/home/ec2-user/envClinicFlow/local/lib/python3.5/site-packages/django/utils/log.py", line 75, in configure_logging
[Thu Apr 13 18:46:13.632466 2017] [:error] [pid 2204] [client 24.146.44.164:61750]     logging_config_func(logging_settings)
[Thu Apr 13 18:46:13.632483 2017] [:error] [pid 2204] [client 24.146.44.164:61750]   File "/usr/lib64/python3.5/logging/config.py", line 795, in dictConfig
[Thu Apr 13 18:46:13.632485 2017] [:error] [pid 2204] [client 24.146.44.164:61750]     dictConfigClass(config).configure()
[Thu Apr 13 18:46:13.632490 2017] [:error] [pid 2204] [client 24.146.44.164:61750]   File "/usr/lib64/python3.5/logging/config.py", line 566, in configure
[Thu Apr 13 18:46:13.632499 2017] [:error] [pid 2204] [client 24.146.44.164:61750]     '%r: %s' % (name, e))
[Thu Apr 13 18:46:13.632511 2017] [:error] [pid 2204] [client 24.146.44.164:61750] ValueError: Unable to configure handler 'file': [Errno 13] Permission denied: '/mysite.log'
[Thu Apr 13 18:58:17.848265 2017] [:error] [pid 2249] [client 24.146.44.164:61786] mod_wsgi (pid=2249): Target WSGI script '/home/ec2-user/envClinicFlow/ClinicFlow/ClinicFlow/wsgi.py' cannot be loaded as Python module.
[Thu Apr 13 18:58:17.848317 2017] [:error] [pid 2249] [client 24.146.44.164:61786] mod_wsgi (pid=2249): Exception occurred processing WSGI script '/home/ec2-user/envClinicFlow/ClinicFlow/ClinicFlow/wsgi.py'.
[Thu Apr 13 18:58:17.849405 2017] [:error] [pid 2249] [client 24.146.44.164:61786] Traceback (most recent call last):
[Thu Apr 13 18:58:17.849441 2017] [:error] [pid 2249] [client 24.146.44.164:61786]   File "/usr/lib64/python3.5/logging/config.py", line 558, in configure
[Thu Apr 13 18:58:17.849445 2017] [:error] [pid 2249] [client 24.146.44.164:61786]     handler = self.configure_handler(handlers[name])
[Thu Apr 13 18:58:17.849451 2017] [:error] [pid 2249] [client 24.146.44.164:61786]   File "/usr/lib64/python3.5/logging/config.py", line 731, in configure_handler
[Thu Apr 13 18:58:17.849454 2017] [:error] [pid 2249] [client 24.146.44.164:61786]     result = factory(**kwargs)
[Thu Apr 13 18:58:17.849458 2017] [:error] [pid 2249] [client 24.146.44.164:61786]   File "/usr/lib64/python3.5/logging/__init__.py", line 1008, in __init__
[Thu Apr 13 18:58:17.849461 2017] [:error] [pid 2249] [client 24.146.44.164:61786]     StreamHandler.__init__(self, self._open())
[Thu Apr 13 18:58:17.849466 2017] [:error] [pid 2249] [client 24.146.44.164:61786]   File "/usr/lib64/python3.5/logging/__init__.py", line 1037, in _open
[Thu Apr 13 18:58:17.849468 2017] [:error] [pid 2249] [client 24.146.44.164:61786]     return open(self.baseFilename, self.mode, encoding=self.encoding)
[Thu Apr 13 18:58:17.849484 2017] [:error] [pid 2249] [client 24.146.44.164:61786] FileNotFoundError: [Errno 2] No such file or directory: '/home/ec2-user/evnClinicFlow/ClinicFlow/mysite.log'
[Thu Apr 13 18:58:17.849493 2017] [:error] [pid 2249] [client 24.146.44.164:61786] 
[Thu Apr 13 18:58:17.849496 2017] [:error] [pid 2249] [client 24.146.44.164:61786] During handling of the above exception, another exception occurred:
[Thu Apr 13 18:58:17.849498 2017] [:error] [pid 2249] [client 24.146.44.164:61786] 
[Thu Apr 13 18:58:17.849503 2017] [:error] [pid 2249] [client 24.146.44.164:61786] Traceback (most recent call last):
[Thu Apr 13 18:58:17.849527 2017] [:error] [pid 2249] [client 24.146.44.164:61786]   File "/home/ec2-user/envClinicFlow/ClinicFlow/ClinicFlow/wsgi.py", line 20, in <module>
[Thu Apr 13 18:58:17.849530 2017] [:error] [pid 2249] [client 24.146.44.164:61786]     application = get_wsgi_application()
[Thu Apr 13 18:58:17.849536 2017] [:error] [pid 2249] [client 24.146.44.164:61786]   File "/home/ec2-user/envClinicFlow/local/lib/python3.5/site-packages/django/core/wsgi.py", line 13, in get_wsgi_application
[Thu Apr 13 18:58:17.849538 2017] [:error] [pid 2249] [client 24.146.44.164:61786]     django.setup(set_prefix=False)
[Thu Apr 13 18:58:17.849543 2017] [:error] [pid 2249] [client 24.146.44.164:61786]   File "/home/ec2-user/envClinicFlow/local/lib/python3.5/site-packages/django/__init__.py", line 22, in setup
[Thu Apr 13 18:58:17.849546 2017] [:error] [pid 2249] [client 24.146.44.164:61786]     configure_logging(settings.LOGGING_CONFIG, settings.LOGGING)
[Thu Apr 13 18:58:17.849551 2017] [:error] [pid 2249] [client 24.146.44.164:61786]   File "/home/ec2-user/envClinicFlow/local/lib/python3.5/site-packages/django/utils/log.py", line 75, in configure_logging
[Thu Apr 13 18:58:17.849553 2017] [:error] [pid 2249] [client 24.146.44.164:61786]     logging_config_func(logging_settings)
[Thu Apr 13 18:58:17.849558 2017] [:error] [pid 2249] [client 24.146.44.164:61786]   File "/usr/lib64/python3.5/logging/config.py", line 795, in dictConfig
[Thu Apr 13 18:58:17.849567 2017] [:error] [pid 2249] [client 24.146.44.164:61786]     dictConfigClass(config).configure()
[Thu Apr 13 18:58:17.849573 2017] [:error] [pid 2249] [client 24.146.44.164:61786]   File "/usr/lib64/python3.5/logging/config.py", line 566, in configure
[Thu Apr 13 18:58:17.849575 2017] [:error] [pid 2249] [client 24.146.44.164:61786]     '%r: %s' % (name, e))
[Thu Apr 13 18:58:17.849586 2017] [:error] [pid 2249] [client 24.146.44.164:61786] ValueError: Unable to configure handler 'file': [Errno 2] No such file or directory: '/home/ec2-user/evnClinicFlow/ClinicFlow/mysite.log'
[Thu Apr 13 19:00:25.608970 2017] [:error] [pid 2203] [client 24.146.44.164:61796] mod_wsgi (pid=2203): Target WSGI script '/home/ec2-user/envClinicFlow/ClinicFlow/ClinicFlow/wsgi.py' cannot be loaded as Python module., referer: http://34.205.53.34/
[Thu Apr 13 19:00:25.609027 2017] [:error] [pid 2203] [client 24.146.44.164:61796] mod_wsgi (pid=2203): Exception occurred processing WSGI script '/home/ec2-user/envClinicFlow/ClinicFlow/ClinicFlow/wsgi.py'., referer: http://34.205.53.34/
[Thu Apr 13 19:00:25.610124 2017] [:error] [pid 2203] [client 24.146.44.164:61796] Traceback (most recent call last):, referer: http://34.205.53.34/
[Thu Apr 13 19:00:25.610157 2017] [:error] [pid 2203] [client 24.146.44.164:61796]   File "/usr/lib64/python3.5/logging/config.py", line 558, in configure, referer: http://34.205.53.34/
[Thu Apr 13 19:00:25.610161 2017] [:error] [pid 2203] [client 24.146.44.164:61796]     handler = self.configure_handler(handlers[name]), referer: http://34.205.53.34/
[Thu Apr 13 19:00:25.610167 2017] [:error] [pid 2203] [client 24.146.44.164:61796]   File "/usr/lib64/python3.5/logging/config.py", line 731, in configure_handler, referer: http://34.205.53.34/
[Thu Apr 13 19:00:25.610169 2017] [:error] [pid 2203] [client 24.146.44.164:61796]     result = factory(**kwargs), referer: http://34.205.53.34/
[Thu Apr 13 19:00:25.610174 2017] [:error] [pid 2203] [client 24.146.44.164:61796]   File "/usr/lib64/python3.5/logging/__init__.py", line 1008, in __init__, referer: http://34.205.53.34/
[Thu Apr 13 19:00:25.610176 2017] [:error] [pid 2203] [client 24.146.44.164:61796]     StreamHandler.__init__(self, self._open()), referer: http://34.205.53.34/
[Thu Apr 13 19:00:25.610180 2017] [:error] [pid 2203] [client 24.146.44.164:61796]   File "/usr/lib64/python3.5/logging/__init__.py", line 1037, in _open, referer: http://34.205.53.34/
[Thu Apr 13 19:00:25.610182 2017] [:error] [pid 2203] [client 24.146.44.164:61796]     return open(self.baseFilename, self.mode, encoding=self.encoding), referer: http://34.205.53.34/
[Thu Apr 13 19:00:25.610196 2017] [:error] [pid 2203] [client 24.146.44.164:61796] PermissionError: [Errno 13] Permission denied: '/home/ec2-user/envClinicFlow/ClinicFlow/mysite.log', referer: http://34.205.53.34/
[Thu Apr 13 19:00:25.610205 2017] [:error] [pid 2203] [client 24.146.44.164:61796] , referer: http://34.205.53.34/
[Thu Apr 13 19:00:25.610207 2017] [:error] [pid 2203] [client 24.146.44.164:61796] During handling of the above exception, another exception occurred:, referer: http://34.205.53.34/
[Thu Apr 13 19:00:25.610209 2017] [:error] [pid 2203] [client 24.146.44.164:61796] , referer: http://34.205.53.34/
[Thu Apr 13 19:00:25.610214 2017] [:error] [pid 2203] [client 24.146.44.164:61796] Traceback (most recent call last):, referer: http://34.205.53.34/
[Thu Apr 13 19:00:25.610236 2017] [:error] [pid 2203] [client 24.146.44.164:61796]   File "/home/ec2-user/envClinicFlow/ClinicFlow/ClinicFlow/wsgi.py", line 20, in <module>, referer: http://34.205.53.34/
[Thu Apr 13 19:00:25.610240 2017] [:error] [pid 2203] [client 24.146.44.164:61796]     application = get_wsgi_application(), referer: http://34.205.53.34/
[Thu Apr 13 19:00:25.610245 2017] [:error] [pid 2203] [client 24.146.44.164:61796]   File "/home/ec2-user/envClinicFlow/local/lib/python3.5/site-packages/django/core/wsgi.py", line 13, in get_wsgi_application, referer: http://34.205.53.34/
[Thu Apr 13 19:00:25.610266 2017] [:error] [pid 2203] [client 24.146.44.164:61796]     django.setup(set_prefix=False), referer: http://34.205.53.34/
[Thu Apr 13 19:00:25.610272 2017] [:error] [pid 2203] [client 24.146.44.164:61796]   File "/home/ec2-user/envClinicFlow/local/lib/python3.5/site-packages/django/__init__.py", line 22, in setup, referer: http://34.205.53.34/
[Thu Apr 13 19:00:25.610275 2017] [:error] [pid 2203] [client 24.146.44.164:61796]     configure_logging(settings.LOGGING_CONFIG, settings.LOGGING), referer: http://34.205.53.34/
[Thu Apr 13 19:00:25.610279 2017] [:error] [pid 2203] [client 24.146.44.164:61796]   File "/home/ec2-user/envClinicFlow/local/lib/python3.5/site-packages/django/utils/log.py", line 75, in configure_logging, referer: http://34.205.53.34/
[Thu Apr 13 19:00:25.610282 2017] [:error] [pid 2203] [client 24.146.44.164:61796]     logging_config_func(logging_settings), referer: http://34.205.53.34/
[Thu Apr 13 19:00:25.610286 2017] [:error] [pid 2203] [client 24.146.44.164:61796]   File "/usr/lib64/python3.5/logging/config.py", line 795, in dictConfig, referer: http://34.205.53.34/
[Thu Apr 13 19:00:25.610288 2017] [:error] [pid 2203] [client 24.146.44.164:61796]     dictConfigClass(config).configure(), referer: http://34.205.53.34/
[Thu Apr 13 19:00:25.610292 2017] [:error] [pid 2203] [client 24.146.44.164:61796]   File "/usr/lib64/python3.5/logging/config.py", line 566, in configure, referer: http://34.205.53.34/
[Thu Apr 13 19:00:25.610294 2017] [:error] [pid 2203] [client 24.146.44.164:61796]     '%r: %s' % (name, e)), referer: http://34.205.53.34/
[Thu Apr 13 19:00:25.610305 2017] [:error] [pid 2203] [client 24.146.44.164:61796] ValueError: Unable to configure handler 'file': [Errno 13] Permission denied: '/home/ec2-user/envClinicFlow/ClinicFlow/mysite.log', referer: http://34.205.53.34/
[Thu Apr 13 19:00:27.846933 2017] [:error] [pid 2200] [client 24.146.44.164:61797] mod_wsgi (pid=2200): Target WSGI script '/home/ec2-user/envClinicFlow/ClinicFlow/ClinicFlow/wsgi.py' cannot be loaded as Python module.
[Thu Apr 13 19:00:27.846981 2017] [:error] [pid 2200] [client 24.146.44.164:61797] mod_wsgi (pid=2200): Exception occurred processing WSGI script '/home/ec2-user/envClinicFlow/ClinicFlow/ClinicFlow/wsgi.py'.
[Thu Apr 13 19:00:27.848057 2017] [:error] [pid 2200] [client 24.146.44.164:61797] Traceback (most recent call last):
[Thu Apr 13 19:00:27.848088 2017] [:error] [pid 2200] [client 24.146.44.164:61797]   File "/usr/lib64/python3.5/logging/config.py", line 558, in configure
[Thu Apr 13 19:00:27.848092 2017] [:error] [pid 2200] [client 24.146.44.164:61797]     handler = self.configure_handler(handlers[name])
[Thu Apr 13 19:00:27.848097 2017] [:error] [pid 2200] [client 24.146.44.164:61797]   File "/usr/lib64/python3.5/logging/config.py", line 731, in configure_handler
[Thu Apr 13 19:00:27.848099 2017] [:error] [pid 2200] [client 24.146.44.164:61797]     result = factory(**kwargs)
[Thu Apr 13 19:00:27.848103 2017] [:error] [pid 2200] [client 24.146.44.164:61797]   File "/usr/lib64/python3.5/logging/__init__.py", line 1008, in __init__
[Thu Apr 13 19:00:27.848105 2017] [:error] [pid 2200] [client 24.146.44.164:61797]     StreamHandler.__init__(self, self._open())
[Thu Apr 13 19:00:27.848109 2017] [:error] [pid 2200] [client 24.146.44.164:61797]   File "/usr/lib64/python3.5/logging/__init__.py", line 1037, in _open
[Thu Apr 13 19:00:27.848111 2017] [:error] [pid 2200] [client 24.146.44.164:61797]     return open(self.baseFilename, self.mode, encoding=self.encoding)
[Thu Apr 13 19:00:27.848125 2017] [:error] [pid 2200] [client 24.146.44.164:61797] PermissionError: [Errno 13] Permission denied: '/home/ec2-user/envClinicFlow/ClinicFlow/mysite.log'
[Thu Apr 13 19:00:27.848134 2017] [:error] [pid 2200] [client 24.146.44.164:61797] 
[Thu Apr 13 19:00:27.848136 2017] [:error] [pid 2200] [client 24.146.44.164:61797] During handling of the above exception, another exception occurred:
[Thu Apr 13 19:00:27.848137 2017] [:error] [pid 2200] [client 24.146.44.164:61797] 
[Thu Apr 13 19:00:27.848150 2017] [:error] [pid 2200] [client 24.146.44.164:61797] Traceback (most recent call last):
[Thu Apr 13 19:00:27.848173 2017] [:error] [pid 2200] [client 24.146.44.164:61797]   File "/home/ec2-user/envClinicFlow/ClinicFlow/ClinicFlow/wsgi.py", line 20, in <module>
[Thu Apr 13 19:00:27.848175 2017] [:error] [pid 2200] [client 24.146.44.164:61797]     application = get_wsgi_application()
[Thu Apr 13 19:00:27.848180 2017] [:error] [pid 2200] [client 24.146.44.164:61797]   File "/home/ec2-user/envClinicFlow/local/lib/python3.5/site-packages/django/core/wsgi.py", line 13, in get_wsgi_application
[Thu Apr 13 19:00:27.848182 2017] [:error] [pid 2200] [client 24.146.44.164:61797]     django.setup(set_prefix=False)
[Thu Apr 13 19:00:27.848186 2017] [:error] [pid 2200] [client 24.146.44.164:61797]   File "/home/ec2-user/envClinicFlow/local/lib/python3.5/site-packages/django/__init__.py", line 22, in setup
[Thu Apr 13 19:00:27.848188 2017] [:error] [pid 2200] [client 24.146.44.164:61797]     configure_logging(settings.LOGGING_CONFIG, settings.LOGGING)
[Thu Apr 13 19:00:27.848192 2017] [:error] [pid 2200] [client 24.146.44.164:61797]   File "/home/ec2-user/envClinicFlow/local/lib/python3.5/site-packages/django/utils/log.py", line 75, in configure_logging
[Thu Apr 13 19:00:27.848194 2017] [:error] [pid 2200] [client 24.146.44.164:61797]     logging_config_func(logging_settings)
[Thu Apr 13 19:00:27.848198 2017] [:error] [pid 2200] [client 24.146.44.164:61797]   File "/usr/lib64/python3.5/logging/config.py", line 795, in dictConfig
[Thu Apr 13 19:00:27.848200 2017] [:error] [pid 2200] [client 24.146.44.164:61797]     dictConfigClass(config).configure()
[Thu Apr 13 19:00:27.848204 2017] [:error] [pid 2200] [client 24.146.44.164:61797]   File "/usr/lib64/python3.5/logging/config.py", line 566, in configure
[Thu Apr 13 19:00:27.848205 2017] [:error] [pid 2200] [client 24.146.44.164:61797]     '%r: %s' % (name, e))
[Thu Apr 13 19:00:27.848215 2017] [:error] [pid 2200] [client 24.146.44.164:61797] ValueError: Unable to configure handler 'file': [Errno 13] Permission denied: '/home/ec2-user/envClinicFlow/ClinicFlow/mysite.log'
[Thu Apr 13 19:02:49.196297 2017] [:error] [pid 2202] [client 24.146.44.164:61804] mod_wsgi (pid=2202): Target WSGI script '/home/ec2-user/envClinicFlow/ClinicFlow/ClinicFlow/wsgi.py' cannot be loaded as Python module.
[Thu Apr 13 19:02:49.196349 2017] [:error] [pid 2202] [client 24.146.44.164:61804] mod_wsgi (pid=2202): Exception occurred processing WSGI script '/home/ec2-user/envClinicFlow/ClinicFlow/ClinicFlow/wsgi.py'.
[Thu Apr 13 19:02:49.196511 2017] [:error] [pid 2202] [client 24.146.44.164:61804] Traceback (most recent call last):
[Thu Apr 13 19:02:49.196545 2017] [:error] [pid 2202] [client 24.146.44.164:61804]   File "/usr/lib64/python3.5/logging/config.py", line 558, in configure
[Thu Apr 13 19:02:49.196549 2017] [:error] [pid 2202] [client 24.146.44.164:61804]     handler = self.configure_handler(handlers[name])
[Thu Apr 13 19:02:49.196556 2017] [:error] [pid 2202] [client 24.146.44.164:61804]   File "/usr/lib64/python3.5/logging/config.py", line 731, in configure_handler
[Thu Apr 13 19:02:49.196558 2017] [:error] [pid 2202] [client 24.146.44.164:61804]     result = factory(**kwargs)
[Thu Apr 13 19:02:49.196563 2017] [:error] [pid 2202] [client 24.146.44.164:61804]   File "/usr/lib64/python3.5/logging/__init__.py", line 1008, in __init__
[Thu Apr 13 19:02:49.196565 2017] [:error] [pid 2202] [client 24.146.44.164:61804]     StreamHandler.__init__(self, self._open())
[Thu Apr 13 19:02:49.196570 2017] [:error] [pid 2202] [client 24.146.44.164:61804]   File "/usr/lib64/python3.5/logging/__init__.py", line 1037, in _open
[Thu Apr 13 19:02:49.196573 2017] [:error] [pid 2202] [client 24.146.44.164:61804]     return open(self.baseFilename, self.mode, encoding=self.encoding)
[Thu Apr 13 19:02:49.196587 2017] [:error] [pid 2202] [client 24.146.44.164:61804] PermissionError: [Errno 13] Permission denied: '/mysite.log'
[Thu Apr 13 19:02:49.196594 2017] [:error] [pid 2202] [client 24.146.44.164:61804] 
[Thu Apr 13 19:02:49.196605 2017] [:error] [pid 2202] [client 24.146.44.164:61804] During handling of the above exception, another exception occurred:
[Thu Apr 13 19:02:49.196607 2017] [:error] [pid 2202] [client 24.146.44.164:61804] 
[Thu Apr 13 19:02:49.196612 2017] [:error] [pid 2202] [client 24.146.44.164:61804] Traceback (most recent call last):
[Thu Apr 13 19:02:49.196637 2017] [:error] [pid 2202] [client 24.146.44.164:61804]   File "/home/ec2-user/envClinicFlow/ClinicFlow/ClinicFlow/wsgi.py", line 20, in <module>
[Thu Apr 13 19:02:49.196640 2017] [:error] [pid 2202] [client 24.146.44.164:61804]     application = get_wsgi_application()
[Thu Apr 13 19:02:49.196645 2017] [:error] [pid 2202] [client 24.146.44.164:61804]   File "/home/ec2-user/envClinicFlow/local/lib/python3.5/site-packages/django/core/wsgi.py", line 13, in get_wsgi_application
[Thu Apr 13 19:02:49.196648 2017] [:error] [pid 2202] [client 24.146.44.164:61804]     django.setup(set_prefix=False)
[Thu Apr 13 19:02:49.196653 2017] [:error] [pid 2202] [client 24.146.44.164:61804]   File "/home/ec2-user/envClinicFlow/local/lib/python3.5/site-packages/django/__init__.py", line 22, in setup
[Thu Apr 13 19:02:49.196655 2017] [:error] [pid 2202] [client 24.146.44.164:61804]     configure_logging(settings.LOGGING_CONFIG, settings.LOGGING)
[Thu Apr 13 19:02:49.196660 2017] [:error] [pid 2202] [client 24.146.44.164:61804]   File "/home/ec2-user/envClinicFlow/local/lib/python3.5/site-packages/django/utils/log.py", line 75, in configure_logging
[Thu Apr 13 19:02:49.196662 2017] [:error] [pid 2202] [client 24.146.44.164:61804]     logging_config_func(logging_settings)
[Thu Apr 13 19:02:49.196666 2017] [:error] [pid 2202] [client 24.146.44.164:61804]   File "/usr/lib64/python3.5/logging/config.py", line 795, in dictConfig
[Thu Apr 13 19:02:49.196668 2017] [:error] [pid 2202] [client 24.146.44.164:61804]     dictConfigClass(config).configure()
[Thu Apr 13 19:02:49.196672 2017] [:error] [pid 2202] [client 24.146.44.164:61804]   File "/usr/lib64/python3.5/logging/config.py", line 566, in configure
[Thu Apr 13 19:02:49.196674 2017] [:error] [pid 2202] [client 24.146.44.164:61804]     '%r: %s' % (name, e))
[Thu Apr 13 19:02:49.196684 2017] [:error] [pid 2202] [client 24.146.44.164:61804] ValueError: Unable to configure handler 'file': [Errno 13] Permission denied: '/mysite.log'
[Thu Apr 13 19:02:50.642262 2017] [:error] [pid 2204] [client 24.146.44.164:61805] mod_wsgi (pid=2204): Target WSGI script '/home/ec2-user/envClinicFlow/ClinicFlow/ClinicFlow/wsgi.py' cannot be loaded as Python module.
[Thu Apr 13 19:02:50.642308 2017] [:error] [pid 2204] [client 24.146.44.164:61805] mod_wsgi (pid=2204): Exception occurred processing WSGI script '/home/ec2-user/envClinicFlow/ClinicFlow/ClinicFlow/wsgi.py'.
[Thu Apr 13 19:02:50.642473 2017] [:error] [pid 2204] [client 24.146.44.164:61805] Traceback (most recent call last):
[Thu Apr 13 19:02:50.642506 2017] [:error] [pid 2204] [client 24.146.44.164:61805]   File "/usr/lib64/python3.5/logging/config.py", line 558, in configure
[Thu Apr 13 19:02:50.642510 2017] [:error] [pid 2204] [client 24.146.44.164:61805]     handler = self.configure_handler(handlers[name])
[Thu Apr 13 19:02:50.642516 2017] [:error] [pid 2204] [client 24.146.44.164:61805]   File "/usr/lib64/python3.5/logging/config.py", line 731, in configure_handler
[Thu Apr 13 19:02:50.642518 2017] [:error] [pid 2204] [client 24.146.44.164:61805]     result = factory(**kwargs)
[Thu Apr 13 19:02:50.642535 2017] [:error] [pid 2204] [client 24.146.44.164:61805]   File "/usr/lib64/python3.5/logging/__init__.py", line 1008, in __init__
[Thu Apr 13 19:02:50.642537 2017] [:error] [pid 2204] [client 24.146.44.164:61805]     StreamHandler.__init__(self, self._open())
[Thu Apr 13 19:02:50.642555 2017] [:error] [pid 2204] [client 24.146.44.164:61805]   File "/usr/lib64/python3.5/logging/__init__.py", line 1037, in _open
[Thu Apr 13 19:02:50.642557 2017] [:error] [pid 2204] [client 24.146.44.164:61805]     return open(self.baseFilename, self.mode, encoding=self.encoding)
[Thu Apr 13 19:02:50.642570 2017] [:error] [pid 2204] [client 24.146.44.164:61805] PermissionError: [Errno 13] Permission denied: '/mysite.log'
[Thu Apr 13 19:02:50.642585 2017] [:error] [pid 2204] [client 24.146.44.164:61805] 
[Thu Apr 13 19:02:50.642588 2017] [:error] [pid 2204] [client 24.146.44.164:61805] During handling of the above exception, another exception occurred:
[Thu Apr 13 19:02:50.642589 2017] [:error] [pid 2204] [client 24.146.44.164:61805] 
[Thu Apr 13 19:02:50.642593 2017] [:error] [pid 2204] [client 24.146.44.164:61805] Traceback (most recent call last):
[Thu Apr 13 19:02:50.642616 2017] [:error] [pid 2204] [client 24.146.44.164:61805]   File "/home/ec2-user/envClinicFlow/ClinicFlow/ClinicFlow/wsgi.py", line 20, in <module>
[Thu Apr 13 19:02:50.642619 2017] [:error] [pid 2204] [client 24.146.44.164:61805]     application = get_wsgi_application()
[Thu Apr 13 19:02:50.642624 2017] [:error] [pid 2204] [client 24.146.44.164:61805]   File "/home/ec2-user/envClinicFlow/local/lib/python3.5/site-packages/django/core/wsgi.py", line 13, in get_wsgi_application
[Thu Apr 13 19:02:50.642626 2017] [:error] [pid 2204] [client 24.146.44.164:61805]     django.setup(set_prefix=False)
[Thu Apr 13 19:02:50.642631 2017] [:error] [pid 2204] [client 24.146.44.164:61805]   File "/home/ec2-user/envClinicFlow/local/lib/python3.5/site-packages/django/__init__.py", line 22, in setup
[Thu Apr 13 19:02:50.642633 2017] [:error] [pid 2204] [client 24.146.44.164:61805]     configure_logging(settings.LOGGING_CONFIG, settings.LOGGING)
[Thu Apr 13 19:02:50.642637 2017] [:error] [pid 2204] [client 24.146.44.164:61805]   File "/home/ec2-user/envClinicFlow/local/lib/python3.5/site-packages/django/utils/log.py", line 75, in configure_logging
[Thu Apr 13 19:02:50.642639 2017] [:error] [pid 2204] [client 24.146.44.164:61805]     logging_config_func(logging_settings)
[Thu Apr 13 19:02:50.642643 2017] [:error] [pid 2204] [client 24.146.44.164:61805]   File "/usr/lib64/python3.5/logging/config.py", line 795, in dictConfig
[Thu Apr 13 19:02:50.642645 2017] [:error] [pid 2204] [client 24.146.44.164:61805]     dictConfigClass(config).configure()
[Thu Apr 13 19:02:50.642648 2017] [:error] [pid 2204] [client 24.146.44.164:61805]   File "/usr/lib64/python3.5/logging/config.py", line 566, in configure
[Thu Apr 13 19:02:50.642650 2017] [:error] [pid 2204] [client 24.146.44.164:61805]     '%r: %s' % (name, e))
[Thu Apr 13 19:02:50.642670 2017] [:error] [pid 2204] [client 24.146.44.164:61805] ValueError: Unable to configure handler 'file': [Errno 13] Permission denied: '/mysite.log'
[Thu Apr 13 19:02:51.754742 2017] [:error] [pid 2249] [client 24.146.44.164:61806] mod_wsgi (pid=2249): Target WSGI script '/home/ec2-user/envClinicFlow/ClinicFlow/ClinicFlow/wsgi.py' cannot be loaded as Python module.
[Thu Apr 13 19:02:51.754788 2017] [:error] [pid 2249] [client 24.146.44.164:61806] mod_wsgi (pid=2249): Exception occurred processing WSGI script '/home/ec2-user/envClinicFlow/ClinicFlow/ClinicFlow/wsgi.py'.
[Thu Apr 13 19:02:51.754958 2017] [:error] [pid 2249] [client 24.146.44.164:61806] Traceback (most recent call last):
[Thu Apr 13 19:02:51.755002 2017] [:error] [pid 2249] [client 24.146.44.164:61806]   File "/usr/lib64/python3.5/logging/config.py", line 558, in configure
[Thu Apr 13 19:02:51.755017 2017] [:error] [pid 2249] [client 24.146.44.164:61806]     handler = self.configure_handler(handlers[name])
[Thu Apr 13 19:02:51.755023 2017] [:error] [pid 2249] [client 24.146.44.164:61806]   File "/usr/lib64/python3.5/logging/config.py", line 731, in configure_handler
[Thu Apr 13 19:02:51.755026 2017] [:error] [pid 2249] [client 24.146.44.164:61806]     result = factory(**kwargs)
[Thu Apr 13 19:02:51.755030 2017] [:error] [pid 2249] [client 24.146.44.164:61806]   File "/usr/lib64/python3.5/logging/__init__.py", line 1008, in __init__
[Thu Apr 13 19:02:51.755032 2017] [:error] [pid 2249] [client 24.146.44.164:61806]     StreamHandler.__init__(self, self._open())
[Thu Apr 13 19:02:51.755037 2017] [:error] [pid 2249] [client 24.146.44.164:61806]   File "/usr/lib64/python3.5/logging/__init__.py", line 1037, in _open
[Thu Apr 13 19:02:51.755046 2017] [:error] [pid 2249] [client 24.146.44.164:61806]     return open(self.baseFilename, self.mode, encoding=self.encoding)
[Thu Apr 13 19:02:51.755062 2017] [:error] [pid 2249] [client 24.146.44.164:61806] FileNotFoundError: [Errno 2] No such file or directory: '/home/ec2-user/evnClinicFlow/ClinicFlow/mysite.log'
[Thu Apr 13 19:02:51.755069 2017] [:error] [pid 2249] [client 24.146.44.164:61806] 
[Thu Apr 13 19:02:51.755071 2017] [:error] [pid 2249] [client 24.146.44.164:61806] During handling of the above exception, another exception occurred:
[Thu Apr 13 19:02:51.755073 2017] [:error] [pid 2249] [client 24.146.44.164:61806] 
[Thu Apr 13 19:02:51.755077 2017] [:error] [pid 2249] [client 24.146.44.164:61806] Traceback (most recent call last):
[Thu Apr 13 19:02:51.755105 2017] [:error] [pid 2249] [client 24.146.44.164:61806]   File "/home/ec2-user/envClinicFlow/ClinicFlow/ClinicFlow/wsgi.py", line 20, in <module>
[Thu Apr 13 19:02:51.755108 2017] [:error] [pid 2249] [client 24.146.44.164:61806]     application = get_wsgi_application()
[Thu Apr 13 19:02:51.755113 2017] [:error] [pid 2249] [client 24.146.44.164:61806]   File "/home/ec2-user/envClinicFlow/local/lib/python3.5/site-packages/django/core/wsgi.py", line 13, in get_wsgi_application
[Thu Apr 13 19:02:51.755115 2017] [:error] [pid 2249] [client 24.146.44.164:61806]     django.setup(set_prefix=False)
[Thu Apr 13 19:02:51.755120 2017] [:error] [pid 2249] [client 24.146.44.164:61806]   File "/home/ec2-user/envClinicFlow/local/lib/python3.5/site-packages/django/__init__.py", line 22, in setup
[Thu Apr 13 19:02:51.755122 2017] [:error] [pid 2249] [client 24.146.44.164:61806]     configure_logging(settings.LOGGING_CONFIG, settings.LOGGING)
[Thu Apr 13 19:02:51.755126 2017] [:error] [pid 2249] [client 24.146.44.164:61806]   File "/home/ec2-user/envClinicFlow/local/lib/python3.5/site-packages/django/utils/log.py", line 75, in configure_logging
[Thu Apr 13 19:02:51.755128 2017] [:error] [pid 2249] [client 24.146.44.164:61806]     logging_config_func(logging_settings)
[Thu Apr 13 19:02:51.755133 2017] [:error] [pid 2249] [client 24.146.44.164:61806]   File "/usr/lib64/python3.5/logging/config.py", line 795, in dictConfig
[Thu Apr 13 19:02:51.755135 2017] [:error] [pid 2249] [client 24.146.44.164:61806]     dictConfigClass(config).configure()
[Thu Apr 13 19:02:51.755139 2017] [:error] [pid 2249] [client 24.146.44.164:61806]   File "/usr/lib64/python3.5/logging/config.py", line 566, in configure
[Thu Apr 13 19:02:51.755141 2017] [:error] [pid 2249] [client 24.146.44.164:61806]     '%r: %s' % (name, e))
[Thu Apr 13 19:02:51.755150 2017] [:error] [pid 2249] [client 24.146.44.164:61806] ValueError: Unable to configure handler 'file': [Errno 2] No such file or directory: '/home/ec2-user/evnClinicFlow/ClinicFlow/mysite.log'
[Thu Apr 13 21:17:21.960023 2017] [:error] [pid 2202] [client 24.146.44.164:62488] mod_wsgi (pid=2202): Target WSGI script '/home/ec2-user/envClinicFlow/ClinicFlow/ClinicFlow/wsgi.py' cannot be loaded as Python module.
[Thu Apr 13 21:17:21.960072 2017] [:error] [pid 2202] [client 24.146.44.164:62488] mod_wsgi (pid=2202): Exception occurred processing WSGI script '/home/ec2-user/envClinicFlow/ClinicFlow/ClinicFlow/wsgi.py'.
[Thu Apr 13 21:17:21.960224 2017] [:error] [pid 2202] [client 24.146.44.164:62488] Traceback (most recent call last):
[Thu Apr 13 21:17:21.960260 2017] [:error] [pid 2202] [client 24.146.44.164:62488]   File "/usr/lib64/python3.5/logging/config.py", line 558, in configure
[Thu Apr 13 21:17:21.960264 2017] [:error] [pid 2202] [client 24.146.44.164:62488]     handler = self.configure_handler(handlers[name])
[Thu Apr 13 21:17:21.960270 2017] [:error] [pid 2202] [client 24.146.44.164:62488]   File "/usr/lib64/python3.5/logging/config.py", line 731, in configure_handler
[Thu Apr 13 21:17:21.960272 2017] [:error] [pid 2202] [client 24.146.44.164:62488]     result = factory(**kwargs)
[Thu Apr 13 21:17:21.960277 2017] [:error] [pid 2202] [client 24.146.44.164:62488]   File "/usr/lib64/python3.5/logging/__init__.py", line 1008, in __init__
[Thu Apr 13 21:17:21.960286 2017] [:error] [pid 2202] [client 24.146.44.164:62488]     StreamHandler.__init__(self, self._open())
[Thu Apr 13 21:17:21.960292 2017] [:error] [pid 2202] [client 24.146.44.164:62488]   File "/usr/lib64/python3.5/logging/__init__.py", line 1037, in _open
[Thu Apr 13 21:17:21.960294 2017] [:error] [pid 2202] [client 24.146.44.164:62488]     return open(self.baseFilename, self.mode, encoding=self.encoding)
[Thu Apr 13 21:17:21.960333 2017] [:error] [pid 2202] [client 24.146.44.164:62488] PermissionError: [Errno 13] Permission denied: '/mysite.log'
[Thu Apr 13 21:17:21.960343 2017] [:error] [pid 2202] [client 24.146.44.164:62488] 
[Thu Apr 13 21:17:21.960345 2017] [:error] [pid 2202] [client 24.146.44.164:62488] During handling of the above exception, another exception occurred:
[Thu Apr 13 21:17:21.960347 2017] [:error] [pid 2202] [client 24.146.44.164:62488] 
[Thu Apr 13 21:17:21.960351 2017] [:error] [pid 2202] [client 24.146.44.164:62488] Traceback (most recent call last):
[Thu Apr 13 21:17:21.960376 2017] [:error] [pid 2202] [client 24.146.44.164:62488]   File "/home/ec2-user/envClinicFlow/ClinicFlow/ClinicFlow/wsgi.py", line 20, in <module>
[Thu Apr 13 21:17:21.960379 2017] [:error] [pid 2202] [client 24.146.44.164:62488]     application = get_wsgi_application()
[Thu Apr 13 21:17:21.960384 2017] [:error] [pid 2202] [client 24.146.44.164:62488]   File "/home/ec2-user/envClinicFlow/local/lib/python3.5/site-packages/django/core/wsgi.py", line 13, in get_wsgi_application
[Thu Apr 13 21:17:21.960386 2017] [:error] [pid 2202] [client 24.146.44.164:62488]     django.setup(set_prefix=False)
[Thu Apr 13 21:17:21.960391 2017] [:error] [pid 2202] [client 24.146.44.164:62488]   File "/home/ec2-user/envClinicFlow/local/lib/python3.5/site-packages/django/__init__.py", line 22, in setup
[Thu Apr 13 21:17:21.960393 2017] [:error] [pid 2202] [client 24.146.44.164:62488]     configure_logging(settings.LOGGING_CONFIG, settings.LOGGING)
[Thu Apr 13 21:17:21.960397 2017] [:error] [pid 2202] [client 24.146.44.164:62488]   File "/home/ec2-user/envClinicFlow/local/lib/python3.5/site-packages/django/utils/log.py", line 75, in configure_logging
[Thu Apr 13 21:17:21.960399 2017] [:error] [pid 2202] [client 24.146.44.164:62488]     logging_config_func(logging_settings)
[Thu Apr 13 21:17:21.960403 2017] [:error] [pid 2202] [client 24.146.44.164:62488]   File "/usr/lib64/python3.5/logging/config.py", line 795, in dictConfig
[Thu Apr 13 21:17:21.960405 2017] [:error] [pid 2202] [client 24.146.44.164:62488]     dictConfigClass(config).configure()
[Thu Apr 13 21:17:21.960409 2017] [:error] [pid 2202] [client 24.146.44.164:62488]   File "/usr/lib64/python3.5/logging/config.py", line 566, in configure
[Thu Apr 13 21:17:21.960411 2017] [:error] [pid 2202] [client 24.146.44.164:62488]     '%r: %s' % (name, e))
[Thu Apr 13 21:17:21.960420 2017] [:error] [pid 2202] [client 24.146.44.164:62488] ValueError: Unable to configure handler 'file': [Errno 13] Permission denied: '/mysite.log'
[Thu Apr 13 21:17:39.433147 2017] [:error] [pid 2204] [client 24.146.44.164:62492] mod_wsgi (pid=2204): Target WSGI script '/home/ec2-user/envClinicFlow/ClinicFlow/ClinicFlow/wsgi.py' cannot be loaded as Python module.
[Thu Apr 13 21:17:39.433259 2017] [:error] [pid 2204] [client 24.146.44.164:62492] mod_wsgi (pid=2204): Exception occurred processing WSGI script '/home/ec2-user/envClinicFlow/ClinicFlow/ClinicFlow/wsgi.py'.
[Thu Apr 13 21:17:39.433475 2017] [:error] [pid 2204] [client 24.146.44.164:62492] Traceback (most recent call last):
[Thu Apr 13 21:17:39.433517 2017] [:error] [pid 2204] [client 24.146.44.164:62492]   File "/usr/lib64/python3.5/logging/config.py", line 558, in configure
[Thu Apr 13 21:17:39.433521 2017] [:error] [pid 2204] [client 24.146.44.164:62492]     handler = self.configure_handler(handlers[name])
[Thu Apr 13 21:17:39.433529 2017] [:error] [pid 2204] [client 24.146.44.164:62492]   File "/usr/lib64/python3.5/logging/config.py", line 731, in configure_handler
[Thu Apr 13 21:17:39.433531 2017] [:error] [pid 2204] [client 24.146.44.164:62492]     result = factory(**kwargs)
[Thu Apr 13 21:17:39.433549 2017] [:error] [pid 2204] [client 24.146.44.164:62492]   File "/usr/lib64/python3.5/logging/__init__.py", line 1008, in __init__
[Thu Apr 13 21:17:39.433566 2017] [:error] [pid 2204] [client 24.146.44.164:62492]     StreamHandler.__init__(self, self._open())
[Thu Apr 13 21:17:39.433572 2017] [:error] [pid 2204] [client 24.146.44.164:62492]   File "/usr/lib64/python3.5/logging/__init__.py", line 1037, in _open
[Thu Apr 13 21:17:39.433575 2017] [:error] [pid 2204] [client 24.146.44.164:62492]     return open(self.baseFilename, self.mode, encoding=self.encoding)
[Thu Apr 13 21:17:39.433594 2017] [:error] [pid 2204] [client 24.146.44.164:62492] PermissionError: [Errno 13] Permission denied: '/mysite.log'
[Thu Apr 13 21:17:39.433603 2017] [:error] [pid 2204] [client 24.146.44.164:62492] 
[Thu Apr 13 21:17:39.433605 2017] [:error] [pid 2204] [client 24.146.44.164:62492] During handling of the above exception, another exception occurred:
[Thu Apr 13 21:17:39.433607 2017] [:error] [pid 2204] [client 24.146.44.164:62492] 
[Thu Apr 13 21:17:39.433612 2017] [:error] [pid 2204] [client 24.146.44.164:62492] Traceback (most recent call last):
[Thu Apr 13 21:17:39.433642 2017] [:error] [pid 2204] [client 24.146.44.164:62492]   File "/home/ec2-user/envClinicFlow/ClinicFlow/ClinicFlow/wsgi.py", line 20, in <module>
[Thu Apr 13 21:17:39.433646 2017] [:error] [pid 2204] [client 24.146.44.164:62492]     application = get_wsgi_application()
[Thu Apr 13 21:17:39.433652 2017] [:error] [pid 2204] [client 24.146.44.164:62492]   File "/home/ec2-user/envClinicFlow/local/lib/python3.5/site-packages/django/core/wsgi.py", line 13, in get_wsgi_application
[Thu Apr 13 21:17:39.433654 2017] [:error] [pid 2204] [client 24.146.44.164:62492]     django.setup(set_prefix=False)
[Thu Apr 13 21:17:39.433660 2017] [:error] [pid 2204] [client 24.146.44.164:62492]   File "/home/ec2-user/envClinicFlow/local/lib/python3.5/site-packages/django/__init__.py", line 22, in setup
[Thu Apr 13 21:17:39.433663 2017] [:error] [pid 2204] [client 24.146.44.164:62492]     configure_logging(settings.LOGGING_CONFIG, settings.LOGGING)
[Thu Apr 13 21:17:39.433668 2017] [:error] [pid 2204] [client 24.146.44.164:62492]   File "/home/ec2-user/envClinicFlow/local/lib/python3.5/site-packages/django/utils/log.py", line 75, in configure_logging
[Thu Apr 13 21:17:39.433670 2017] [:error] [pid 2204] [client 24.146.44.164:62492]     logging_config_func(logging_settings)
[Thu Apr 13 21:17:39.433675 2017] [:error] [pid 2204] [client 24.146.44.164:62492]   File "/usr/lib64/python3.5/logging/config.py", line 795, in dictConfig
[Thu Apr 13 21:17:39.433677 2017] [:error] [pid 2204] [client 24.146.44.164:62492]     dictConfigClass(config).configure()
[Thu Apr 13 21:17:39.433682 2017] [:error] [pid 2204] [client 24.146.44.164:62492]   File "/usr/lib64/python3.5/logging/config.py", line 566, in configure
[Thu Apr 13 21:17:39.433684 2017] [:error] [pid 2204] [client 24.146.44.164:62492]     '%r: %s' % (name, e))
[Thu Apr 13 21:17:39.433695 2017] [:error] [pid 2204] [client 24.146.44.164:62492] ValueError: Unable to configure handler 'file': [Errno 13] Permission denied: '/mysite.log'
[Thu Apr 13 21:17:40.548543 2017] [:error] [pid 2249] [client 24.146.44.164:62493] mod_wsgi (pid=2249): Target WSGI script '/home/ec2-user/envClinicFlow/ClinicFlow/ClinicFlow/wsgi.py' cannot be loaded as Python module.
[Thu Apr 13 21:17:40.548612 2017] [:error] [pid 2249] [client 24.146.44.164:62493] mod_wsgi (pid=2249): Exception occurred processing WSGI script '/home/ec2-user/envClinicFlow/ClinicFlow/ClinicFlow/wsgi.py'.
[Thu Apr 13 21:17:40.548797 2017] [:error] [pid 2249] [client 24.146.44.164:62493] Traceback (most recent call last):
[Thu Apr 13 21:17:40.548852 2017] [:error] [pid 2249] [client 24.146.44.164:62493]   File "/usr/lib64/python3.5/logging/config.py", line 558, in configure
[Thu Apr 13 21:17:40.548856 2017] [:error] [pid 2249] [client 24.146.44.164:62493]     handler = self.configure_handler(handlers[name])
[Thu Apr 13 21:17:40.548888 2017] [:error] [pid 2249] [client 24.146.44.164:62493]   File "/usr/lib64/python3.5/logging/config.py", line 731, in configure_handler
[Thu Apr 13 21:17:40.548891 2017] [:error] [pid 2249] [client 24.146.44.164:62493]     result = factory(**kwargs)
[Thu Apr 13 21:17:40.548895 2017] [:error] [pid 2249] [client 24.146.44.164:62493]   File "/usr/lib64/python3.5/logging/__init__.py", line 1008, in __init__
[Thu Apr 13 21:17:40.548897 2017] [:error] [pid 2249] [client 24.146.44.164:62493]     StreamHandler.__init__(self, self._open())
[Thu Apr 13 21:17:40.548902 2017] [:error] [pid 2249] [client 24.146.44.164:62493]   File "/usr/lib64/python3.5/logging/__init__.py", line 1037, in _open
[Thu Apr 13 21:17:40.548904 2017] [:error] [pid 2249] [client 24.146.44.164:62493]     return open(self.baseFilename, self.mode, encoding=self.encoding)
[Thu Apr 13 21:17:40.548920 2017] [:error] [pid 2249] [client 24.146.44.164:62493] FileNotFoundError: [Errno 2] No such file or directory: '/home/ec2-user/evnClinicFlow/ClinicFlow/mysite.log'
[Thu Apr 13 21:17:40.548928 2017] [:error] [pid 2249] [client 24.146.44.164:62493] 
[Thu Apr 13 21:17:40.548929 2017] [:error] [pid 2249] [client 24.146.44.164:62493] During handling of the above exception, another exception occurred:
[Thu Apr 13 21:17:40.548931 2017] [:error] [pid 2249] [client 24.146.44.164:62493] 
[Thu Apr 13 21:17:40.548935 2017] [:error] [pid 2249] [client 24.146.44.164:62493] Traceback (most recent call last):
[Thu Apr 13 21:17:40.548960 2017] [:error] [pid 2249] [client 24.146.44.164:62493]   File "/home/ec2-user/envClinicFlow/ClinicFlow/ClinicFlow/wsgi.py", line 20, in <module>
[Thu Apr 13 21:17:40.548963 2017] [:error] [pid 2249] [client 24.146.44.164:62493]     application = get_wsgi_application()
[Thu Apr 13 21:17:40.548968 2017] [:error] [pid 2249] [client 24.146.44.164:62493]   File "/home/ec2-user/envClinicFlow/local/lib/python3.5/site-packages/django/core/wsgi.py", line 13, in get_wsgi_application
[Thu Apr 13 21:17:40.548970 2017] [:error] [pid 2249] [client 24.146.44.164:62493]     django.setup(set_prefix=False)
[Thu Apr 13 21:17:40.548975 2017] [:error] [pid 2249] [client 24.146.44.164:62493]   File "/home/ec2-user/envClinicFlow/local/lib/python3.5/site-packages/django/__init__.py", line 22, in setup
[Thu Apr 13 21:17:40.548977 2017] [:error] [pid 2249] [client 24.146.44.164:62493]     configure_logging(settings.LOGGING_CONFIG, settings.LOGGING)
[Thu Apr 13 21:17:40.548981 2017] [:error] [pid 2249] [client 24.146.44.164:62493]   File "/home/ec2-user/envClinicFlow/local/lib/python3.5/site-packages/django/utils/log.py", line 75, in configure_logging
[Thu Apr 13 21:17:40.548983 2017] [:error] [pid 2249] [client 24.146.44.164:62493]     logging_config_func(logging_settings)
[Thu Apr 13 21:17:40.548987 2017] [:error] [pid 2249] [client 24.146.44.164:62493]   File "/usr/lib64/python3.5/logging/config.py", line 795, in dictConfig
[Thu Apr 13 21:17:40.548989 2017] [:error] [pid 2249] [client 24.146.44.164:62493]     dictConfigClass(config).configure()
[Thu Apr 13 21:17:40.548993 2017] [:error] [pid 2249] [client 24.146.44.164:62493]   File "/usr/lib64/python3.5/logging/config.py", line 566, in configure
[Thu Apr 13 21:17:40.548995 2017] [:error] [pid 2249] [client 24.146.44.164:62493]     '%r: %s' % (name, e))
[Thu Apr 13 21:17:40.549005 2017] [:error] [pid 2249] [client 24.146.44.164:62493] ValueError: Unable to configure handler 'file': [Errno 2] No such file or directory: '/home/ec2-user/evnClinicFlow/ClinicFlow/mysite.log'
[Thu Apr 13 21:17:41.396708 2017] [:error] [pid 2203] [client 24.146.44.164:62494] mod_wsgi (pid=2203): Target WSGI script '/home/ec2-user/envClinicFlow/ClinicFlow/ClinicFlow/wsgi.py' cannot be loaded as Python module.
[Thu Apr 13 21:17:41.396754 2017] [:error] [pid 2203] [client 24.146.44.164:62494] mod_wsgi (pid=2203): Exception occurred processing WSGI script '/home/ec2-user/envClinicFlow/ClinicFlow/ClinicFlow/wsgi.py'.
[Thu Apr 13 21:17:41.396955 2017] [:error] [pid 2203] [client 24.146.44.164:62494] Traceback (most recent call last):
[Thu Apr 13 21:17:41.396995 2017] [:error] [pid 2203] [client 24.146.44.164:62494]   File "/usr/lib64/python3.5/logging/config.py", line 558, in configure
[Thu Apr 13 21:17:41.396999 2017] [:error] [pid 2203] [client 24.146.44.164:62494]     handler = self.configure_handler(handlers[name])
[Thu Apr 13 21:17:41.397004 2017] [:error] [pid 2203] [client 24.146.44.164:62494]   File "/usr/lib64/python3.5/logging/config.py", line 731, in configure_handler
[Thu Apr 13 21:17:41.397006 2017] [:error] [pid 2203] [client 24.146.44.164:62494]     result = factory(**kwargs)
[Thu Apr 13 21:17:41.397011 2017] [:error] [pid 2203] [client 24.146.44.164:62494]   File "/usr/lib64/python3.5/logging/__init__.py", line 1008, in __init__
[Thu Apr 13 21:17:41.397012 2017] [:error] [pid 2203] [client 24.146.44.164:62494]     StreamHandler.__init__(self, self._open())
[Thu Apr 13 21:17:41.397017 2017] [:error] [pid 2203] [client 24.146.44.164:62494]   File "/usr/lib64/python3.5/logging/__init__.py", line 1037, in _open
[Thu Apr 13 21:17:41.397018 2017] [:error] [pid 2203] [client 24.146.44.164:62494]     return open(self.baseFilename, self.mode, encoding=self.encoding)
[Thu Apr 13 21:17:41.397032 2017] [:error] [pid 2203] [client 24.146.44.164:62494] PermissionError: [Errno 13] Permission denied: '/home/ec2-user/envClinicFlow/ClinicFlow/mysite.log'
[Thu Apr 13 21:17:41.397038 2017] [:error] [pid 2203] [client 24.146.44.164:62494] 
[Thu Apr 13 21:17:41.397039 2017] [:error] [pid 2203] [client 24.146.44.164:62494] During handling of the above exception, another exception occurred:
[Thu Apr 13 21:17:41.397041 2017] [:error] [pid 2203] [client 24.146.44.164:62494] 
[Thu Apr 13 21:17:41.397045 2017] [:error] [pid 2203] [client 24.146.44.164:62494] Traceback (most recent call last):
[Thu Apr 13 21:17:41.397067 2017] [:error] [pid 2203] [client 24.146.44.164:62494]   File "/home/ec2-user/envClinicFlow/ClinicFlow/ClinicFlow/wsgi.py", line 20, in <module>
[Thu Apr 13 21:17:41.397070 2017] [:error] [pid 2203] [client 24.146.44.164:62494]     application = get_wsgi_application()
[Thu Apr 13 21:17:41.397075 2017] [:error] [pid 2203] [client 24.146.44.164:62494]   File "/home/ec2-user/envClinicFlow/local/lib/python3.5/site-packages/django/core/wsgi.py", line 13, in get_wsgi_application
[Thu Apr 13 21:17:41.397077 2017] [:error] [pid 2203] [client 24.146.44.164:62494]     django.setup(set_prefix=False)
[Thu Apr 13 21:17:41.397083 2017] [:error] [pid 2203] [client 24.146.44.164:62494]   File "/home/ec2-user/envClinicFlow/local/lib/python3.5/site-packages/django/__init__.py", line 22, in setup
[Thu Apr 13 21:17:41.397085 2017] [:error] [pid 2203] [client 24.146.44.164:62494]     configure_logging(settings.LOGGING_CONFIG, settings.LOGGING)
[Thu Apr 13 21:17:41.397089 2017] [:error] [pid 2203] [client 24.146.44.164:62494]   File "/home/ec2-user/envClinicFlow/local/lib/python3.5/site-packages/django/utils/log.py", line 75, in configure_logging
[Thu Apr 13 21:17:41.397091 2017] [:error] [pid 2203] [client 24.146.44.164:62494]     logging_config_func(logging_settings)
[Thu Apr 13 21:17:41.397096 2017] [:error] [pid 2203] [client 24.146.44.164:62494]   File "/usr/lib64/python3.5/logging/config.py", line 795, in dictConfig
[Thu Apr 13 21:17:41.397097 2017] [:error] [pid 2203] [client 24.146.44.164:62494]     dictConfigClass(config).configure()
[Thu Apr 13 21:17:41.397101 2017] [:error] [pid 2203] [client 24.146.44.164:62494]   File "/usr/lib64/python3.5/logging/config.py", line 566, in configure
[Thu Apr 13 21:17:41.397103 2017] [:error] [pid 2203] [client 24.146.44.164:62494]     '%r: %s' % (name, e))
[Thu Apr 13 21:17:41.397112 2017] [:error] [pid 2203] [client 24.146.44.164:62494] ValueError: Unable to configure handler 'file': [Errno 13] Permission denied: '/home/ec2-user/envClinicFlow/ClinicFlow/mysite.log'
[Thu Apr 13 21:32:55.449882 2017] [:error] [pid 2200] [client 24.146.44.164:62545] mod_wsgi (pid=2200): Target WSGI script '/home/ec2-user/envClinicFlow/ClinicFlow/ClinicFlow/wsgi.py' cannot be loaded as Python module.
[Thu Apr 13 21:32:55.449955 2017] [:error] [pid 2200] [client 24.146.44.164:62545] mod_wsgi (pid=2200): Exception occurred processing WSGI script '/home/ec2-user/envClinicFlow/ClinicFlow/ClinicFlow/wsgi.py'.
[Thu Apr 13 21:32:55.450153 2017] [:error] [pid 2200] [client 24.146.44.164:62545] Traceback (most recent call last):
[Thu Apr 13 21:32:55.450190 2017] [:error] [pid 2200] [client 24.146.44.164:62545]   File "/usr/lib64/python3.5/logging/config.py", line 558, in configure
[Thu Apr 13 21:32:55.450194 2017] [:error] [pid 2200] [client 24.146.44.164:62545]     handler = self.configure_handler(handlers[name])
[Thu Apr 13 21:32:55.450200 2017] [:error] [pid 2200] [client 24.146.44.164:62545]   File "/usr/lib64/python3.5/logging/config.py", line 731, in configure_handler
[Thu Apr 13 21:32:55.450203 2017] [:error] [pid 2200] [client 24.146.44.164:62545]     result = factory(**kwargs)
[Thu Apr 13 21:32:55.450207 2017] [:error] [pid 2200] [client 24.146.44.164:62545]   File "/usr/lib64/python3.5/logging/__init__.py", line 1008, in __init__
[Thu Apr 13 21:32:55.450209 2017] [:error] [pid 2200] [client 24.146.44.164:62545]     StreamHandler.__init__(self, self._open())
[Thu Apr 13 21:32:55.450214 2017] [:error] [pid 2200] [client 24.146.44.164:62545]   File "/usr/lib64/python3.5/logging/__init__.py", line 1037, in _open
[Thu Apr 13 21:32:55.450216 2017] [:error] [pid 2200] [client 24.146.44.164:62545]     return open(self.baseFilename, self.mode, encoding=self.encoding)
[Thu Apr 13 21:32:55.450231 2017] [:error] [pid 2200] [client 24.146.44.164:62545] PermissionError: [Errno 13] Permission denied: '/home/ec2-user/envClinicFlow/ClinicFlow/mysite.log'
[Thu Apr 13 21:32:55.450239 2017] [:error] [pid 2200] [client 24.146.44.164:62545] 
[Thu Apr 13 21:32:55.450241 2017] [:error] [pid 2200] [client 24.146.44.164:62545] During handling of the above exception, another exception occurred:
[Thu Apr 13 21:32:55.450243 2017] [:error] [pid 2200] [client 24.146.44.164:62545] 
[Thu Apr 13 21:32:55.450247 2017] [:error] [pid 2200] [client 24.146.44.164:62545] Traceback (most recent call last):
[Thu Apr 13 21:32:55.450272 2017] [:error] [pid 2200] [client 24.146.44.164:62545]   File "/home/ec2-user/envClinicFlow/ClinicFlow/ClinicFlow/wsgi.py", line 20, in <module>
[Thu Apr 13 21:32:55.450275 2017] [:error] [pid 2200] [client 24.146.44.164:62545]     application = get_wsgi_application()
[Thu Apr 13 21:32:55.450280 2017] [:error] [pid 2200] [client 24.146.44.164:62545]   File "/home/ec2-user/envClinicFlow/local/lib/python3.5/site-packages/django/core/wsgi.py", line 13, in get_wsgi_application
[Thu Apr 13 21:32:55.450282 2017] [:error] [pid 2200] [client 24.146.44.164:62545]     django.setup(set_prefix=False)
[Thu Apr 13 21:32:55.450288 2017] [:error] [pid 2200] [client 24.146.44.164:62545]   File "/home/ec2-user/envClinicFlow/local/lib/python3.5/site-packages/django/__init__.py", line 22, in setup
[Thu Apr 13 21:32:55.450291 2017] [:error] [pid 2200] [client 24.146.44.164:62545]     configure_logging(settings.LOGGING_CONFIG, settings.LOGGING)
[Thu Apr 13 21:32:55.450295 2017] [:error] [pid 2200] [client 24.146.44.164:62545]   File "/home/ec2-user/envClinicFlow/local/lib/python3.5/site-packages/django/utils/log.py", line 75, in configure_logging
[Thu Apr 13 21:32:55.450297 2017] [:error] [pid 2200] [client 24.146.44.164:62545]     logging_config_func(logging_settings)
[Thu Apr 13 21:32:55.450302 2017] [:error] [pid 2200] [client 24.146.44.164:62545]   File "/usr/lib64/python3.5/logging/config.py", line 795, in dictConfig
[Thu Apr 13 21:32:55.450304 2017] [:error] [pid 2200] [client 24.146.44.164:62545]     dictConfigClass(config).configure()
[Thu Apr 13 21:32:55.450308 2017] [:error] [pid 2200] [client 24.146.44.164:62545]   File "/usr/lib64/python3.5/logging/config.py", line 566, in configure
[Thu Apr 13 21:32:55.450310 2017] [:error] [pid 2200] [client 24.146.44.164:62545]     '%r: %s' % (name, e))
[Thu Apr 13 21:32:55.450320 2017] [:error] [pid 2200] [client 24.146.44.164:62545] ValueError: Unable to configure handler 'file': [Errno 13] Permission denied: '/home/ec2-user/envClinicFlow/ClinicFlow/mysite.log'
[Thu Apr 13 21:41:58.292840 2017] [:error] [pid 2204] [client 24.146.44.164:62579] mod_wsgi (pid=2204): Target WSGI script '/home/ec2-user/envClinicFlow/ClinicFlow/ClinicFlow/wsgi.py' cannot be loaded as Python module., referer: http://34.205.53.34/setting
[Thu Apr 13 21:41:58.292916 2017] [:error] [pid 2204] [client 24.146.44.164:62579] mod_wsgi (pid=2204): Exception occurred processing WSGI script '/home/ec2-user/envClinicFlow/ClinicFlow/ClinicFlow/wsgi.py'., referer: http://34.205.53.34/setting
[Thu Apr 13 21:41:58.293125 2017] [:error] [pid 2204] [client 24.146.44.164:62579] Traceback (most recent call last):, referer: http://34.205.53.34/setting
[Thu Apr 13 21:41:58.293168 2017] [:error] [pid 2204] [client 24.146.44.164:62579]   File "/usr/lib64/python3.5/logging/config.py", line 558, in configure, referer: http://34.205.53.34/setting
[Thu Apr 13 21:41:58.293173 2017] [:error] [pid 2204] [client 24.146.44.164:62579]     handler = self.configure_handler(handlers[name]), referer: http://34.205.53.34/setting
[Thu Apr 13 21:41:58.293217 2017] [:error] [pid 2204] [client 24.146.44.164:62579]   File "/usr/lib64/python3.5/logging/config.py", line 731, in configure_handler, referer: http://34.205.53.34/setting
[Thu Apr 13 21:41:58.293225 2017] [:error] [pid 2204] [client 24.146.44.164:62579]     result = factory(**kwargs), referer: http://34.205.53.34/setting
[Thu Apr 13 21:41:58.293230 2017] [:error] [pid 2204] [client 24.146.44.164:62579]   File "/usr/lib64/python3.5/logging/__init__.py", line 1008, in __init__, referer: http://34.205.53.34/setting
[Thu Apr 13 21:41:58.293233 2017] [:error] [pid 2204] [client 24.146.44.164:62579]     StreamHandler.__init__(self, self._open()), referer: http://34.205.53.34/setting
[Thu Apr 13 21:41:58.293239 2017] [:error] [pid 2204] [client 24.146.44.164:62579]   File "/usr/lib64/python3.5/logging/__init__.py", line 1037, in _open, referer: http://34.205.53.34/setting
[Thu Apr 13 21:41:58.293241 2017] [:error] [pid 2204] [client 24.146.44.164:62579]     return open(self.baseFilename, self.mode, encoding=self.encoding), referer: http://34.205.53.34/setting
[Thu Apr 13 21:41:58.293261 2017] [:error] [pid 2204] [client 24.146.44.164:62579] PermissionError: [Errno 13] Permission denied: '/mysite.log', referer: http://34.205.53.34/setting
[Thu Apr 13 21:41:58.293270 2017] [:error] [pid 2204] [client 24.146.44.164:62579] , referer: http://34.205.53.34/setting
[Thu Apr 13 21:41:58.293273 2017] [:error] [pid 2204] [client 24.146.44.164:62579] During handling of the above exception, another exception occurred:, referer: http://34.205.53.34/setting
[Thu Apr 13 21:41:58.293275 2017] [:error] [pid 2204] [client 24.146.44.164:62579] , referer: http://34.205.53.34/setting
[Thu Apr 13 21:41:58.293280 2017] [:error] [pid 2204] [client 24.146.44.164:62579] Traceback (most recent call last):, referer: http://34.205.53.34/setting
[Thu Apr 13 21:41:58.293308 2017] [:error] [pid 2204] [client 24.146.44.164:62579]   File "/home/ec2-user/envClinicFlow/ClinicFlow/ClinicFlow/wsgi.py", line 20, in <module>, referer: http://34.205.53.34/setting
[Thu Apr 13 21:41:58.293312 2017] [:error] [pid 2204] [client 24.146.44.164:62579]     application = get_wsgi_application(), referer: http://34.205.53.34/setting
[Thu Apr 13 21:41:58.293318 2017] [:error] [pid 2204] [client 24.146.44.164:62579]   File "/home/ec2-user/envClinicFlow/local/lib/python3.5/site-packages/django/core/wsgi.py", line 13, in get_wsgi_application, referer: http://34.205.53.34/setting
[Thu Apr 13 21:41:58.293321 2017] [:error] [pid 2204] [client 24.146.44.164:62579]     django.setup(set_prefix=False), referer: http://34.205.53.34/setting
[Thu Apr 13 21:41:58.293327 2017] [:error] [pid 2204] [client 24.146.44.164:62579]   File "/home/ec2-user/envClinicFlow/local/lib/python3.5/site-packages/django/__init__.py", line 22, in setup, referer: http://34.205.53.34/setting
[Thu Apr 13 21:41:58.293330 2017] [:error] [pid 2204] [client 24.146.44.164:62579]     configure_logging(settings.LOGGING_CONFIG, settings.LOGGING), referer: http://34.205.53.34/setting
[Thu Apr 13 21:41:58.293349 2017] [:error] [pid 2204] [client 24.146.44.164:62579]   File "/home/ec2-user/envClinicFlow/local/lib/python3.5/site-packages/django/utils/log.py", line 75, in configure_logging, referer: http://34.205.53.34/setting
[Thu Apr 13 21:41:58.293351 2017] [:error] [pid 2204] [client 24.146.44.164:62579]     logging_config_func(logging_settings), referer: http://34.205.53.34/setting
[Thu Apr 13 21:41:58.293357 2017] [:error] [pid 2204] [client 24.146.44.164:62579]   File "/usr/lib64/python3.5/logging/config.py", line 795, in dictConfig, referer: http://34.205.53.34/setting
[Thu Apr 13 21:41:58.293359 2017] [:error] [pid 2204] [client 24.146.44.164:62579]     dictConfigClass(config).configure(), referer: http://34.205.53.34/setting
[Thu Apr 13 21:41:58.293363 2017] [:error] [pid 2204] [client 24.146.44.164:62579]   File "/usr/lib64/python3.5/logging/config.py", line 566, in configure, referer: http://34.205.53.34/setting
[Thu Apr 13 21:41:58.293365 2017] [:error] [pid 2204] [client 24.146.44.164:62579]     '%r: %s' % (name, e)), referer: http://34.205.53.34/setting
[Thu Apr 13 21:41:58.293377 2017] [:error] [pid 2204] [client 24.146.44.164:62579] ValueError: Unable to configure handler 'file': [Errno 13] Permission denied: '/mysite.log', referer: http://34.205.53.34/setting
[Thu Apr 13 21:42:00.902648 2017] [:error] [pid 2249] [client 24.146.44.164:62580] mod_wsgi (pid=2249): Target WSGI script '/home/ec2-user/envClinicFlow/ClinicFlow/ClinicFlow/wsgi.py' cannot be loaded as Python module., referer: http://34.205.53.34/setting
[Thu Apr 13 21:42:00.902721 2017] [:error] [pid 2249] [client 24.146.44.164:62580] mod_wsgi (pid=2249): Exception occurred processing WSGI script '/home/ec2-user/envClinicFlow/ClinicFlow/ClinicFlow/wsgi.py'., referer: http://34.205.53.34/setting
[Thu Apr 13 21:42:00.902877 2017] [:error] [pid 2249] [client 24.146.44.164:62580] Traceback (most recent call last):, referer: http://34.205.53.34/setting
[Thu Apr 13 21:42:00.902909 2017] [:error] [pid 2249] [client 24.146.44.164:62580]   File "/usr/lib64/python3.5/logging/config.py", line 558, in configure, referer: http://34.205.53.34/setting
[Thu Apr 13 21:42:00.902912 2017] [:error] [pid 2249] [client 24.146.44.164:62580]     handler = self.configure_handler(handlers[name]), referer: http://34.205.53.34/setting
[Thu Apr 13 21:42:00.902918 2017] [:error] [pid 2249] [client 24.146.44.164:62580]   File "/usr/lib64/python3.5/logging/config.py", line 731, in configure_handler, referer: http://34.205.53.34/setting
[Thu Apr 13 21:42:00.902921 2017] [:error] [pid 2249] [client 24.146.44.164:62580]     result = factory(**kwargs), referer: http://34.205.53.34/setting
[Thu Apr 13 21:42:00.902925 2017] [:error] [pid 2249] [client 24.146.44.164:62580]   File "/usr/lib64/python3.5/logging/__init__.py", line 1008, in __init__, referer: http://34.205.53.34/setting
[Thu Apr 13 21:42:00.902928 2017] [:error] [pid 2249] [client 24.146.44.164:62580]     StreamHandler.__init__(self, self._open()), referer: http://34.205.53.34/setting
[Thu Apr 13 21:42:00.902932 2017] [:error] [pid 2249] [client 24.146.44.164:62580]   File "/usr/lib64/python3.5/logging/__init__.py", line 1037, in _open, referer: http://34.205.53.34/setting
[Thu Apr 13 21:42:00.902934 2017] [:error] [pid 2249] [client 24.146.44.164:62580]     return open(self.baseFilename, self.mode, encoding=self.encoding), referer: http://34.205.53.34/setting
[Thu Apr 13 21:42:00.902948 2017] [:error] [pid 2249] [client 24.146.44.164:62580] FileNotFoundError: [Errno 2] No such file or directory: '/home/ec2-user/evnClinicFlow/ClinicFlow/mysite.log', referer: http://34.205.53.34/setting
[Thu Apr 13 21:42:00.902956 2017] [:error] [pid 2249] [client 24.146.44.164:62580] , referer: http://34.205.53.34/setting
[Thu Apr 13 21:42:00.902958 2017] [:error] [pid 2249] [client 24.146.44.164:62580] During handling of the above exception, another exception occurred:, referer: http://34.205.53.34/setting
[Thu Apr 13 21:42:00.902960 2017] [:error] [pid 2249] [client 24.146.44.164:62580] , referer: http://34.205.53.34/setting
[Thu Apr 13 21:42:00.902973 2017] [:error] [pid 2249] [client 24.146.44.164:62580] Traceback (most recent call last):, referer: http://34.205.53.34/setting
[Thu Apr 13 21:42:00.902997 2017] [:error] [pid 2249] [client 24.146.44.164:62580]   File "/home/ec2-user/envClinicFlow/ClinicFlow/ClinicFlow/wsgi.py", line 20, in <module>, referer: http://34.205.53.34/setting
[Thu Apr 13 21:42:00.903000 2017] [:error] [pid 2249] [client 24.146.44.164:62580]     application = get_wsgi_application(), referer: http://34.205.53.34/setting
[Thu Apr 13 21:42:00.903004 2017] [:error] [pid 2249] [client 24.146.44.164:62580]   File "/home/ec2-user/envClinicFlow/local/lib/python3.5/site-packages/django/core/wsgi.py", line 13, in get_wsgi_application, referer: http://34.205.53.34/setting
[Thu Apr 13 21:42:00.903007 2017] [:error] [pid 2249] [client 24.146.44.164:62580]     django.setup(set_prefix=False), referer: http://34.205.53.34/setting
[Thu Apr 13 21:42:00.903012 2017] [:error] [pid 2249] [client 24.146.44.164:62580]   File "/home/ec2-user/envClinicFlow/local/lib/python3.5/site-packages/django/__init__.py", line 22, in setup, referer: http://34.205.53.34/setting
[Thu Apr 13 21:42:00.903014 2017] [:error] [pid 2249] [client 24.146.44.164:62580]     configure_logging(settings.LOGGING_CONFIG, settings.LOGGING), referer: http://34.205.53.34/setting
[Thu Apr 13 21:42:00.903018 2017] [:error] [pid 2249] [client 24.146.44.164:62580]   File "/home/ec2-user/envClinicFlow/local/lib/python3.5/site-packages/django/utils/log.py", line 75, in configure_logging, referer: http://34.205.53.34/setting
[Thu Apr 13 21:42:00.903020 2017] [:error] [pid 2249] [client 24.146.44.164:62580]     logging_config_func(logging_settings), referer: http://34.205.53.34/setting
[Thu Apr 13 21:42:00.903024 2017] [:error] [pid 2249] [client 24.146.44.164:62580]   File "/usr/lib64/python3.5/logging/config.py", line 795, in dictConfig, referer: http://34.205.53.34/setting
[Thu Apr 13 21:42:00.903026 2017] [:error] [pid 2249] [client 24.146.44.164:62580]     dictConfigClass(config).configure(), referer: http://34.205.53.34/setting
[Thu Apr 13 21:42:00.903030 2017] [:error] [pid 2249] [client 24.146.44.164:62580]   File "/usr/lib64/python3.5/logging/config.py", line 566, in configure, referer: http://34.205.53.34/setting
[Thu Apr 13 21:42:00.903032 2017] [:error] [pid 2249] [client 24.146.44.164:62580]     '%r: %s' % (name, e)), referer: http://34.205.53.34/setting
[Thu Apr 13 21:42:00.903042 2017] [:error] [pid 2249] [client 24.146.44.164:62580] ValueError: Unable to configure handler 'file': [Errno 2] No such file or directory: '/home/ec2-user/evnClinicFlow/ClinicFlow/mysite.log', referer: http://34.205.53.34/setting
[Thu Apr 13 21:50:03.883032 2017] [:error] [pid 2910] [client 24.146.44.164:62614] mod_wsgi (pid=2910): Target WSGI script '/home/ec2-user/envClinicFlow/ClinicFlow/ClinicFlow/wsgi.py' cannot be loaded as Python module.
[Thu Apr 13 21:50:03.883094 2017] [:error] [pid 2910] [client 24.146.44.164:62614] mod_wsgi (pid=2910): Exception occurred processing WSGI script '/home/ec2-user/envClinicFlow/ClinicFlow/ClinicFlow/wsgi.py'.
[Thu Apr 13 21:50:03.884232 2017] [:error] [pid 2910] [client 24.146.44.164:62614] Traceback (most recent call last):
[Thu Apr 13 21:50:03.884285 2017] [:error] [pid 2910] [client 24.146.44.164:62614]   File "/home/ec2-user/envClinicFlow/ClinicFlow/ClinicFlow/wsgi.py", line 20, in <module>
[Thu Apr 13 21:50:03.884289 2017] [:error] [pid 2910] [client 24.146.44.164:62614]     application = get_wsgi_application()
[Thu Apr 13 21:50:03.884296 2017] [:error] [pid 2910] [client 24.146.44.164:62614]   File "/home/ec2-user/envClinicFlow/local/lib/python3.5/site-packages/django/core/wsgi.py", line 13, in get_wsgi_application
[Thu Apr 13 21:50:03.884299 2017] [:error] [pid 2910] [client 24.146.44.164:62614]     django.setup(set_prefix=False)
[Thu Apr 13 21:50:03.884304 2017] [:error] [pid 2910] [client 24.146.44.164:62614]   File "/home/ec2-user/envClinicFlow/local/lib/python3.5/site-packages/django/__init__.py", line 22, in setup
[Thu Apr 13 21:50:03.884313 2017] [:error] [pid 2910] [client 24.146.44.164:62614]     configure_logging(settings.LOGGING_CONFIG, settings.LOGGING)
[Thu Apr 13 21:50:03.884318 2017] [:error] [pid 2910] [client 24.146.44.164:62614]   File "/home/ec2-user/envClinicFlow/local/lib/python3.5/site-packages/django/conf/__init__.py", line 56, in __getattr__
[Thu Apr 13 21:50:03.884321 2017] [:error] [pid 2910] [client 24.146.44.164:62614]     self._setup(name)
[Thu Apr 13 21:50:03.884325 2017] [:error] [pid 2910] [client 24.146.44.164:62614]   File "/home/ec2-user/envClinicFlow/local/lib/python3.5/site-packages/django/conf/__init__.py", line 41, in _setup
[Thu Apr 13 21:50:03.884328 2017] [:error] [pid 2910] [client 24.146.44.164:62614]     self._wrapped = Settings(settings_module)
[Thu Apr 13 21:50:03.884332 2017] [:error] [pid 2910] [client 24.146.44.164:62614]   File "/home/ec2-user/envClinicFlow/local/lib/python3.5/site-packages/django/conf/__init__.py", line 110, in __init__
[Thu Apr 13 21:50:03.884334 2017] [:error] [pid 2910] [client 24.146.44.164:62614]     mod = importlib.import_module(self.SETTINGS_MODULE)
[Thu Apr 13 21:50:03.884339 2017] [:error] [pid 2910] [client 24.146.44.164:62614]   File "/home/ec2-user/envClinicFlow/lib64/python3.5/importlib/__init__.py", line 126, in import_module
[Thu Apr 13 21:50:03.884341 2017] [:error] [pid 2910] [client 24.146.44.164:62614]     return _bootstrap._gcd_import(name[level:], package, level)
[Thu Apr 13 21:50:03.884345 2017] [:error] [pid 2910] [client 24.146.44.164:62614]   File "<frozen importlib._bootstrap>", line 986, in _gcd_import
[Thu Apr 13 21:50:03.884350 2017] [:error] [pid 2910] [client 24.146.44.164:62614]   File "<frozen importlib._bootstrap>", line 969, in _find_and_load
[Thu Apr 13 21:50:03.884355 2017] [:error] [pid 2910] [client 24.146.44.164:62614]   File "<frozen importlib._bootstrap>", line 958, in _find_and_load_unlocked
[Thu Apr 13 21:50:03.884360 2017] [:error] [pid 2910] [client 24.146.44.164:62614]   File "<frozen importlib._bootstrap>", line 673, in _load_unlocked
[Thu Apr 13 21:50:03.884365 2017] [:error] [pid 2910] [client 24.146.44.164:62614]   File "<frozen importlib._bootstrap_external>", line 658, in exec_module
[Thu Apr 13 21:50:03.884370 2017] [:error] [pid 2910] [client 24.146.44.164:62614]   File "<frozen importlib._bootstrap_external>", line 764, in get_code
[Thu Apr 13 21:50:03.884374 2017] [:error] [pid 2910] [client 24.146.44.164:62614]   File "<frozen importlib._bootstrap_external>", line 724, in source_to_code
[Thu Apr 13 21:50:03.884379 2017] [:error] [pid 2910] [client 24.146.44.164:62614]   File "<frozen importlib._bootstrap>", line 222, in _call_with_frames_removed
[Thu Apr 13 21:50:03.884394 2017] [:error] [pid 2910] [client 24.146.44.164:62614]   File "/home/ec2-user/envClinicFlow/ClinicFlow/ClinicFlow/settings.py", line 159
[Thu Apr 13 21:50:03.884402 2017] [:error] [pid 2910] [client 24.146.44.164:62614]     }
[Thu Apr 13 21:50:03.884416 2017] [:error] [pid 2910] [client 24.146.44.164:62614]     ^
[Thu Apr 13 21:50:03.884423 2017] [:error] [pid 2910] [client 24.146.44.164:62614] SyntaxError: unexpected EOF while parsing
[Thu Apr 13 21:50:08.795904 2017] [:error] [pid 2907] [client 24.146.44.164:62616] mod_wsgi (pid=2907): Target WSGI script '/home/ec2-user/envClinicFlow/ClinicFlow/ClinicFlow/wsgi.py' cannot be loaded as Python module.
[Thu Apr 13 21:50:08.795983 2017] [:error] [pid 2907] [client 24.146.44.164:62616] mod_wsgi (pid=2907): Exception occurred processing WSGI script '/home/ec2-user/envClinicFlow/ClinicFlow/ClinicFlow/wsgi.py'.
[Thu Apr 13 21:50:08.796542 2017] [:error] [pid 2907] [client 24.146.44.164:62616] Traceback (most recent call last):
[Thu Apr 13 21:50:08.796588 2017] [:error] [pid 2907] [client 24.146.44.164:62616]   File "/home/ec2-user/envClinicFlow/ClinicFlow/ClinicFlow/wsgi.py", line 20, in <module>
[Thu Apr 13 21:50:08.796592 2017] [:error] [pid 2907] [client 24.146.44.164:62616]     application = get_wsgi_application()
[Thu Apr 13 21:50:08.796598 2017] [:error] [pid 2907] [client 24.146.44.164:62616]   File "/home/ec2-user/envClinicFlow/local/lib/python3.5/site-packages/django/core/wsgi.py", line 13, in get_wsgi_application
[Thu Apr 13 21:50:08.796607 2017] [:error] [pid 2907] [client 24.146.44.164:62616]     django.setup(set_prefix=False)
[Thu Apr 13 21:50:08.796613 2017] [:error] [pid 2907] [client 24.146.44.164:62616]   File "/home/ec2-user/envClinicFlow/local/lib/python3.5/site-packages/django/__init__.py", line 22, in setup
[Thu Apr 13 21:50:08.796615 2017] [:error] [pid 2907] [client 24.146.44.164:62616]     configure_logging(settings.LOGGING_CONFIG, settings.LOGGING)
[Thu Apr 13 21:50:08.796620 2017] [:error] [pid 2907] [client 24.146.44.164:62616]   File "/home/ec2-user/envClinicFlow/local/lib/python3.5/site-packages/django/conf/__init__.py", line 56, in __getattr__
[Thu Apr 13 21:50:08.796622 2017] [:error] [pid 2907] [client 24.146.44.164:62616]     self._setup(name)
[Thu Apr 13 21:50:08.796626 2017] [:error] [pid 2907] [client 24.146.44.164:62616]   File "/home/ec2-user/envClinicFlow/local/lib/python3.5/site-packages/django/conf/__init__.py", line 41, in _setup
[Thu Apr 13 21:50:08.796628 2017] [:error] [pid 2907] [client 24.146.44.164:62616]     self._wrapped = Settings(settings_module)
[Thu Apr 13 21:50:08.796632 2017] [:error] [pid 2907] [client 24.146.44.164:62616]   File "/home/ec2-user/envClinicFlow/local/lib/python3.5/site-packages/django/conf/__init__.py", line 110, in __init__
[Thu Apr 13 21:50:08.796634 2017] [:error] [pid 2907] [client 24.146.44.164:62616]     mod = importlib.import_module(self.SETTINGS_MODULE)
[Thu Apr 13 21:50:08.796638 2017] [:error] [pid 2907] [client 24.146.44.164:62616]   File "/home/ec2-user/envClinicFlow/lib64/python3.5/importlib/__init__.py", line 126, in import_module
[Thu Apr 13 21:50:08.796641 2017] [:error] [pid 2907] [client 24.146.44.164:62616]     return _bootstrap._gcd_import(name[level:], package, level)
[Thu Apr 13 21:50:08.796645 2017] [:error] [pid 2907] [client 24.146.44.164:62616]   File "<frozen importlib._bootstrap>", line 986, in _gcd_import
[Thu Apr 13 21:50:08.796649 2017] [:error] [pid 2907] [client 24.146.44.164:62616]   File "<frozen importlib._bootstrap>", line 969, in _find_and_load
[Thu Apr 13 21:50:08.796666 2017] [:error] [pid 2907] [client 24.146.44.164:62616]   File "<frozen importlib._bootstrap>", line 958, in _find_and_load_unlocked
[Thu Apr 13 21:50:08.796671 2017] [:error] [pid 2907] [client 24.146.44.164:62616]   File "<frozen importlib._bootstrap>", line 673, in _load_unlocked
[Thu Apr 13 21:50:08.796676 2017] [:error] [pid 2907] [client 24.146.44.164:62616]   File "<frozen importlib._bootstrap_external>", line 658, in exec_module
[Thu Apr 13 21:50:08.796681 2017] [:error] [pid 2907] [client 24.146.44.164:62616]   File "<frozen importlib._bootstrap_external>", line 764, in get_code
[Thu Apr 13 21:50:08.796685 2017] [:error] [pid 2907] [client 24.146.44.164:62616]   File "<frozen importlib._bootstrap_external>", line 724, in source_to_code
[Thu Apr 13 21:50:08.796690 2017] [:error] [pid 2907] [client 24.146.44.164:62616]   File "<frozen importlib._bootstrap>", line 222, in _call_with_frames_removed
[Thu Apr 13 21:50:08.796706 2017] [:error] [pid 2907] [client 24.146.44.164:62616]   File "/home/ec2-user/envClinicFlow/ClinicFlow/ClinicFlow/settings.py", line 159
[Thu Apr 13 21:50:08.796715 2017] [:error] [pid 2907] [client 24.146.44.164:62616]     }
[Thu Apr 13 21:50:08.796728 2017] [:error] [pid 2907] [client 24.146.44.164:62616]     ^
[Thu Apr 13 21:50:08.796736 2017] [:error] [pid 2907] [client 24.146.44.164:62616] SyntaxError: unexpected EOF while parsing
[Thu Apr 13 21:50:09.770382 2017] [:error] [pid 2909] [client 24.146.44.164:62617] mod_wsgi (pid=2909): Target WSGI script '/home/ec2-user/envClinicFlow/ClinicFlow/ClinicFlow/wsgi.py' cannot be loaded as Python module.
[Thu Apr 13 21:50:09.770440 2017] [:error] [pid 2909] [client 24.146.44.164:62617] mod_wsgi (pid=2909): Exception occurred processing WSGI script '/home/ec2-user/envClinicFlow/ClinicFlow/ClinicFlow/wsgi.py'.
[Thu Apr 13 21:50:09.771054 2017] [:error] [pid 2909] [client 24.146.44.164:62617] Traceback (most recent call last):
[Thu Apr 13 21:50:09.771113 2017] [:error] [pid 2909] [client 24.146.44.164:62617]   File "/home/ec2-user/envClinicFlow/ClinicFlow/ClinicFlow/wsgi.py", line 20, in <module>
[Thu Apr 13 21:50:09.771117 2017] [:error] [pid 2909] [client 24.146.44.164:62617]     application = get_wsgi_application()
[Thu Apr 13 21:50:09.771124 2017] [:error] [pid 2909] [client 24.146.44.164:62617]   File "/home/ec2-user/envClinicFlow/local/lib/python3.5/site-packages/django/core/wsgi.py", line 13, in get_wsgi_application
[Thu Apr 13 21:50:09.771127 2017] [:error] [pid 2909] [client 24.146.44.164:62617]     django.setup(set_prefix=False)
[Thu Apr 13 21:50:09.771132 2017] [:error] [pid 2909] [client 24.146.44.164:62617]   File "/home/ec2-user/envClinicFlow/local/lib/python3.5/site-packages/django/__init__.py", line 22, in setup
[Thu Apr 13 21:50:09.771134 2017] [:error] [pid 2909] [client 24.146.44.164:62617]     configure_logging(settings.LOGGING_CONFIG, settings.LOGGING)
[Thu Apr 13 21:50:09.771139 2017] [:error] [pid 2909] [client 24.146.44.164:62617]   File "/home/ec2-user/envClinicFlow/local/lib/python3.5/site-packages/django/conf/__init__.py", line 56, in __getattr__
[Thu Apr 13 21:50:09.771141 2017] [:error] [pid 2909] [client 24.146.44.164:62617]     self._setup(name)
[Thu Apr 13 21:50:09.771146 2017] [:error] [pid 2909] [client 24.146.44.164:62617]   File "/home/ec2-user/envClinicFlow/local/lib/python3.5/site-packages/django/conf/__init__.py", line 41, in _setup
[Thu Apr 13 21:50:09.771148 2017] [:error] [pid 2909] [client 24.146.44.164:62617]     self._wrapped = Settings(settings_module)
[Thu Apr 13 21:50:09.771153 2017] [:error] [pid 2909] [client 24.146.44.164:62617]   File "/home/ec2-user/envClinicFlow/local/lib/python3.5/site-packages/django/conf/__init__.py", line 110, in __init__
[Thu Apr 13 21:50:09.771155 2017] [:error] [pid 2909] [client 24.146.44.164:62617]     mod = importlib.import_module(self.SETTINGS_MODULE)
[Thu Apr 13 21:50:09.771160 2017] [:error] [pid 2909] [client 24.146.44.164:62617]   File "/home/ec2-user/envClinicFlow/lib64/python3.5/importlib/__init__.py", line 126, in import_module
[Thu Apr 13 21:50:09.771162 2017] [:error] [pid 2909] [client 24.146.44.164:62617]     return _bootstrap._gcd_import(name[level:], package, level)
[Thu Apr 13 21:50:09.771167 2017] [:error] [pid 2909] [client 24.146.44.164:62617]   File "<frozen importlib._bootstrap>", line 986, in _gcd_import
[Thu Apr 13 21:50:09.771171 2017] [:error] [pid 2909] [client 24.146.44.164:62617]   File "<frozen importlib._bootstrap>", line 969, in _find_and_load
[Thu Apr 13 21:50:09.771188 2017] [:error] [pid 2909] [client 24.146.44.164:62617]   File "<frozen importlib._bootstrap>", line 958, in _find_and_load_unlocked
[Thu Apr 13 21:50:09.771193 2017] [:error] [pid 2909] [client 24.146.44.164:62617]   File "<frozen importlib._bootstrap>", line 673, in _load_unlocked
[Thu Apr 13 21:50:09.771198 2017] [:error] [pid 2909] [client 24.146.44.164:62617]   File "<frozen importlib._bootstrap_external>", line 658, in exec_module
[Thu Apr 13 21:50:09.771202 2017] [:error] [pid 2909] [client 24.146.44.164:62617]   File "<frozen importlib._bootstrap_external>", line 764, in get_code
[Thu Apr 13 21:50:09.771207 2017] [:error] [pid 2909] [client 24.146.44.164:62617]   File "<frozen importlib._bootstrap_external>", line 724, in source_to_code
[Thu Apr 13 21:50:09.771212 2017] [:error] [pid 2909] [client 24.146.44.164:62617]   File "<frozen importlib._bootstrap>", line 222, in _call_with_frames_removed
[Thu Apr 13 21:50:09.771226 2017] [:error] [pid 2909] [client 24.146.44.164:62617]   File "/home/ec2-user/envClinicFlow/ClinicFlow/ClinicFlow/settings.py", line 159
[Thu Apr 13 21:50:09.771234 2017] [:error] [pid 2909] [client 24.146.44.164:62617]     }
[Thu Apr 13 21:50:09.771248 2017] [:error] [pid 2909] [client 24.146.44.164:62617]     ^
[Thu Apr 13 21:50:09.771255 2017] [:error] [pid 2909] [client 24.146.44.164:62617] SyntaxError: unexpected EOF while parsing
[Thu Apr 13 21:50:12.542460 2017] [:error] [pid 2908] [client 24.146.44.164:62618] mod_wsgi (pid=2908): Target WSGI script '/home/ec2-user/envClinicFlow/ClinicFlow/ClinicFlow/wsgi.py' cannot be loaded as Python module.
[Thu Apr 13 21:50:12.542521 2017] [:error] [pid 2908] [client 24.146.44.164:62618] mod_wsgi (pid=2908): Exception occurred processing WSGI script '/home/ec2-user/envClinicFlow/ClinicFlow/ClinicFlow/wsgi.py'.
[Thu Apr 13 21:50:12.543120 2017] [:error] [pid 2908] [client 24.146.44.164:62618] Traceback (most recent call last):
[Thu Apr 13 21:50:12.543172 2017] [:error] [pid 2908] [client 24.146.44.164:62618]   File "/home/ec2-user/envClinicFlow/ClinicFlow/ClinicFlow/wsgi.py", line 20, in <module>
[Thu Apr 13 21:50:12.543177 2017] [:error] [pid 2908] [client 24.146.44.164:62618]     application = get_wsgi_application()
[Thu Apr 13 21:50:12.543183 2017] [:error] [pid 2908] [client 24.146.44.164:62618]   File "/home/ec2-user/envClinicFlow/local/lib/python3.5/site-packages/django/core/wsgi.py", line 13, in get_wsgi_application
[Thu Apr 13 21:50:12.543186 2017] [:error] [pid 2908] [client 24.146.44.164:62618]     django.setup(set_prefix=False)
[Thu Apr 13 21:50:12.543191 2017] [:error] [pid 2908] [client 24.146.44.164:62618]   File "/home/ec2-user/envClinicFlow/local/lib/python3.5/site-packages/django/__init__.py", line 22, in setup
[Thu Apr 13 21:50:12.543193 2017] [:error] [pid 2908] [client 24.146.44.164:62618]     configure_logging(settings.LOGGING_CONFIG, settings.LOGGING)
[Thu Apr 13 21:50:12.543198 2017] [:error] [pid 2908] [client 24.146.44.164:62618]   File "/home/ec2-user/envClinicFlow/local/lib/python3.5/site-packages/django/conf/__init__.py", line 56, in __getattr__
[Thu Apr 13 21:50:12.543201 2017] [:error] [pid 2908] [client 24.146.44.164:62618]     self._setup(name)
[Thu Apr 13 21:50:12.543206 2017] [:error] [pid 2908] [client 24.146.44.164:62618]   File "/home/ec2-user/envClinicFlow/local/lib/python3.5/site-packages/django/conf/__init__.py", line 41, in _setup
[Thu Apr 13 21:50:12.543208 2017] [:error] [pid 2908] [client 24.146.44.164:62618]     self._wrapped = Settings(settings_module)
[Thu Apr 13 21:50:12.543213 2017] [:error] [pid 2908] [client 24.146.44.164:62618]   File "/home/ec2-user/envClinicFlow/local/lib/python3.5/site-packages/django/conf/__init__.py", line 110, in __init__
[Thu Apr 13 21:50:12.543215 2017] [:error] [pid 2908] [client 24.146.44.164:62618]     mod = importlib.import_module(self.SETTINGS_MODULE)
[Thu Apr 13 21:50:12.543220 2017] [:error] [pid 2908] [client 24.146.44.164:62618]   File "/home/ec2-user/envClinicFlow/lib64/python3.5/importlib/__init__.py", line 126, in import_module
[Thu Apr 13 21:50:12.543222 2017] [:error] [pid 2908] [client 24.146.44.164:62618]     return _bootstrap._gcd_import(name[level:], package, level)
[Thu Apr 13 21:50:12.543227 2017] [:error] [pid 2908] [client 24.146.44.164:62618]   File "<frozen importlib._bootstrap>", line 986, in _gcd_import
[Thu Apr 13 21:50:12.543232 2017] [:error] [pid 2908] [client 24.146.44.164:62618]   File "<frozen importlib._bootstrap>", line 969, in _find_and_load
[Thu Apr 13 21:50:12.543237 2017] [:error] [pid 2908] [client 24.146.44.164:62618]   File "<frozen importlib._bootstrap>", line 958, in _find_and_load_unlocked
[Thu Apr 13 21:50:12.543242 2017] [:error] [pid 2908] [client 24.146.44.164:62618]   File "<frozen importlib._bootstrap>", line 673, in _load_unlocked
[Thu Apr 13 21:50:12.543247 2017] [:error] [pid 2908] [client 24.146.44.164:62618]   File "<frozen importlib._bootstrap_external>", line 658, in exec_module
[Thu Apr 13 21:50:12.543252 2017] [:error] [pid 2908] [client 24.146.44.164:62618]   File "<frozen importlib._bootstrap_external>", line 764, in get_code
[Thu Apr 13 21:50:12.543257 2017] [:error] [pid 2908] [client 24.146.44.164:62618]   File "<frozen importlib._bootstrap_external>", line 724, in source_to_code
[Thu Apr 13 21:50:12.543262 2017] [:error] [pid 2908] [client 24.146.44.164:62618]   File "<frozen importlib._bootstrap>", line 222, in _call_with_frames_removed
[Thu Apr 13 21:50:12.543278 2017] [:error] [pid 2908] [client 24.146.44.164:62618]   File "/home/ec2-user/envClinicFlow/ClinicFlow/ClinicFlow/settings.py", line 159
[Thu Apr 13 21:50:12.543292 2017] [:error] [pid 2908] [client 24.146.44.164:62618]     }
[Thu Apr 13 21:50:12.543306 2017] [:error] [pid 2908] [client 24.146.44.164:62618]     ^
[Thu Apr 13 21:50:12.543314 2017] [:error] [pid 2908] [client 24.146.44.164:62618] SyntaxError: unexpected EOF while parsing
[Thu Apr 13 21:50:13.318214 2017] [:error] [pid 2906] [client 24.146.44.164:62619] mod_wsgi (pid=2906): Target WSGI script '/home/ec2-user/envClinicFlow/ClinicFlow/ClinicFlow/wsgi.py' cannot be loaded as Python module.
[Thu Apr 13 21:50:13.318266 2017] [:error] [pid 2906] [client 24.146.44.164:62619] mod_wsgi (pid=2906): Exception occurred processing WSGI script '/home/ec2-user/envClinicFlow/ClinicFlow/ClinicFlow/wsgi.py'.
[Thu Apr 13 21:50:13.318840 2017] [:error] [pid 2906] [client 24.146.44.164:62619] Traceback (most recent call last):
[Thu Apr 13 21:50:13.318892 2017] [:error] [pid 2906] [client 24.146.44.164:62619]   File "/home/ec2-user/envClinicFlow/ClinicFlow/ClinicFlow/wsgi.py", line 20, in <module>
[Thu Apr 13 21:50:13.318896 2017] [:error] [pid 2906] [client 24.146.44.164:62619]     application = get_wsgi_application()
[Thu Apr 13 21:50:13.318902 2017] [:error] [pid 2906] [client 24.146.44.164:62619]   File "/home/ec2-user/envClinicFlow/local/lib/python3.5/site-packages/django/core/wsgi.py", line 13, in get_wsgi_application
[Thu Apr 13 21:50:13.318905 2017] [:error] [pid 2906] [client 24.146.44.164:62619]     django.setup(set_prefix=False)
[Thu Apr 13 21:50:13.318911 2017] [:error] [pid 2906] [client 24.146.44.164:62619]   File "/home/ec2-user/envClinicFlow/local/lib/python3.5/site-packages/django/__init__.py", line 22, in setup
[Thu Apr 13 21:50:13.318913 2017] [:error] [pid 2906] [client 24.146.44.164:62619]     configure_logging(settings.LOGGING_CONFIG, settings.LOGGING)
[Thu Apr 13 21:50:13.318918 2017] [:error] [pid 2906] [client 24.146.44.164:62619]   File "/home/ec2-user/envClinicFlow/local/lib/python3.5/site-packages/django/conf/__init__.py", line 56, in __getattr__
[Thu Apr 13 21:50:13.318921 2017] [:error] [pid 2906] [client 24.146.44.164:62619]     self._setup(name)
[Thu Apr 13 21:50:13.318926 2017] [:error] [pid 2906] [client 24.146.44.164:62619]   File "/home/ec2-user/envClinicFlow/local/lib/python3.5/site-packages/django/conf/__init__.py", line 41, in _setup
[Thu Apr 13 21:50:13.318928 2017] [:error] [pid 2906] [client 24.146.44.164:62619]     self._wrapped = Settings(settings_module)
[Thu Apr 13 21:50:13.318933 2017] [:error] [pid 2906] [client 24.146.44.164:62619]   File "/home/ec2-user/envClinicFlow/local/lib/python3.5/site-packages/django/conf/__init__.py", line 110, in __init__
[Thu Apr 13 21:50:13.318936 2017] [:error] [pid 2906] [client 24.146.44.164:62619]     mod = importlib.import_module(self.SETTINGS_MODULE)
[Thu Apr 13 21:50:13.318940 2017] [:error] [pid 2906] [client 24.146.44.164:62619]   File "/home/ec2-user/envClinicFlow/lib64/python3.5/importlib/__init__.py", line 126, in import_module
[Thu Apr 13 21:50:13.318943 2017] [:error] [pid 2906] [client 24.146.44.164:62619]     return _bootstrap._gcd_import(name[level:], package, level)
[Thu Apr 13 21:50:13.318947 2017] [:error] [pid 2906] [client 24.146.44.164:62619]   File "<frozen importlib._bootstrap>", line 986, in _gcd_import
[Thu Apr 13 21:50:13.318952 2017] [:error] [pid 2906] [client 24.146.44.164:62619]   File "<frozen importlib._bootstrap>", line 969, in _find_and_load
[Thu Apr 13 21:50:13.318969 2017] [:error] [pid 2906] [client 24.146.44.164:62619]   File "<frozen importlib._bootstrap>", line 958, in _find_and_load_unlocked
[Thu Apr 13 21:50:13.318973 2017] [:error] [pid 2906] [client 24.146.44.164:62619]   File "<frozen importlib._bootstrap>", line 673, in _load_unlocked
[Thu Apr 13 21:50:13.318991 2017] [:error] [pid 2906] [client 24.146.44.164:62619]   File "<frozen importlib._bootstrap_external>", line 658, in exec_module
[Thu Apr 13 21:50:13.318995 2017] [:error] [pid 2906] [client 24.146.44.164:62619]   File "<frozen importlib._bootstrap_external>", line 764, in get_code
[Thu Apr 13 21:50:13.319007 2017] [:error] [pid 2906] [client 24.146.44.164:62619]   File "<frozen importlib._bootstrap_external>", line 724, in source_to_code
[Thu Apr 13 21:50:13.319012 2017] [:error] [pid 2906] [client 24.146.44.164:62619]   File "<frozen importlib._bootstrap>", line 222, in _call_with_frames_removed
[Thu Apr 13 21:50:13.319026 2017] [:error] [pid 2906] [client 24.146.44.164:62619]   File "/home/ec2-user/envClinicFlow/ClinicFlow/ClinicFlow/settings.py", line 159
[Thu Apr 13 21:50:13.319034 2017] [:error] [pid 2906] [client 24.146.44.164:62619]     }
[Thu Apr 13 21:50:13.319047 2017] [:error] [pid 2906] [client 24.146.44.164:62619]     ^
[Thu Apr 13 21:50:13.319054 2017] [:error] [pid 2906] [client 24.146.44.164:62619] SyntaxError: unexpected EOF while parsing
[Thu Apr 13 21:50:13.916815 2017] [:error] [pid 2910] [client 24.146.44.164:62620] mod_wsgi (pid=2910): Target WSGI script '/home/ec2-user/envClinicFlow/ClinicFlow/ClinicFlow/wsgi.py' cannot be loaded as Python module.
[Thu Apr 13 21:50:13.916865 2017] [:error] [pid 2910] [client 24.146.44.164:62620] mod_wsgi (pid=2910): Exception occurred processing WSGI script '/home/ec2-user/envClinicFlow/ClinicFlow/ClinicFlow/wsgi.py'.
[Thu Apr 13 21:50:13.917051 2017] [:error] [pid 2910] [client 24.146.44.164:62620] Traceback (most recent call last):
[Thu Apr 13 21:50:13.917097 2017] [:error] [pid 2910] [client 24.146.44.164:62620]   File "/home/ec2-user/envClinicFlow/ClinicFlow/ClinicFlow/wsgi.py", line 20, in <module>
[Thu Apr 13 21:50:13.917101 2017] [:error] [pid 2910] [client 24.146.44.164:62620]     application = get_wsgi_application()
[Thu Apr 13 21:50:13.917107 2017] [:error] [pid 2910] [client 24.146.44.164:62620]   File "/home/ec2-user/envClinicFlow/local/lib/python3.5/site-packages/django/core/wsgi.py", line 13, in get_wsgi_application
[Thu Apr 13 21:50:13.917109 2017] [:error] [pid 2910] [client 24.146.44.164:62620]     django.setup(set_prefix=False)
[Thu Apr 13 21:50:13.917115 2017] [:error] [pid 2910] [client 24.146.44.164:62620]   File "/home/ec2-user/envClinicFlow/local/lib/python3.5/site-packages/django/__init__.py", line 22, in setup
[Thu Apr 13 21:50:13.917117 2017] [:error] [pid 2910] [client 24.146.44.164:62620]     configure_logging(settings.LOGGING_CONFIG, settings.LOGGING)
[Thu Apr 13 21:50:13.917122 2017] [:error] [pid 2910] [client 24.146.44.164:62620]   File "/home/ec2-user/envClinicFlow/local/lib/python3.5/site-packages/django/conf/__init__.py", line 56, in __getattr__
[Thu Apr 13 21:50:13.917125 2017] [:error] [pid 2910] [client 24.146.44.164:62620]     self._setup(name)
[Thu Apr 13 21:50:13.917129 2017] [:error] [pid 2910] [client 24.146.44.164:62620]   File "/home/ec2-user/envClinicFlow/local/lib/python3.5/site-packages/django/conf/__init__.py", line 41, in _setup
[Thu Apr 13 21:50:13.917131 2017] [:error] [pid 2910] [client 24.146.44.164:62620]     self._wrapped = Settings(settings_module)
[Thu Apr 13 21:50:13.917136 2017] [:error] [pid 2910] [client 24.146.44.164:62620]   File "/home/ec2-user/envClinicFlow/local/lib/python3.5/site-packages/django/conf/__init__.py", line 110, in __init__
[Thu Apr 13 21:50:13.917138 2017] [:error] [pid 2910] [client 24.146.44.164:62620]     mod = importlib.import_module(self.SETTINGS_MODULE)
[Thu Apr 13 21:50:13.917142 2017] [:error] [pid 2910] [client 24.146.44.164:62620]   File "/home/ec2-user/envClinicFlow/lib64/python3.5/importlib/__init__.py", line 126, in import_module
[Thu Apr 13 21:50:13.917145 2017] [:error] [pid 2910] [client 24.146.44.164:62620]     return _bootstrap._gcd_import(name[level:], package, level)
[Thu Apr 13 21:50:13.917149 2017] [:error] [pid 2910] [client 24.146.44.164:62620]   File "<frozen importlib._bootstrap>", line 986, in _gcd_import
[Thu Apr 13 21:50:13.917153 2017] [:error] [pid 2910] [client 24.146.44.164:62620]   File "<frozen importlib._bootstrap>", line 969, in _find_and_load
[Thu Apr 13 21:50:13.917158 2017] [:error] [pid 2910] [client 24.146.44.164:62620]   File "<frozen importlib._bootstrap>", line 958, in _find_and_load_unlocked
[Thu Apr 13 21:50:13.917171 2017] [:error] [pid 2910] [client 24.146.44.164:62620]   File "<frozen importlib._bootstrap>", line 673, in _load_unlocked
[Thu Apr 13 21:50:13.917176 2017] [:error] [pid 2910] [client 24.146.44.164:62620]   File "<frozen importlib._bootstrap_external>", line 658, in exec_module
[Thu Apr 13 21:50:13.917231 2017] [:error] [pid 2910] [client 24.146.44.164:62620]   File "<frozen importlib._bootstrap_external>", line 764, in get_code
[Thu Apr 13 21:50:13.917237 2017] [:error] [pid 2910] [client 24.146.44.164:62620]   File "<frozen importlib._bootstrap_external>", line 724, in source_to_code
[Thu Apr 13 21:50:13.917242 2017] [:error] [pid 2910] [client 24.146.44.164:62620]   File "<frozen importlib._bootstrap>", line 222, in _call_with_frames_removed
[Thu Apr 13 21:50:13.917257 2017] [:error] [pid 2910] [client 24.146.44.164:62620]   File "/home/ec2-user/envClinicFlow/ClinicFlow/ClinicFlow/settings.py", line 159
[Thu Apr 13 21:50:13.917265 2017] [:error] [pid 2910] [client 24.146.44.164:62620]     }
[Thu Apr 13 21:50:13.917279 2017] [:error] [pid 2910] [client 24.146.44.164:62620]     ^
[Thu Apr 13 21:50:13.917286 2017] [:error] [pid 2910] [client 24.146.44.164:62620] SyntaxError: unexpected EOF while parsing
[Thu Apr 13 21:50:14.500848 2017] [:error] [pid 2907] [client 24.146.44.164:62621] mod_wsgi (pid=2907): Target WSGI script '/home/ec2-user/envClinicFlow/ClinicFlow/ClinicFlow/wsgi.py' cannot be loaded as Python module.
[Thu Apr 13 21:50:14.500896 2017] [:error] [pid 2907] [client 24.146.44.164:62621] mod_wsgi (pid=2907): Exception occurred processing WSGI script '/home/ec2-user/envClinicFlow/ClinicFlow/ClinicFlow/wsgi.py'.
[Thu Apr 13 21:50:14.501088 2017] [:error] [pid 2907] [client 24.146.44.164:62621] Traceback (most recent call last):
[Thu Apr 13 21:50:14.501133 2017] [:error] [pid 2907] [client 24.146.44.164:62621]   File "/home/ec2-user/envClinicFlow/ClinicFlow/ClinicFlow/wsgi.py", line 20, in <module>
[Thu Apr 13 21:50:14.501136 2017] [:error] [pid 2907] [client 24.146.44.164:62621]     application = get_wsgi_application()
[Thu Apr 13 21:50:14.501142 2017] [:error] [pid 2907] [client 24.146.44.164:62621]   File "/home/ec2-user/envClinicFlow/local/lib/python3.5/site-packages/django/core/wsgi.py", line 13, in get_wsgi_application
[Thu Apr 13 21:50:14.501145 2017] [:error] [pid 2907] [client 24.146.44.164:62621]     django.setup(set_prefix=False)
[Thu Apr 13 21:50:14.501151 2017] [:error] [pid 2907] [client 24.146.44.164:62621]   File "/home/ec2-user/envClinicFlow/local/lib/python3.5/site-packages/django/__init__.py", line 22, in setup
[Thu Apr 13 21:50:14.501153 2017] [:error] [pid 2907] [client 24.146.44.164:62621]     configure_logging(settings.LOGGING_CONFIG, settings.LOGGING)
[Thu Apr 13 21:50:14.501158 2017] [:error] [pid 2907] [client 24.146.44.164:62621]   File "/home/ec2-user/envClinicFlow/local/lib/python3.5/site-packages/django/conf/__init__.py", line 56, in __getattr__
[Thu Apr 13 21:50:14.501160 2017] [:error] [pid 2907] [client 24.146.44.164:62621]     self._setup(name)
[Thu Apr 13 21:50:14.501164 2017] [:error] [pid 2907] [client 24.146.44.164:62621]   File "/home/ec2-user/envClinicFlow/local/lib/python3.5/site-packages/django/conf/__init__.py", line 41, in _setup
[Thu Apr 13 21:50:14.501167 2017] [:error] [pid 2907] [client 24.146.44.164:62621]     self._wrapped = Settings(settings_module)
[Thu Apr 13 21:50:14.501171 2017] [:error] [pid 2907] [client 24.146.44.164:62621]   File "/home/ec2-user/envClinicFlow/local/lib/python3.5/site-packages/django/conf/__init__.py", line 110, in __init__
[Thu Apr 13 21:50:14.501173 2017] [:error] [pid 2907] [client 24.146.44.164:62621]     mod = importlib.import_module(self.SETTINGS_MODULE)
[Thu Apr 13 21:50:14.501204 2017] [:error] [pid 2907] [client 24.146.44.164:62621]   File "/home/ec2-user/envClinicFlow/lib64/python3.5/importlib/__init__.py", line 126, in import_module
[Thu Apr 13 21:50:14.501209 2017] [:error] [pid 2907] [client 24.146.44.164:62621]     return _bootstrap._gcd_import(name[level:], package, level)
[Thu Apr 13 21:50:14.501224 2017] [:error] [pid 2907] [client 24.146.44.164:62621]   File "<frozen importlib._bootstrap>", line 986, in _gcd_import
[Thu Apr 13 21:50:14.501229 2017] [:error] [pid 2907] [client 24.146.44.164:62621]   File "<frozen importlib._bootstrap>", line 969, in _find_and_load
[Thu Apr 13 21:50:14.501233 2017] [:error] [pid 2907] [client 24.146.44.164:62621]   File "<frozen importlib._bootstrap>", line 958, in _find_and_load_unlocked
[Thu Apr 13 21:50:14.501238 2017] [:error] [pid 2907] [client 24.146.44.164:62621]   File "<frozen importlib._bootstrap>", line 673, in _load_unlocked
[Thu Apr 13 21:50:14.501242 2017] [:error] [pid 2907] [client 24.146.44.164:62621]   File "<frozen importlib._bootstrap_external>", line 658, in exec_module
[Thu Apr 13 21:50:14.501247 2017] [:error] [pid 2907] [client 24.146.44.164:62621]   File "<frozen importlib._bootstrap_external>", line 764, in get_code
[Thu Apr 13 21:50:14.501251 2017] [:error] [pid 2907] [client 24.146.44.164:62621]   File "<frozen importlib._bootstrap_external>", line 724, in source_to_code
[Thu Apr 13 21:50:14.501256 2017] [:error] [pid 2907] [client 24.146.44.164:62621]   File "<frozen importlib._bootstrap>", line 222, in _call_with_frames_removed
[Thu Apr 13 21:50:14.501269 2017] [:error] [pid 2907] [client 24.146.44.164:62621]   File "/home/ec2-user/envClinicFlow/ClinicFlow/ClinicFlow/settings.py", line 159
[Thu Apr 13 21:50:14.501277 2017] [:error] [pid 2907] [client 24.146.44.164:62621]     }
[Thu Apr 13 21:50:14.501291 2017] [:error] [pid 2907] [client 24.146.44.164:62621]     ^
[Thu Apr 13 21:50:14.501298 2017] [:error] [pid 2907] [client 24.146.44.164:62621] SyntaxError: unexpected EOF while parsing
[Thu Apr 13 21:50:15.049355 2017] [:error] [pid 2909] [client 24.146.44.164:62622] mod_wsgi (pid=2909): Target WSGI script '/home/ec2-user/envClinicFlow/ClinicFlow/ClinicFlow/wsgi.py' cannot be loaded as Python module.
[Thu Apr 13 21:50:15.049449 2017] [:error] [pid 2909] [client 24.146.44.164:62622] mod_wsgi (pid=2909): Exception occurred processing WSGI script '/home/ec2-user/envClinicFlow/ClinicFlow/ClinicFlow/wsgi.py'.
[Thu Apr 13 21:50:15.050343 2017] [:error] [pid 2909] [client 24.146.44.164:62622] Traceback (most recent call last):
[Thu Apr 13 21:50:15.050391 2017] [:error] [pid 2909] [client 24.146.44.164:62622]   File "/home/ec2-user/envClinicFlow/ClinicFlow/ClinicFlow/wsgi.py", line 20, in <module>
[Thu Apr 13 21:50:15.050395 2017] [:error] [pid 2909] [client 24.146.44.164:62622]     application = get_wsgi_application()
[Thu Apr 13 21:50:15.050401 2017] [:error] [pid 2909] [client 24.146.44.164:62622]   File "/home/ec2-user/envClinicFlow/local/lib/python3.5/site-packages/django/core/wsgi.py", line 13, in get_wsgi_application
[Thu Apr 13 21:50:15.050403 2017] [:error] [pid 2909] [client 24.146.44.164:62622]     django.setup(set_prefix=False)
[Thu Apr 13 21:50:15.050409 2017] [:error] [pid 2909] [client 24.146.44.164:62622]   File "/home/ec2-user/envClinicFlow/local/lib/python3.5/site-packages/django/__init__.py", line 22, in setup
[Thu Apr 13 21:50:15.050411 2017] [:error] [pid 2909] [client 24.146.44.164:62622]     configure_logging(settings.LOGGING_CONFIG, settings.LOGGING)
[Thu Apr 13 21:50:15.050416 2017] [:error] [pid 2909] [client 24.146.44.164:62622]   File "/home/ec2-user/envClinicFlow/local/lib/python3.5/site-packages/django/conf/__init__.py", line 56, in __getattr__
[Thu Apr 13 21:50:15.050419 2017] [:error] [pid 2909] [client 24.146.44.164:62622]     self._setup(name)
[Thu Apr 13 21:50:15.050423 2017] [:error] [pid 2909] [client 24.146.44.164:62622]   File "/home/ec2-user/envClinicFlow/local/lib/python3.5/site-packages/django/conf/__init__.py", line 41, in _setup
[Thu Apr 13 21:50:15.050425 2017] [:error] [pid 2909] [client 24.146.44.164:62622]     self._wrapped = Settings(settings_module)
[Thu Apr 13 21:50:15.050430 2017] [:error] [pid 2909] [client 24.146.44.164:62622]   File "/home/ec2-user/envClinicFlow/local/lib/python3.5/site-packages/django/conf/__init__.py", line 110, in __init__
[Thu Apr 13 21:50:15.050437 2017] [:error] [pid 2909] [client 24.146.44.164:62622]     mod = importlib.import_module(self.SETTINGS_MODULE)
[Thu Apr 13 21:50:15.050442 2017] [:error] [pid 2909] [client 24.146.44.164:62622]   File "/home/ec2-user/envClinicFlow/lib64/python3.5/importlib/__init__.py", line 126, in import_module
[Thu Apr 13 21:50:15.050444 2017] [:error] [pid 2909] [client 24.146.44.164:62622]     return _bootstrap._gcd_import(name[level:], package, level)
[Thu Apr 13 21:50:15.050449 2017] [:error] [pid 2909] [client 24.146.44.164:62622]   File "<frozen importlib._bootstrap>", line 986, in _gcd_import
[Thu Apr 13 21:50:15.050453 2017] [:error] [pid 2909] [client 24.146.44.164:62622]   File "<frozen importlib._bootstrap>", line 969, in _find_and_load
[Thu Apr 13 21:50:15.050458 2017] [:error] [pid 2909] [client 24.146.44.164:62622]   File "<frozen importlib._bootstrap>", line 958, in _find_and_load_unlocked
[Thu Apr 13 21:50:15.050462 2017] [:error] [pid 2909] [client 24.146.44.164:62622]   File "<frozen importlib._bootstrap>", line 673, in _load_unlocked
[Thu Apr 13 21:50:15.050467 2017] [:error] [pid 2909] [client 24.146.44.164:62622]   File "<frozen importlib._bootstrap_external>", line 658, in exec_module
[Thu Apr 13 21:50:15.050471 2017] [:error] [pid 2909] [client 24.146.44.164:62622]   File "<frozen importlib._bootstrap_external>", line 764, in get_code
[Thu Apr 13 21:50:15.050476 2017] [:error] [pid 2909] [client 24.146.44.164:62622]   File "<frozen importlib._bootstrap_external>", line 724, in source_to_code
[Thu Apr 13 21:50:15.050480 2017] [:error] [pid 2909] [client 24.146.44.164:62622]   File "<frozen importlib._bootstrap>", line 222, in _call_with_frames_removed
[Thu Apr 13 21:50:15.050492 2017] [:error] [pid 2909] [client 24.146.44.164:62622]   File "/home/ec2-user/envClinicFlow/ClinicFlow/ClinicFlow/settings.py", line 159
[Thu Apr 13 21:50:15.050500 2017] [:error] [pid 2909] [client 24.146.44.164:62622]     }
[Thu Apr 13 21:50:15.050513 2017] [:error] [pid 2909] [client 24.146.44.164:62622]     ^
[Thu Apr 13 21:50:15.050520 2017] [:error] [pid 2909] [client 24.146.44.164:62622] SyntaxError: unexpected EOF while parsing
[Thu Apr 13 21:50:15.633406 2017] [:error] [pid 2908] [client 24.146.44.164:62623] mod_wsgi (pid=2908): Target WSGI script '/home/ec2-user/envClinicFlow/ClinicFlow/ClinicFlow/wsgi.py' cannot be loaded as Python module.
[Thu Apr 13 21:50:15.633454 2017] [:error] [pid 2908] [client 24.146.44.164:62623] mod_wsgi (pid=2908): Exception occurred processing WSGI script '/home/ec2-user/envClinicFlow/ClinicFlow/ClinicFlow/wsgi.py'.
[Thu Apr 13 21:50:15.633636 2017] [:error] [pid 2908] [client 24.146.44.164:62623] Traceback (most recent call last):
[Thu Apr 13 21:50:15.633683 2017] [:error] [pid 2908] [client 24.146.44.164:62623]   File "/home/ec2-user/envClinicFlow/ClinicFlow/ClinicFlow/wsgi.py", line 20, in <module>
[Thu Apr 13 21:50:15.633687 2017] [:error] [pid 2908] [client 24.146.44.164:62623]     application = get_wsgi_application()
[Thu Apr 13 21:50:15.633692 2017] [:error] [pid 2908] [client 24.146.44.164:62623]   File "/home/ec2-user/envClinicFlow/local/lib/python3.5/site-packages/django/core/wsgi.py", line 13, in get_wsgi_application
[Thu Apr 13 21:50:15.633695 2017] [:error] [pid 2908] [client 24.146.44.164:62623]     django.setup(set_prefix=False)
[Thu Apr 13 21:50:15.633714 2017] [:error] [pid 2908] [client 24.146.44.164:62623]   File "/home/ec2-user/envClinicFlow/local/lib/python3.5/site-packages/django/__init__.py", line 22, in setup
[Thu Apr 13 21:50:15.633716 2017] [:error] [pid 2908] [client 24.146.44.164:62623]     configure_logging(settings.LOGGING_CONFIG, settings.LOGGING)
[Thu Apr 13 21:50:15.633722 2017] [:error] [pid 2908] [client 24.146.44.164:62623]   File "/home/ec2-user/envClinicFlow/local/lib/python3.5/site-packages/django/conf/__init__.py", line 56, in __getattr__
[Thu Apr 13 21:50:15.633724 2017] [:error] [pid 2908] [client 24.146.44.164:62623]     self._setup(name)
[Thu Apr 13 21:50:15.633729 2017] [:error] [pid 2908] [client 24.146.44.164:62623]   File "/home/ec2-user/envClinicFlow/local/lib/python3.5/site-packages/django/conf/__init__.py", line 41, in _setup
[Thu Apr 13 21:50:15.633739 2017] [:error] [pid 2908] [client 24.146.44.164:62623]     self._wrapped = Settings(settings_module)
[Thu Apr 13 21:50:15.633745 2017] [:error] [pid 2908] [client 24.146.44.164:62623]   File "/home/ec2-user/envClinicFlow/local/lib/python3.5/site-packages/django/conf/__init__.py", line 110, in __init__
[Thu Apr 13 21:50:15.633747 2017] [:error] [pid 2908] [client 24.146.44.164:62623]     mod = importlib.import_module(self.SETTINGS_MODULE)
[Thu Apr 13 21:50:15.633752 2017] [:error] [pid 2908] [client 24.146.44.164:62623]   File "/home/ec2-user/envClinicFlow/lib64/python3.5/importlib/__init__.py", line 126, in import_module
[Thu Apr 13 21:50:15.633754 2017] [:error] [pid 2908] [client 24.146.44.164:62623]     return _bootstrap._gcd_import(name[level:], package, level)
[Thu Apr 13 21:50:15.633759 2017] [:error] [pid 2908] [client 24.146.44.164:62623]   File "<frozen importlib._bootstrap>", line 986, in _gcd_import
[Thu Apr 13 21:50:15.633764 2017] [:error] [pid 2908] [client 24.146.44.164:62623]   File "<frozen importlib._bootstrap>", line 969, in _find_and_load
[Thu Apr 13 21:50:15.633769 2017] [:error] [pid 2908] [client 24.146.44.164:62623]   File "<frozen importlib._bootstrap>", line 958, in _find_and_load_unlocked
[Thu Apr 13 21:50:15.633774 2017] [:error] [pid 2908] [client 24.146.44.164:62623]   File "<frozen importlib._bootstrap>", line 673, in _load_unlocked
[Thu Apr 13 21:50:15.633779 2017] [:error] [pid 2908] [client 24.146.44.164:62623]   File "<frozen importlib._bootstrap_external>", line 658, in exec_module
[Thu Apr 13 21:50:15.633784 2017] [:error] [pid 2908] [client 24.146.44.164:62623]   File "<frozen importlib._bootstrap_external>", line 764, in get_code
[Thu Apr 13 21:50:15.633789 2017] [:error] [pid 2908] [client 24.146.44.164:62623]   File "<frozen importlib._bootstrap_external>", line 724, in source_to_code
[Thu Apr 13 21:50:15.633793 2017] [:error] [pid 2908] [client 24.146.44.164:62623]   File "<frozen importlib._bootstrap>", line 222, in _call_with_frames_removed
[Thu Apr 13 21:50:15.633807 2017] [:error] [pid 2908] [client 24.146.44.164:62623]   File "/home/ec2-user/envClinicFlow/ClinicFlow/ClinicFlow/settings.py", line 159
[Thu Apr 13 21:50:15.633815 2017] [:error] [pid 2908] [client 24.146.44.164:62623]     }
[Thu Apr 13 21:50:15.633829 2017] [:error] [pid 2908] [client 24.146.44.164:62623]     ^
[Thu Apr 13 21:50:15.633836 2017] [:error] [pid 2908] [client 24.146.44.164:62623] SyntaxError: unexpected EOF while parsing
[Thu Apr 13 21:50:16.171365 2017] [:error] [pid 2906] [client 24.146.44.164:62624] mod_wsgi (pid=2906): Target WSGI script '/home/ec2-user/envClinicFlow/ClinicFlow/ClinicFlow/wsgi.py' cannot be loaded as Python module.
[Thu Apr 13 21:50:16.171411 2017] [:error] [pid 2906] [client 24.146.44.164:62624] mod_wsgi (pid=2906): Exception occurred processing WSGI script '/home/ec2-user/envClinicFlow/ClinicFlow/ClinicFlow/wsgi.py'.
[Thu Apr 13 21:50:16.171594 2017] [:error] [pid 2906] [client 24.146.44.164:62624] Traceback (most recent call last):
[Thu Apr 13 21:50:16.171644 2017] [:error] [pid 2906] [client 24.146.44.164:62624]   File "/home/ec2-user/envClinicFlow/ClinicFlow/ClinicFlow/wsgi.py", line 20, in <module>
[Thu Apr 13 21:50:16.171648 2017] [:error] [pid 2906] [client 24.146.44.164:62624]     application = get_wsgi_application()
[Thu Apr 13 21:50:16.171655 2017] [:error] [pid 2906] [client 24.146.44.164:62624]   File "/home/ec2-user/envClinicFlow/local/lib/python3.5/site-packages/django/core/wsgi.py", line 13, in get_wsgi_application
[Thu Apr 13 21:50:16.171658 2017] [:error] [pid 2906] [client 24.146.44.164:62624]     django.setup(set_prefix=False)
[Thu Apr 13 21:50:16.171663 2017] [:error] [pid 2906] [client 24.146.44.164:62624]   File "/home/ec2-user/envClinicFlow/local/lib/python3.5/site-packages/django/__init__.py", line 22, in setup
[Thu Apr 13 21:50:16.171666 2017] [:error] [pid 2906] [client 24.146.44.164:62624]     configure_logging(settings.LOGGING_CONFIG, settings.LOGGING)
[Thu Apr 13 21:50:16.171679 2017] [:error] [pid 2906] [client 24.146.44.164:62624]   File "/home/ec2-user/envClinicFlow/local/lib/python3.5/site-packages/django/conf/__init__.py", line 56, in __getattr__
[Thu Apr 13 21:50:16.171682 2017] [:error] [pid 2906] [client 24.146.44.164:62624]     self._setup(name)
[Thu Apr 13 21:50:16.171687 2017] [:error] [pid 2906] [client 24.146.44.164:62624]   File "/home/ec2-user/envClinicFlow/local/lib/python3.5/site-packages/django/conf/__init__.py", line 41, in _setup
[Thu Apr 13 21:50:16.171689 2017] [:error] [pid 2906] [client 24.146.44.164:62624]     self._wrapped = Settings(settings_module)
[Thu Apr 13 21:50:16.171694 2017] [:error] [pid 2906] [client 24.146.44.164:62624]   File "/home/ec2-user/envClinicFlow/local/lib/python3.5/site-packages/django/conf/__init__.py", line 110, in __init__
[Thu Apr 13 21:50:16.171696 2017] [:error] [pid 2906] [client 24.146.44.164:62624]     mod = importlib.import_module(self.SETTINGS_MODULE)
[Thu Apr 13 21:50:16.171701 2017] [:error] [pid 2906] [client 24.146.44.164:62624]   File "/home/ec2-user/envClinicFlow/lib64/python3.5/importlib/__init__.py", line 126, in import_module
[Thu Apr 13 21:50:16.171703 2017] [:error] [pid 2906] [client 24.146.44.164:62624]     return _bootstrap._gcd_import(name[level:], package, level)
[Thu Apr 13 21:50:16.171708 2017] [:error] [pid 2906] [client 24.146.44.164:62624]   File "<frozen importlib._bootstrap>", line 986, in _gcd_import
[Thu Apr 13 21:50:16.171713 2017] [:error] [pid 2906] [client 24.146.44.164:62624]   File "<frozen importlib._bootstrap>", line 969, in _find_and_load
[Thu Apr 13 21:50:16.171718 2017] [:error] [pid 2906] [client 24.146.44.164:62624]   File "<frozen importlib._bootstrap>", line 958, in _find_and_load_unlocked
[Thu Apr 13 21:50:16.171723 2017] [:error] [pid 2906] [client 24.146.44.164:62624]   File "<frozen importlib._bootstrap>", line 673, in _load_unlocked
[Thu Apr 13 21:50:16.171728 2017] [:error] [pid 2906] [client 24.146.44.164:62624]   File "<frozen importlib._bootstrap_external>", line 658, in exec_module
[Thu Apr 13 21:50:16.171733 2017] [:error] [pid 2906] [client 24.146.44.164:62624]   File "<frozen importlib._bootstrap_external>", line 764, in get_code
[Thu Apr 13 21:50:16.171737 2017] [:error] [pid 2906] [client 24.146.44.164:62624]   File "<frozen importlib._bootstrap_external>", line 724, in source_to_code
[Thu Apr 13 21:50:16.171742 2017] [:error] [pid 2906] [client 24.146.44.164:62624]   File "<frozen importlib._bootstrap>", line 222, in _call_with_frames_removed
[Thu Apr 13 21:50:16.171756 2017] [:error] [pid 2906] [client 24.146.44.164:62624]   File "/home/ec2-user/envClinicFlow/ClinicFlow/ClinicFlow/settings.py", line 159
[Thu Apr 13 21:50:16.171764 2017] [:error] [pid 2906] [client 24.146.44.164:62624]     }
[Thu Apr 13 21:50:16.171779 2017] [:error] [pid 2906] [client 24.146.44.164:62624]     ^
[Thu Apr 13 21:50:16.171787 2017] [:error] [pid 2906] [client 24.146.44.164:62624] SyntaxError: unexpected EOF while parsing
[Thu Apr 13 21:50:18.117527 2017] [:error] [pid 2910] [client 24.146.44.164:62626] mod_wsgi (pid=2910): Target WSGI script '/home/ec2-user/envClinicFlow/ClinicFlow/ClinicFlow/wsgi.py' cannot be loaded as Python module.
[Thu Apr 13 21:50:18.117576 2017] [:error] [pid 2910] [client 24.146.44.164:62626] mod_wsgi (pid=2910): Exception occurred processing WSGI script '/home/ec2-user/envClinicFlow/ClinicFlow/ClinicFlow/wsgi.py'.
[Thu Apr 13 21:50:18.117762 2017] [:error] [pid 2910] [client 24.146.44.164:62626] Traceback (most recent call last):
[Thu Apr 13 21:50:18.117813 2017] [:error] [pid 2910] [client 24.146.44.164:62626]   File "/home/ec2-user/envClinicFlow/ClinicFlow/ClinicFlow/wsgi.py", line 20, in <module>
[Thu Apr 13 21:50:18.117817 2017] [:error] [pid 2910] [client 24.146.44.164:62626]     application = get_wsgi_application()
[Thu Apr 13 21:50:18.117824 2017] [:error] [pid 2910] [client 24.146.44.164:62626]   File "/home/ec2-user/envClinicFlow/local/lib/python3.5/site-packages/django/core/wsgi.py", line 13, in get_wsgi_application
[Thu Apr 13 21:50:18.117835 2017] [:error] [pid 2910] [client 24.146.44.164:62626]     django.setup(set_prefix=False)
[Thu Apr 13 21:50:18.117842 2017] [:error] [pid 2910] [client 24.146.44.164:62626]   File "/home/ec2-user/envClinicFlow/local/lib/python3.5/site-packages/django/__init__.py", line 22, in setup
[Thu Apr 13 21:50:18.117844 2017] [:error] [pid 2910] [client 24.146.44.164:62626]     configure_logging(settings.LOGGING_CONFIG, settings.LOGGING)
[Thu Apr 13 21:50:18.117850 2017] [:error] [pid 2910] [client 24.146.44.164:62626]   File "/home/ec2-user/envClinicFlow/local/lib/python3.5/site-packages/django/conf/__init__.py", line 56, in __getattr__
[Thu Apr 13 21:50:18.117852 2017] [:error] [pid 2910] [client 24.146.44.164:62626]     self._setup(name)
[Thu Apr 13 21:50:18.117857 2017] [:error] [pid 2910] [client 24.146.44.164:62626]   File "/home/ec2-user/envClinicFlow/local/lib/python3.5/site-packages/django/conf/__init__.py", line 41, in _setup
[Thu Apr 13 21:50:18.117859 2017] [:error] [pid 2910] [client 24.146.44.164:62626]     self._wrapped = Settings(settings_module)
[Thu Apr 13 21:50:18.117864 2017] [:error] [pid 2910] [client 24.146.44.164:62626]   File "/home/ec2-user/envClinicFlow/local/lib/python3.5/site-packages/django/conf/__init__.py", line 110, in __init__
[Thu Apr 13 21:50:18.117866 2017] [:error] [pid 2910] [client 24.146.44.164:62626]     mod = importlib.import_module(self.SETTINGS_MODULE)
[Thu Apr 13 21:50:18.117871 2017] [:error] [pid 2910] [client 24.146.44.164:62626]   File "/home/ec2-user/envClinicFlow/lib64/python3.5/importlib/__init__.py", line 126, in import_module
[Thu Apr 13 21:50:18.117873 2017] [:error] [pid 2910] [client 24.146.44.164:62626]     return _bootstrap._gcd_import(name[level:], package, level)
[Thu Apr 13 21:50:18.117878 2017] [:error] [pid 2910] [client 24.146.44.164:62626]   File "<frozen importlib._bootstrap>", line 986, in _gcd_import
[Thu Apr 13 21:50:18.117883 2017] [:error] [pid 2910] [client 24.146.44.164:62626]   File "<frozen importlib._bootstrap>", line 969, in _find_and_load
[Thu Apr 13 21:50:18.117888 2017] [:error] [pid 2910] [client 24.146.44.164:62626]   File "<frozen importlib._bootstrap>", line 958, in _find_and_load_unlocked
[Thu Apr 13 21:50:18.117893 2017] [:error] [pid 2910] [client 24.146.44.164:62626]   File "<frozen importlib._bootstrap>", line 673, in _load_unlocked
[Thu Apr 13 21:50:18.117897 2017] [:error] [pid 2910] [client 24.146.44.164:62626]   File "<frozen importlib._bootstrap_external>", line 658, in exec_module
[Thu Apr 13 21:50:18.117902 2017] [:error] [pid 2910] [client 24.146.44.164:62626]   File "<frozen importlib._bootstrap_external>", line 764, in get_code
[Thu Apr 13 21:50:18.117907 2017] [:error] [pid 2910] [client 24.146.44.164:62626]   File "<frozen importlib._bootstrap_external>", line 724, in source_to_code
[Thu Apr 13 21:50:18.117912 2017] [:error] [pid 2910] [client 24.146.44.164:62626]   File "<frozen importlib._bootstrap>", line 222, in _call_with_frames_removed
[Thu Apr 13 21:50:18.117927 2017] [:error] [pid 2910] [client 24.146.44.164:62626]   File "/home/ec2-user/envClinicFlow/ClinicFlow/ClinicFlow/settings.py", line 159
[Thu Apr 13 21:50:18.117935 2017] [:error] [pid 2910] [client 24.146.44.164:62626]     }
[Thu Apr 13 21:50:18.117950 2017] [:error] [pid 2910] [client 24.146.44.164:62626]     ^
[Thu Apr 13 21:50:18.117958 2017] [:error] [pid 2910] [client 24.146.44.164:62626] SyntaxError: unexpected EOF while parsing
[Thu Apr 13 21:50:18.901601 2017] [:error] [pid 2907] [client 24.146.44.164:62625] mod_wsgi (pid=2907): Target WSGI script '/home/ec2-user/envClinicFlow/ClinicFlow/ClinicFlow/wsgi.py' cannot be loaded as Python module.
[Thu Apr 13 21:50:18.901648 2017] [:error] [pid 2907] [client 24.146.44.164:62625] mod_wsgi (pid=2907): Exception occurred processing WSGI script '/home/ec2-user/envClinicFlow/ClinicFlow/ClinicFlow/wsgi.py'.
[Thu Apr 13 21:50:18.901829 2017] [:error] [pid 2907] [client 24.146.44.164:62625] Traceback (most recent call last):
[Thu Apr 13 21:50:18.901884 2017] [:error] [pid 2907] [client 24.146.44.164:62625]   File "/home/ec2-user/envClinicFlow/ClinicFlow/ClinicFlow/wsgi.py", line 20, in <module>
[Thu Apr 13 21:50:18.901896 2017] [:error] [pid 2907] [client 24.146.44.164:62625]     application = get_wsgi_application()
[Thu Apr 13 21:50:18.901904 2017] [:error] [pid 2907] [client 24.146.44.164:62625]   File "/home/ec2-user/envClinicFlow/local/lib/python3.5/site-packages/django/core/wsgi.py", line 13, in get_wsgi_application
[Thu Apr 13 21:50:18.901907 2017] [:error] [pid 2907] [client 24.146.44.164:62625]     django.setup(set_prefix=False)
[Thu Apr 13 21:50:18.901913 2017] [:error] [pid 2907] [client 24.146.44.164:62625]   File "/home/ec2-user/envClinicFlow/local/lib/python3.5/site-packages/django/__init__.py", line 22, in setup
[Thu Apr 13 21:50:18.901915 2017] [:error] [pid 2907] [client 24.146.44.164:62625]     configure_logging(settings.LOGGING_CONFIG, settings.LOGGING)
[Thu Apr 13 21:50:18.901921 2017] [:error] [pid 2907] [client 24.146.44.164:62625]   File "/home/ec2-user/envClinicFlow/local/lib/python3.5/site-packages/django/conf/__init__.py", line 56, in __getattr__
[Thu Apr 13 21:50:18.901923 2017] [:error] [pid 2907] [client 24.146.44.164:62625]     self._setup(name)
[Thu Apr 13 21:50:18.901928 2017] [:error] [pid 2907] [client 24.146.44.164:62625]   File "/home/ec2-user/envClinicFlow/local/lib/python3.5/site-packages/django/conf/__init__.py", line 41, in _setup
[Thu Apr 13 21:50:18.901930 2017] [:error] [pid 2907] [client 24.146.44.164:62625]     self._wrapped = Settings(settings_module)
[Thu Apr 13 21:50:18.901935 2017] [:error] [pid 2907] [client 24.146.44.164:62625]   File "/home/ec2-user/envClinicFlow/local/lib/python3.5/site-packages/django/conf/__init__.py", line 110, in __init__
[Thu Apr 13 21:50:18.901937 2017] [:error] [pid 2907] [client 24.146.44.164:62625]     mod = importlib.import_module(self.SETTINGS_MODULE)
[Thu Apr 13 21:50:18.901942 2017] [:error] [pid 2907] [client 24.146.44.164:62625]   File "/home/ec2-user/envClinicFlow/lib64/python3.5/importlib/__init__.py", line 126, in import_module
[Thu Apr 13 21:50:18.901944 2017] [:error] [pid 2907] [client 24.146.44.164:62625]     return _bootstrap._gcd_import(name[level:], package, level)
[Thu Apr 13 21:50:18.901949 2017] [:error] [pid 2907] [client 24.146.44.164:62625]   File "<frozen importlib._bootstrap>", line 986, in _gcd_import
[Thu Apr 13 21:50:18.901954 2017] [:error] [pid 2907] [client 24.146.44.164:62625]   File "<frozen importlib._bootstrap>", line 969, in _find_and_load
[Thu Apr 13 21:50:18.901960 2017] [:error] [pid 2907] [client 24.146.44.164:62625]   File "<frozen importlib._bootstrap>", line 958, in _find_and_load_unlocked
[Thu Apr 13 21:50:18.901965 2017] [:error] [pid 2907] [client 24.146.44.164:62625]   File "<frozen importlib._bootstrap>", line 673, in _load_unlocked
[Thu Apr 13 21:50:18.901970 2017] [:error] [pid 2907] [client 24.146.44.164:62625]   File "<frozen importlib._bootstrap_external>", line 658, in exec_module
[Thu Apr 13 21:50:18.901975 2017] [:error] [pid 2907] [client 24.146.44.164:62625]   File "<frozen importlib._bootstrap_external>", line 764, in get_code
[Thu Apr 13 21:50:18.901979 2017] [:error] [pid 2907] [client 24.146.44.164:62625]   File "<frozen importlib._bootstrap_external>", line 724, in source_to_code
[Thu Apr 13 21:50:18.901984 2017] [:error] [pid 2907] [client 24.146.44.164:62625]   File "<frozen importlib._bootstrap>", line 222, in _call_with_frames_removed
[Thu Apr 13 21:50:18.902012 2017] [:error] [pid 2907] [client 24.146.44.164:62625]   File "/home/ec2-user/envClinicFlow/ClinicFlow/ClinicFlow/settings.py", line 159
[Thu Apr 13 21:50:18.902020 2017] [:error] [pid 2907] [client 24.146.44.164:62625]     }
[Thu Apr 13 21:50:18.902034 2017] [:error] [pid 2907] [client 24.146.44.164:62625]     ^
[Thu Apr 13 21:50:18.902041 2017] [:error] [pid 2907] [client 24.146.44.164:62625] SyntaxError: unexpected EOF while parsing
[Thu Apr 13 21:50:22.286454 2017] [:error] [pid 2909] [client 24.146.44.164:62627] mod_wsgi (pid=2909): Target WSGI script '/home/ec2-user/envClinicFlow/ClinicFlow/ClinicFlow/wsgi.py' cannot be loaded as Python module.
[Thu Apr 13 21:50:22.286536 2017] [:error] [pid 2909] [client 24.146.44.164:62627] mod_wsgi (pid=2909): Exception occurred processing WSGI script '/home/ec2-user/envClinicFlow/ClinicFlow/ClinicFlow/wsgi.py'.
[Thu Apr 13 21:50:22.286760 2017] [:error] [pid 2909] [client 24.146.44.164:62627] Traceback (most recent call last):
[Thu Apr 13 21:50:22.286820 2017] [:error] [pid 2909] [client 24.146.44.164:62627]   File "/home/ec2-user/envClinicFlow/ClinicFlow/ClinicFlow/wsgi.py", line 20, in <module>
[Thu Apr 13 21:50:22.286825 2017] [:error] [pid 2909] [client 24.146.44.164:62627]     application = get_wsgi_application()
[Thu Apr 13 21:50:22.286832 2017] [:error] [pid 2909] [client 24.146.44.164:62627]   File "/home/ec2-user/envClinicFlow/local/lib/python3.5/site-packages/django/core/wsgi.py", line 13, in get_wsgi_application
[Thu Apr 13 21:50:22.286835 2017] [:error] [pid 2909] [client 24.146.44.164:62627]     django.setup(set_prefix=False)
[Thu Apr 13 21:50:22.286842 2017] [:error] [pid 2909] [client 24.146.44.164:62627]   File "/home/ec2-user/envClinicFlow/local/lib/python3.5/site-packages/django/__init__.py", line 22, in setup
[Thu Apr 13 21:50:22.286845 2017] [:error] [pid 2909] [client 24.146.44.164:62627]     configure_logging(settings.LOGGING_CONFIG, settings.LOGGING)
[Thu Apr 13 21:50:22.286851 2017] [:error] [pid 2909] [client 24.146.44.164:62627]   File "/home/ec2-user/envClinicFlow/local/lib/python3.5/site-packages/django/conf/__init__.py", line 56, in __getattr__
[Thu Apr 13 21:50:22.286853 2017] [:error] [pid 2909] [client 24.146.44.164:62627]     self._setup(name)
[Thu Apr 13 21:50:22.286858 2017] [:error] [pid 2909] [client 24.146.44.164:62627]   File "/home/ec2-user/envClinicFlow/local/lib/python3.5/site-packages/django/conf/__init__.py", line 41, in _setup
[Thu Apr 13 21:50:22.286861 2017] [:error] [pid 2909] [client 24.146.44.164:62627]     self._wrapped = Settings(settings_module)
[Thu Apr 13 21:50:22.286865 2017] [:error] [pid 2909] [client 24.146.44.164:62627]   File "/home/ec2-user/envClinicFlow/local/lib/python3.5/site-packages/django/conf/__init__.py", line 110, in __init__
[Thu Apr 13 21:50:22.286868 2017] [:error] [pid 2909] [client 24.146.44.164:62627]     mod = importlib.import_module(self.SETTINGS_MODULE)
[Thu Apr 13 21:50:22.286872 2017] [:error] [pid 2909] [client 24.146.44.164:62627]   File "/home/ec2-user/envClinicFlow/lib64/python3.5/importlib/__init__.py", line 126, in import_module
[Thu Apr 13 21:50:22.286875 2017] [:error] [pid 2909] [client 24.146.44.164:62627]     return _bootstrap._gcd_import(name[level:], package, level)
[Thu Apr 13 21:50:22.286880 2017] [:error] [pid 2909] [client 24.146.44.164:62627]   File "<frozen importlib._bootstrap>", line 986, in _gcd_import
[Thu Apr 13 21:50:22.286885 2017] [:error] [pid 2909] [client 24.146.44.164:62627]   File "<frozen importlib._bootstrap>", line 969, in _find_and_load
[Thu Apr 13 21:50:22.286891 2017] [:error] [pid 2909] [client 24.146.44.164:62627]   File "<frozen importlib._bootstrap>", line 958, in _find_and_load_unlocked
[Thu Apr 13 21:50:22.286896 2017] [:error] [pid 2909] [client 24.146.44.164:62627]   File "<frozen importlib._bootstrap>", line 673, in _load_unlocked
[Thu Apr 13 21:50:22.286901 2017] [:error] [pid 2909] [client 24.146.44.164:62627]   File "<frozen importlib._bootstrap_external>", line 658, in exec_module
[Thu Apr 13 21:50:22.286906 2017] [:error] [pid 2909] [client 24.146.44.164:62627]   File "<frozen importlib._bootstrap_external>", line 764, in get_code
[Thu Apr 13 21:50:22.286911 2017] [:error] [pid 2909] [client 24.146.44.164:62627]   File "<frozen importlib._bootstrap_external>", line 724, in source_to_code
[Thu Apr 13 21:50:22.286916 2017] [:error] [pid 2909] [client 24.146.44.164:62627]   File "<frozen importlib._bootstrap>", line 222, in _call_with_frames_removed
[Thu Apr 13 21:50:22.286933 2017] [:error] [pid 2909] [client 24.146.44.164:62627]   File "/home/ec2-user/envClinicFlow/ClinicFlow/ClinicFlow/settings.py", line 159
[Thu Apr 13 21:50:22.286943 2017] [:error] [pid 2909] [client 24.146.44.164:62627]     }
[Thu Apr 13 21:50:22.286968 2017] [:error] [pid 2909] [client 24.146.44.164:62627]     ^
[Thu Apr 13 21:50:22.286979 2017] [:error] [pid 2909] [client 24.146.44.164:62627] SyntaxError: unexpected EOF while parsing
[Thu Apr 13 21:50:25.518863 2017] [:error] [pid 2908] [client 24.146.44.164:62628] mod_wsgi (pid=2908): Target WSGI script '/home/ec2-user/envClinicFlow/ClinicFlow/ClinicFlow/wsgi.py' cannot be loaded as Python module.
[Thu Apr 13 21:50:25.518940 2017] [:error] [pid 2908] [client 24.146.44.164:62628] mod_wsgi (pid=2908): Exception occurred processing WSGI script '/home/ec2-user/envClinicFlow/ClinicFlow/ClinicFlow/wsgi.py'.
[Thu Apr 13 21:50:25.519189 2017] [:error] [pid 2908] [client 24.146.44.164:62628] Traceback (most recent call last):
[Thu Apr 13 21:50:25.519245 2017] [:error] [pid 2908] [client 24.146.44.164:62628]   File "/home/ec2-user/envClinicFlow/ClinicFlow/ClinicFlow/wsgi.py", line 20, in <module>
[Thu Apr 13 21:50:25.519250 2017] [:error] [pid 2908] [client 24.146.44.164:62628]     application = get_wsgi_application()
[Thu Apr 13 21:50:25.519258 2017] [:error] [pid 2908] [client 24.146.44.164:62628]   File "/home/ec2-user/envClinicFlow/local/lib/python3.5/site-packages/django/core/wsgi.py", line 13, in get_wsgi_application
[Thu Apr 13 21:50:25.519261 2017] [:error] [pid 2908] [client 24.146.44.164:62628]     django.setup(set_prefix=False)
[Thu Apr 13 21:50:25.519268 2017] [:error] [pid 2908] [client 24.146.44.164:62628]   File "/home/ec2-user/envClinicFlow/local/lib/python3.5/site-packages/django/__init__.py", line 22, in setup
[Thu Apr 13 21:50:25.519270 2017] [:error] [pid 2908] [client 24.146.44.164:62628]     configure_logging(settings.LOGGING_CONFIG, settings.LOGGING)
[Thu Apr 13 21:50:25.519276 2017] [:error] [pid 2908] [client 24.146.44.164:62628]   File "/home/ec2-user/envClinicFlow/local/lib/python3.5/site-packages/django/conf/__init__.py", line 56, in __getattr__
[Thu Apr 13 21:50:25.519279 2017] [:error] [pid 2908] [client 24.146.44.164:62628]     self._setup(name)
[Thu Apr 13 21:50:25.519283 2017] [:error] [pid 2908] [client 24.146.44.164:62628]   File "/home/ec2-user/envClinicFlow/local/lib/python3.5/site-packages/django/conf/__init__.py", line 41, in _setup
[Thu Apr 13 21:50:25.519286 2017] [:error] [pid 2908] [client 24.146.44.164:62628]     self._wrapped = Settings(settings_module)
[Thu Apr 13 21:50:25.519290 2017] [:error] [pid 2908] [client 24.146.44.164:62628]   File "/home/ec2-user/envClinicFlow/local/lib/python3.5/site-packages/django/conf/__init__.py", line 110, in __init__
[Thu Apr 13 21:50:25.519293 2017] [:error] [pid 2908] [client 24.146.44.164:62628]     mod = importlib.import_module(self.SETTINGS_MODULE)
[Thu Apr 13 21:50:25.519298 2017] [:error] [pid 2908] [client 24.146.44.164:62628]   File "/home/ec2-user/envClinicFlow/lib64/python3.5/importlib/__init__.py", line 126, in import_module
[Thu Apr 13 21:50:25.519301 2017] [:error] [pid 2908] [client 24.146.44.164:62628]     return _bootstrap._gcd_import(name[level:], package, level)
[Thu Apr 13 21:50:25.519305 2017] [:error] [pid 2908] [client 24.146.44.164:62628]   File "<frozen importlib._bootstrap>", line 986, in _gcd_import
[Thu Apr 13 21:50:25.519310 2017] [:error] [pid 2908] [client 24.146.44.164:62628]   File "<frozen importlib._bootstrap>", line 969, in _find_and_load
[Thu Apr 13 21:50:25.519315 2017] [:error] [pid 2908] [client 24.146.44.164:62628]   File "<frozen importlib._bootstrap>", line 958, in _find_and_load_unlocked
[Thu Apr 13 21:50:25.519321 2017] [:error] [pid 2908] [client 24.146.44.164:62628]   File "<frozen importlib._bootstrap>", line 673, in _load_unlocked
[Thu Apr 13 21:50:25.519326 2017] [:error] [pid 2908] [client 24.146.44.164:62628]   File "<frozen importlib._bootstrap_external>", line 658, in exec_module
[Thu Apr 13 21:50:25.519331 2017] [:error] [pid 2908] [client 24.146.44.164:62628]   File "<frozen importlib._bootstrap_external>", line 764, in get_code
[Thu Apr 13 21:50:25.519336 2017] [:error] [pid 2908] [client 24.146.44.164:62628]   File "<frozen importlib._bootstrap_external>", line 724, in source_to_code
[Thu Apr 13 21:50:25.519354 2017] [:error] [pid 2908] [client 24.146.44.164:62628]   File "<frozen importlib._bootstrap>", line 222, in _call_with_frames_removed
[Thu Apr 13 21:50:25.519372 2017] [:error] [pid 2908] [client 24.146.44.164:62628]   File "/home/ec2-user/envClinicFlow/ClinicFlow/ClinicFlow/settings.py", line 159
[Thu Apr 13 21:50:25.519382 2017] [:error] [pid 2908] [client 24.146.44.164:62628]     }
[Thu Apr 13 21:50:25.519400 2017] [:error] [pid 2908] [client 24.146.44.164:62628]     ^
[Thu Apr 13 21:50:25.519409 2017] [:error] [pid 2908] [client 24.146.44.164:62628] SyntaxError: unexpected EOF while parsing
[Thu Apr 13 22:48:53.937133 2017] [core:error] [pid 3600] (13)Permission denied: [client 24.146.44.164:53919] AH00035: access to /simengine denied (filesystem path '/home/ec2-user/envClinicFlow/ClinicFlow/ClinicFlow') because search permissions are missing on a component of the path
[Thu Apr 13 22:48:59.487619 2017] [core:error] [pid 3602] (13)Permission denied: [client 24.146.44.164:53920] AH00035: access to /simengine denied (filesystem path '/home/ec2-user/envClinicFlow/ClinicFlow/ClinicFlow') because search permissions are missing on a component of the path
[Thu Apr 13 22:49:05.602845 2017] [core:error] [pid 3598] (13)Permission denied: [client 24.146.44.164:53921] AH00035: access to / denied (filesystem path '/home/ec2-user/envClinicFlow/ClinicFlow/ClinicFlow') because search permissions are missing on a component of the path
[Thu Apr 13 22:52:53.274161 2017] [core:error] [pid 3664] (13)Permission denied: [client 24.146.44.164:53954] AH00035: access to / denied (filesystem path '/home/ec2-user/envClinicFlow/ClinicFlow/ClinicFlow') because search permissions are missing on a component of the path
[Thu Apr 13 22:52:53.802181 2017] [core:error] [pid 3664] (13)Permission denied: [client 24.146.44.164:53954] AH00035: access to / denied (filesystem path '/home/ec2-user/envClinicFlow/ClinicFlow/ClinicFlow') because search permissions are missing on a component of the path
[Fri Apr 14 01:42:35.856311 2017] [:error] [pid 3808] [client 185.169.230.8:50493] mod_wsgi (pid=3808): Exception occurred processing WSGI script '/home/ec2-user/envClinicFlow/ClinicFlow/ClinicFlow/wsgi.py'.
[Fri Apr 14 01:42:35.856427 2017] [:error] [pid 3808] [client 185.169.230.8:50493] OSError: failed to write data
[Fri Apr 14 10:40:56.850817 2017] [:error] [pid 3808] [client 177.142.73.178:42187] mod_wsgi (pid=3808): Exception occurred processing WSGI script '/home/ec2-user/envClinicFlow/ClinicFlow/ClinicFlow/wsgi.py'.
[Fri Apr 14 10:40:56.850932 2017] [:error] [pid 3808] [client 177.142.73.178:42187] OSError: failed to write data
[Fri Apr 14 19:55:21.186317 2017] [:error] [pid 3806] [client 185.169.230.8:39687] mod_wsgi (pid=3806): Exception occurred processing WSGI script '/home/ec2-user/envClinicFlow/ClinicFlow/ClinicFlow/wsgi.py'.
[Fri Apr 14 19:55:21.186474 2017] [:error] [pid 3806] [client 185.169.230.8:39687] OSError: failed to write data
[Fri Apr 14 20:47:00.841704 2017] [:error] [pid 7499] [client 185.110.132.232:45894] mod_wsgi (pid=7499): Exception occurred processing WSGI script '/home/ec2-user/envClinicFlow/ClinicFlow/ClinicFlow/wsgi.py'.
[Fri Apr 14 20:47:00.841845 2017] [:error] [pid 7499] [client 185.110.132.232:45894] OSError: failed to write data
[Sat Apr 15 07:05:19.046525 2017] [:error] [pid 3808] [client 185.169.230.8:52600] mod_wsgi (pid=3808): Exception occurred processing WSGI script '/home/ec2-user/envClinicFlow/ClinicFlow/ClinicFlow/wsgi.py'.
[Sat Apr 15 07:05:19.046654 2017] [:error] [pid 3808] [client 185.169.230.8:52600] OSError: failed to write data
[Sat Apr 15 07:10:00.739343 2017] [:error] [pid 3806] [client 66.240.205.34:48667] mod_wsgi (pid=3806): Exception occurred processing WSGI script '/home/ec2-user/envClinicFlow/ClinicFlow/ClinicFlow/wsgi.py'.
[Sat Apr 15 07:10:00.739434 2017] [:error] [pid 3806] [client 66.240.205.34:48667] OSError: failed to write data
[Sat Apr 15 09:29:33.314110 2017] [:error] [pid 7499] [client 73.67.99.174:58713] mod_wsgi (pid=7499): Exception occurred processing WSGI script '/home/ec2-user/envClinicFlow/ClinicFlow/ClinicFlow/wsgi.py'.
[Sat Apr 15 09:29:33.314197 2017] [:error] [pid 7499] [client 73.67.99.174:58713] OSError: failed to write data
[Sat Apr 15 14:31:48.954564 2017] [:error] [pid 3848] [client 185.169.230.8:47425] mod_wsgi (pid=3848): Exception occurred processing WSGI script '/home/ec2-user/envClinicFlow/ClinicFlow/ClinicFlow/wsgi.py'.
[Sat Apr 15 14:31:48.954722 2017] [:error] [pid 3848] [client 185.169.230.8:47425] OSError: failed to write data
[Sat Apr 15 20:30:15.432321 2017] [:error] [pid 3806] [client 54.81.79.130:58512] mod_wsgi (pid=3806): Exception occurred processing WSGI script '/home/ec2-user/envClinicFlow/ClinicFlow/ClinicFlow/wsgi.py'.
[Sat Apr 15 20:30:15.432402 2017] [:error] [pid 3806] [client 54.81.79.130:58512] OSError: failed to write data
[Sat Apr 15 21:15:34.335461 2017] [:error] [pid 7499] [client 187.162.94.239:4476] mod_wsgi (pid=7499): Exception occurred processing WSGI script '/home/ec2-user/envClinicFlow/ClinicFlow/ClinicFlow/wsgi.py'.
[Sat Apr 15 21:15:34.335542 2017] [:error] [pid 7499] [client 187.162.94.239:4476] OSError: failed to write data
[Sat Apr 15 21:55:29.039897 2017] [:error] [pid 3804] [client 115.127.81.219:4423] mod_wsgi (pid=3804): Exception occurred processing WSGI script '/home/ec2-user/envClinicFlow/ClinicFlow/ClinicFlow/wsgi.py'.
[Sat Apr 15 21:55:29.040038 2017] [:error] [pid 3804] [client 115.127.81.219:4423] OSError: failed to write data
[Sun Apr 16 01:34:39.675887 2017] [:error] [pid 3807] [client 139.162.108.53:51856] mod_wsgi (pid=3807): Exception occurred processing WSGI script '/home/ec2-user/envClinicFlow/ClinicFlow/ClinicFlow/wsgi.py'.
[Sun Apr 16 01:34:39.675988 2017] [:error] [pid 3807] [client 139.162.108.53:51856] OSError: failed to write data
[Sun Apr 16 01:53:52.273786 2017] [:error] [pid 3808] [client 185.169.230.8:41515] mod_wsgi (pid=3808): Exception occurred processing WSGI script '/home/ec2-user/envClinicFlow/ClinicFlow/ClinicFlow/wsgi.py'.
[Sun Apr 16 01:53:52.273937 2017] [:error] [pid 3808] [client 185.169.230.8:41515] OSError: failed to write data
[Sun Apr 16 04:20:01.400132 2017] [:error] [pid 12569] [client 185.93.226.90:41676] mod_wsgi (pid=12569): Exception occurred processing WSGI script '/home/ec2-user/envClinicFlow/ClinicFlow/ClinicFlow/wsgi.py'.
[Sun Apr 16 04:20:01.400259 2017] [:error] [pid 12569] [client 185.93.226.90:41676] OSError: failed to write data
[Sun Apr 16 07:57:20.094213 2017] [:error] [pid 12568] [client 185.169.230.8:41899] mod_wsgi (pid=12568): Exception occurred processing WSGI script '/home/ec2-user/envClinicFlow/ClinicFlow/ClinicFlow/wsgi.py'.
[Sun Apr 16 07:57:20.094363 2017] [:error] [pid 12568] [client 185.169.230.8:41899] OSError: failed to write data
[Sun Apr 16 13:28:15.306587 2017] [:error] [pid 12571] [client 71.6.167.142:49348] mod_wsgi (pid=12571): Exception occurred processing WSGI script '/home/ec2-user/envClinicFlow/ClinicFlow/ClinicFlow/wsgi.py'.
[Sun Apr 16 13:28:15.306667 2017] [:error] [pid 12571] [client 71.6.167.142:49348] OSError: failed to write data
[Sun Apr 16 21:26:32.040863 2017] [:error] [pid 12570] [client 202.180.52.51:3758] mod_wsgi (pid=12570): Exception occurred processing WSGI script '/home/ec2-user/envClinicFlow/ClinicFlow/ClinicFlow/wsgi.py'.
[Sun Apr 16 21:26:32.041007 2017] [:error] [pid 12570] [client 202.180.52.51:3758] OSError: failed to write data
[Sun Apr 16 22:56:44.029188 2017] [:error] [pid 12567] [client 185.169.230.8:57257] mod_wsgi (pid=12567): Exception occurred processing WSGI script '/home/ec2-user/envClinicFlow/ClinicFlow/ClinicFlow/wsgi.py'.
[Sun Apr 16 22:56:44.029338 2017] [:error] [pid 12567] [client 185.169.230.8:57257] OSError: failed to write data
[Mon Apr 17 05:32:57.011351 2017] [:error] [pid 12568] [client 222.252.14.177:40737] mod_wsgi (pid=12568): Exception occurred processing WSGI script '/home/ec2-user/envClinicFlow/ClinicFlow/ClinicFlow/wsgi.py'.
[Mon Apr 17 05:32:57.011511 2017] [:error] [pid 12568] [client 222.252.14.177:40737] OSError: failed to write data
[Mon Apr 17 06:13:19.383202 2017] [:error] [pid 12570] [client 185.169.230.8:41011] mod_wsgi (pid=12570): Exception occurred processing WSGI script '/home/ec2-user/envClinicFlow/ClinicFlow/ClinicFlow/wsgi.py'.
[Mon Apr 17 06:13:19.383344 2017] [:error] [pid 12570] [client 185.169.230.8:41011] OSError: failed to write data
[Mon Apr 17 08:10:59.217583 2017] [:error] [pid 12571] [client 185.110.132.232:34284] mod_wsgi (pid=12571): Exception occurred processing WSGI script '/home/ec2-user/envClinicFlow/ClinicFlow/ClinicFlow/wsgi.py'.
[Mon Apr 17 08:10:59.217732 2017] [:error] [pid 12571] [client 185.110.132.232:34284] OSError: failed to write data
[Mon Apr 17 17:50:14.351042 2017] [:error] [pid 12569] [client 185.169.230.8:49514] mod_wsgi (pid=12569): Exception occurred processing WSGI script '/home/ec2-user/envClinicFlow/ClinicFlow/ClinicFlow/wsgi.py'.
[Mon Apr 17 17:50:14.351183 2017] [:error] [pid 12569] [client 185.169.230.8:49514] OSError: failed to write data
[Mon Apr 17 22:40:19.689734 2017] [:error] [pid 12570] [client 109.236.84.106:36323] mod_wsgi (pid=12570): Exception occurred processing WSGI script '/home/ec2-user/envClinicFlow/ClinicFlow/ClinicFlow/wsgi.py'.
[Mon Apr 17 22:40:19.689817 2017] [:error] [pid 12570] [client 109.236.84.106:36323] OSError: failed to write data
[Mon Apr 17 23:13:06.578730 2017] [:error] [pid 12570] [client 109.236.84.106:56761] mod_wsgi (pid=12570): Exception occurred processing WSGI script '/home/ec2-user/envClinicFlow/ClinicFlow/ClinicFlow/wsgi.py'.
[Mon Apr 17 23:13:06.578835 2017] [:error] [pid 12570] [client 109.236.84.106:56761] OSError: failed to write data
[Tue Apr 18 00:55:46.665141 2017] [:error] [pid 12571] [client 80.14.80.27:2388] mod_wsgi (pid=12571): Exception occurred processing WSGI script '/home/ec2-user/envClinicFlow/ClinicFlow/ClinicFlow/wsgi.py'.
[Tue Apr 18 00:55:46.665217 2017] [:error] [pid 12571] [client 80.14.80.27:2388] OSError: failed to write data
[Tue Apr 18 00:57:09.533529 2017] [:error] [pid 12567] [client 185.169.230.8:38365] mod_wsgi (pid=12567): Exception occurred processing WSGI script '/home/ec2-user/envClinicFlow/ClinicFlow/ClinicFlow/wsgi.py'.
[Tue Apr 18 00:57:09.533664 2017] [:error] [pid 12567] [client 185.169.230.8:38365] OSError: failed to write data
[Tue Apr 18 04:35:13.815689 2017] [:error] [pid 12569] [client 185.169.230.8:33058] mod_wsgi (pid=12569): Exception occurred processing WSGI script '/home/ec2-user/envClinicFlow/ClinicFlow/ClinicFlow/wsgi.py'.
[Tue Apr 18 04:35:13.815823 2017] [:error] [pid 12569] [client 185.169.230.8:33058] OSError: failed to write data
[Tue Apr 18 08:40:42.266167 2017] [:error] [pid 12568] [client 185.169.230.8:41656] mod_wsgi (pid=12568): Exception occurred processing WSGI script '/home/ec2-user/envClinicFlow/ClinicFlow/ClinicFlow/wsgi.py'.
[Tue Apr 18 08:40:42.266301 2017] [:error] [pid 12568] [client 185.169.230.8:41656] OSError: failed to write data
[Tue Apr 18 10:46:10.901474 2017] [:error] [pid 12679] [client 139.162.124.167:53764] mod_wsgi (pid=12679): Exception occurred processing WSGI script '/home/ec2-user/envClinicFlow/ClinicFlow/ClinicFlow/wsgi.py'.
[Tue Apr 18 10:46:10.901622 2017] [:error] [pid 12679] [client 139.162.124.167:53764] OSError: failed to write data
[Tue Apr 18 10:46:38.330627 2017] [:error] [pid 12567] [client 139.162.124.167:48438] mod_wsgi (pid=12567): Exception occurred processing WSGI script '/home/ec2-user/envClinicFlow/ClinicFlow/ClinicFlow/wsgi.py'.
[Tue Apr 18 10:46:38.330692 2017] [:error] [pid 12567] [client 139.162.124.167:48438] OSError: failed to write data
[Tue Apr 18 12:00:45.283588 2017] [:error] [pid 12568] [client 185.169.230.8:49197] mod_wsgi (pid=12568): Exception occurred processing WSGI script '/home/ec2-user/envClinicFlow/ClinicFlow/ClinicFlow/wsgi.py'.
[Tue Apr 18 12:00:45.283726 2017] [:error] [pid 12568] [client 185.169.230.8:49197] OSError: failed to write data
[Tue Apr 18 19:27:36.650809 2017] [:error] [pid 12679] [client 23.20.205.190:53226] mod_wsgi (pid=12679): Exception occurred processing WSGI script '/home/ec2-user/envClinicFlow/ClinicFlow/ClinicFlow/wsgi.py'.
[Tue Apr 18 19:27:36.650910 2017] [:error] [pid 12679] [client 23.20.205.190:53226] OSError: failed to write data
[Tue Apr 18 21:08:13.632643 2017] [:error] [pid 12569] [client 190.123.226.112:47845] mod_wsgi (pid=12569): Exception occurred processing WSGI script '/home/ec2-user/envClinicFlow/ClinicFlow/ClinicFlow/wsgi.py'.
[Tue Apr 18 21:08:13.632810 2017] [:error] [pid 12569] [client 190.123.226.112:47845] OSError: failed to write data
[Tue Apr 18 21:50:49.837750 2017] [:error] [pid 12567] [client 139.162.119.197:34272] mod_wsgi (pid=12567): Exception occurred processing WSGI script '/home/ec2-user/envClinicFlow/ClinicFlow/ClinicFlow/wsgi.py'.
[Tue Apr 18 21:50:49.837901 2017] [:error] [pid 12567] [client 139.162.119.197:34272] OSError: failed to write data
[Tue Apr 18 22:49:54.988169 2017] [:error] [pid 12679] [client 191.191.232.146:59350] mod_wsgi (pid=12679): Exception occurred processing WSGI script '/home/ec2-user/envClinicFlow/ClinicFlow/ClinicFlow/wsgi.py'.
[Tue Apr 18 22:49:54.988245 2017] [:error] [pid 12679] [client 191.191.232.146:59350] OSError: failed to write data
[Wed Apr 19 01:14:25.795400 2017] [:error] [pid 12569] [client 77.117.222.200:52189] mod_wsgi (pid=12569): Exception occurred processing WSGI script '/home/ec2-user/envClinicFlow/ClinicFlow/ClinicFlow/wsgi.py'.
[Wed Apr 19 01:14:25.795541 2017] [:error] [pid 12569] [client 77.117.222.200:52189] OSError: failed to write data
[Wed Apr 19 02:08:31.383020 2017] [:error] [pid 12567] [client 93.132.52.105:41589] mod_wsgi (pid=12567): Exception occurred processing WSGI script '/home/ec2-user/envClinicFlow/ClinicFlow/ClinicFlow/wsgi.py'.
[Wed Apr 19 02:08:31.383094 2017] [:error] [pid 12567] [client 93.132.52.105:41589] OSError: failed to write data
[Wed Apr 19 02:20:35.371798 2017] [:error] [pid 12570] [client 139.162.124.167:45314] mod_wsgi (pid=12570): Exception occurred processing WSGI script '/home/ec2-user/envClinicFlow/ClinicFlow/ClinicFlow/wsgi.py'.
[Wed Apr 19 02:20:35.371933 2017] [:error] [pid 12570] [client 139.162.124.167:45314] OSError: failed to write data
[Wed Apr 19 02:21:02.427342 2017] [:error] [pid 12568] [client 139.162.124.167:43100] mod_wsgi (pid=12568): Exception occurred processing WSGI script '/home/ec2-user/envClinicFlow/ClinicFlow/ClinicFlow/wsgi.py'.
[Wed Apr 19 02:21:02.427447 2017] [:error] [pid 12568] [client 139.162.124.167:43100] OSError: failed to write data
[Wed Apr 19 06:54:07.101061 2017] [:error] [pid 12679] [client 139.162.119.197:57834] mod_wsgi (pid=12679): Exception occurred processing WSGI script '/home/ec2-user/envClinicFlow/ClinicFlow/ClinicFlow/wsgi.py'.
[Wed Apr 19 06:54:07.101155 2017] [:error] [pid 12679] [client 139.162.119.197:57834] OSError: failed to write data
[Wed Apr 19 19:41:19.476453 2017] [:error] [pid 12570] [client 185.110.132.232:45784] mod_wsgi (pid=12570): Exception occurred processing WSGI script '/home/ec2-user/envClinicFlow/ClinicFlow/ClinicFlow/wsgi.py'.
[Wed Apr 19 19:41:19.476539 2017] [:error] [pid 12570] [client 185.110.132.232:45784] OSError: failed to write data
[Thu Apr 20 01:06:38.196731 2017] [:error] [pid 12567] [client 209.126.136.5:34686] mod_wsgi (pid=12567): Exception occurred processing WSGI script '/home/ec2-user/envClinicFlow/ClinicFlow/ClinicFlow/wsgi.py'.
[Thu Apr 20 01:06:38.196868 2017] [:error] [pid 12567] [client 209.126.136.5:34686] OSError: failed to write data
[Thu Apr 20 14:44:26.862878 2017] [:error] [pid 22678] [client 94.102.49.193:54687] mod_wsgi (pid=22678): Exception occurred processing WSGI script '/home/ec2-user/envClinicFlow/ClinicFlow/ClinicFlow/wsgi.py'.
[Thu Apr 20 14:44:26.863019 2017] [:error] [pid 22678] [client 94.102.49.193:54687] OSError: failed to write data
[Thu Apr 20 18:46:06.111077 2017] [:error] [pid 12571] [client 27.121.147.117:45188] mod_wsgi (pid=12571): Exception occurred processing WSGI script '/home/ec2-user/envClinicFlow/ClinicFlow/ClinicFlow/wsgi.py'.
[Thu Apr 20 18:46:06.111174 2017] [:error] [pid 12571] [client 27.121.147.117:45188] OSError: failed to write data
[Thu Apr 20 20:11:01.824700 2017] [:error] [pid 12568] [client 179.218.246.242:37343] mod_wsgi (pid=12568): Exception occurred processing WSGI script '/home/ec2-user/envClinicFlow/ClinicFlow/ClinicFlow/wsgi.py'.
[Thu Apr 20 20:11:01.824850 2017] [:error] [pid 12568] [client 179.218.246.242:37343] OSError: failed to write data
[Thu Apr 20 22:10:46.915246 2017] [:error] [pid 19837] [client 14.162.17.37:3948] mod_wsgi (pid=19837): Exception occurred processing WSGI script '/home/ec2-user/envClinicFlow/ClinicFlow/ClinicFlow/wsgi.py'.
[Thu Apr 20 22:10:46.915385 2017] [:error] [pid 19837] [client 14.162.17.37:3948] OSError: failed to write data
[Fri Apr 21 01:36:52.660446 2017] [:error] [pid 12679] [client 139.162.119.197:45282] mod_wsgi (pid=12679): Exception occurred processing WSGI script '/home/ec2-user/envClinicFlow/ClinicFlow/ClinicFlow/wsgi.py'.
[Fri Apr 21 01:36:52.660574 2017] [:error] [pid 12679] [client 139.162.119.197:45282] OSError: failed to write data
[Fri Apr 21 02:22:08.056911 2017] [:error] [pid 12567] [client 193.63.58.83:21666] mod_wsgi (pid=12567): Exception occurred processing WSGI script '/home/ec2-user/envClinicFlow/ClinicFlow/ClinicFlow/wsgi.py'.
[Fri Apr 21 02:22:08.057021 2017] [:error] [pid 12567] [client 193.63.58.83:21666] OSError: failed to write data
[Fri Apr 21 05:45:33.879063 2017] [:error] [pid 12568] [client 218.161.63.235:4674] mod_wsgi (pid=12568): Exception occurred processing WSGI script '/home/ec2-user/envClinicFlow/ClinicFlow/ClinicFlow/wsgi.py'.
[Fri Apr 21 05:45:33.879206 2017] [:error] [pid 12568] [client 218.161.63.235:4674] OSError: failed to write data
[Fri Apr 21 06:46:44.173166 2017] [:error] [pid 19837] [client 103.247.219.155:36577] mod_wsgi (pid=19837): Exception occurred processing WSGI script '/home/ec2-user/envClinicFlow/ClinicFlow/ClinicFlow/wsgi.py'.
[Fri Apr 21 06:46:44.173396 2017] [:error] [pid 19837] [client 103.247.219.155:36577] OSError: failed to write data
[Fri Apr 21 18:48:04.927275 2017] [:error] [pid 22678] [client 130.113.109.147:54204] mod_wsgi (pid=22678): Exception occurred processing WSGI script '/home/ec2-user/envClinicFlow/ClinicFlow/ClinicFlow/wsgi.py'.
[Fri Apr 21 18:48:04.927354 2017] [:error] [pid 22678] [client 130.113.109.147:54204] OSError: failed to write data
[Fri Apr 21 21:07:23.772993 2017] [:error] [pid 12569] [client 139.162.124.167:58548] mod_wsgi (pid=12569): Exception occurred processing WSGI script '/home/ec2-user/envClinicFlow/ClinicFlow/ClinicFlow/wsgi.py'.
[Fri Apr 21 21:07:23.773125 2017] [:error] [pid 12569] [client 139.162.124.167:58548] OSError: failed to write data
[Fri Apr 21 21:07:50.627994 2017] [:error] [pid 12679] [client 139.162.124.167:55464] mod_wsgi (pid=12679): Exception occurred processing WSGI script '/home/ec2-user/envClinicFlow/ClinicFlow/ClinicFlow/wsgi.py'.
[Fri Apr 21 21:07:50.628134 2017] [:error] [pid 12679] [client 139.162.124.167:55464] OSError: failed to write data
[Fri Apr 21 21:48:12.271648 2017] [:error] [pid 12568] [client 104.222.67.56:59722] mod_wsgi (pid=12568): Exception occurred processing WSGI script '/home/ec2-user/envClinicFlow/ClinicFlow/ClinicFlow/wsgi.py'.
[Fri Apr 21 21:48:12.271747 2017] [:error] [pid 12568] [client 104.222.67.56:59722] OSError: failed to write data
[Sat Apr 22 02:11:31.356812 2017] [:error] [pid 12571] [client 71.6.146.185:33870] mod_wsgi (pid=12571): Exception occurred processing WSGI script '/home/ec2-user/envClinicFlow/ClinicFlow/ClinicFlow/wsgi.py'.
[Sat Apr 22 02:11:31.356901 2017] [:error] [pid 12571] [client 71.6.146.185:33870] OSError: failed to write data
[Sat Apr 22 04:41:45.312873 2017] [:error] [pid 12679] [client 139.162.124.167:34938] mod_wsgi (pid=12679): Exception occurred processing WSGI script '/home/ec2-user/envClinicFlow/ClinicFlow/ClinicFlow/wsgi.py'.
[Sat Apr 22 04:41:45.312984 2017] [:error] [pid 12679] [client 139.162.124.167:34938] OSError: failed to write data
[Sat Apr 22 04:42:12.586139 2017] [:error] [pid 12567] [client 139.162.124.167:59582] mod_wsgi (pid=12567): Exception occurred processing WSGI script '/home/ec2-user/envClinicFlow/ClinicFlow/ClinicFlow/wsgi.py'.
[Sat Apr 22 04:42:12.586268 2017] [:error] [pid 12567] [client 139.162.124.167:59582] OSError: failed to write data
[Sat Apr 22 06:16:21.745565 2017] [:error] [pid 22678] [client 187.154.5.161:63894] mod_wsgi (pid=22678): Exception occurred processing WSGI script '/home/ec2-user/envClinicFlow/ClinicFlow/ClinicFlow/wsgi.py'.
[Sat Apr 22 06:16:21.745727 2017] [:error] [pid 22678] [client 187.154.5.161:63894] OSError: failed to write data
[Sat Apr 22 07:47:58.753934 2017] [:error] [pid 12571] [client 125.26.232.3:3798] mod_wsgi (pid=12571): Exception occurred processing WSGI script '/home/ec2-user/envClinicFlow/ClinicFlow/ClinicFlow/wsgi.py'.
[Sat Apr 22 07:47:58.754133 2017] [:error] [pid 12571] [client 125.26.232.3:3798] OSError: failed to write data
[Sat Apr 22 11:29:02.281793 2017] [:error] [pid 12569] [client 191.96.249.97:48934] mod_wsgi (pid=12569): Exception occurred processing WSGI script '/home/ec2-user/envClinicFlow/ClinicFlow/ClinicFlow/wsgi.py'.
[Sat Apr 22 11:29:02.281888 2017] [:error] [pid 12569] [client 191.96.249.97:48934] OSError: failed to write data
[Sat Apr 22 12:05:37.858131 2017] [:error] [pid 12679] [client 116.100.129.181:1534] mod_wsgi (pid=12679): Exception occurred processing WSGI script '/home/ec2-user/envClinicFlow/ClinicFlow/ClinicFlow/wsgi.py'.
[Sat Apr 22 12:05:37.858321 2017] [:error] [pid 12679] [client 116.100.129.181:1534] OSError: failed to write data
[Sun Apr 23 03:14:51.107419 2017] [:error] [pid 12679] [client 139.162.114.70:47718] mod_wsgi (pid=12679): Exception occurred processing WSGI script '/home/ec2-user/envClinicFlow/ClinicFlow/ClinicFlow/wsgi.py'.
[Sun Apr 23 03:14:51.108196 2017] [:error] [pid 12679] [client 139.162.114.70:47718] OSError: failed to write data
[Sun Apr 23 18:20:01.610593 2017] [:error] [pid 2494] [client 185.110.132.232:38090] mod_wsgi (pid=2494): Exception occurred processing WSGI script '/home/ec2-user/envClinicFlow/ClinicFlow/ClinicFlow/wsgi.py'.
[Sun Apr 23 18:20:01.610770 2017] [:error] [pid 2494] [client 185.110.132.232:38090] OSError: failed to write data
[Sun Apr 23 22:20:08.500864 2017] [:error] [pid 2495] [client 191.96.249.97:37188] mod_wsgi (pid=2495): Exception occurred processing WSGI script '/home/ec2-user/envClinicFlow/ClinicFlow/ClinicFlow/wsgi.py'.
[Sun Apr 23 22:20:08.500998 2017] [:error] [pid 2495] [client 191.96.249.97:37188] OSError: failed to write data
